Workbook

Sheet 20260228波箱油&刹车油售价&订单
AD1: 订货周期（OC） | AK1: 排序 | AL1: 产品名称 | AM1: BCS HO | BI1: 历史销量 | BJ1: 库存状态 | BN1: 调拨需求 | BT1: BCS 01-KLG | CE1: BCS 02-PIK 2 | CP1: BCS HO ST0CK-(Franchise store requirements)
A2: 序号 | B2: 零件号 | C2: 品牌 | D2: 零件类别 | E2: 产品类型 | F2: 产品类型 | J2: 产品名称 | K2: 产品名称 | L2: Quantity | M2: Unit | N2: Cost Price | O2: Fixed Markup Rate | P2: Floating Markup Rate | Q2: Total Markup Rate | S2: BQUICK 参考价 | T2: shopee官网 | U2: tokopedia官网 | V2: 平均 参考价 | W2: 初始销售价 --02 | X2: 初始销售价 --03 | Y2: 修正销售价 | Z2: 工时费 | AA2: 含工时费 销售价 | AB2: 毛利 | AC2: 毛利率 | AD2: 订货周期（OC） | AF2: 到货周期（LT） | AH2: 安全库存 行业系数经验值 | AI2: 安全库存周期（SS） | AM2: Total | AN2: Average 6 | AO2: Average 11 | AP2: 销售趋向系数 | AQ2: 5~9月 进店量 | AR2: 配件 更换率 | AS2: 月度 理论销量 | AT2: 最小库存量 （安全库存量） | AU2: 标准库存量（SSQ） | AV2: 现有库存量 （O/H） | AW2: 在途库存量 （O/O） | AX2: 追加订单量 （B/O） | AY2: 建议订单量 （SOQ） | AZ2: 修正订单 | BA2: 修正订单/箱 | BB2: 包装 | BC2: 桶/箱 | BD2: 对应送货动作 | BF2: 备货策略 | BG2: 质量等级 | BH2: 产品名称 | BJ2: BCS 01-KLG | BK2: BCS 02-PIK 2 | BL2: BCS HO | BM2: TOTAL | BN2: BCS 01-KLG | BO2: BCS 02-PIK 2 | BP2: TOTAL | BQ2: KLG | BR2: PIK2 | BS2: 产品名称 | BT2: Average 6 | BU2: Avergae 11 | BV2: 销售趋向系数 | BW2: 修正 最小库存量 | BX2: 最小库存量 （安全库存量） | BY2: 标准库存量（SSQ） | BZ2: 现有库存量 （O/H） | CA2: 在途库存量 （O/O） | CB2: 追加订单量 （B/O） | CC2: 建议订单量 （SOQ） | CD2: 修正订单 | CE2: Average 6 | CF2: Average 6 | CG2: 销售趋向系数 | CH2: 修正 最小库存量 | CI2: 最小库存量 （安全库存量） | CJ2: 标准库存量（SSQ） | CK2: 现有库存量 （O/H） | CL2: 在途库存量 （O/O） | CM2: 追加订单量 （B/O） | CN2: 建议订单量 （SOQ） | CO2: 修正订单 | CP2: Average 6 | CQ2: Average 6 | CR2: 销售趋向系数 | CS2: 修正 最小库存量 | CT2: 最小库存量 （安全库存量） | CU2: 标准库存量（SSQ） | CV2: 现有库存量 （O/H） | CW2: 在途库存量 （O/O） | CX2: 追加订单量 （B/O） | CY2: 建议订单量 （SOQ） | CZ2: 修正订单/桶 | DA2: 产品名称
A3: NO | B3: Part Number | C3: Brand | D3: Part Category | E3: Product Type | F3: Product Type | G3: 容量/桶 | H3: 包装 | I3: 桶/箱 | J3: Product Name | K3: Product Name | L3: 数量 | M3: 单位 | N3: 成本价 | O3: 固定加价率 | P3: 浮动加价率 | Q3: 合计加价率 | R3: 初始销售价01 | BD3: BCS 01-KLG | BE3: BCS 02-PIK 2 | BH3: Product Name | BJ3: 库存 | BK3: 库存 | BL3: 库存 | BM3: 总计 | BN3: 需求 | BO3: 需求 | BP3: 需求 | BS3: Product Name | DA3: Product Name
A4: 2 | B4: 101771 | C4: MOBIL | D4: Transmission Oil | E4: Dexron-VI | F4: ATF | G4: 1L | H4: 12*1L | I4: 12 | J4: =C4&" "&D4&" "&E4&" "&F4&" "&G4 -> MOBIL Transmission Oil Dexron-VI ATF 1L | K4: MOBIL Transmission Oil Dexron-VI ATF 1L | L4: 1 | M4: 桶 | N4: 65100 | O4: 0.4 | P4: 0.2 | Q4: =O4+P4 -> 0.6 | R4: =N4*(1+Q4) -> 104160 | S4: 0 | T4: 0 | U4: 0 | V4: =IF((S4+T4+U4)=0,R4,IF(AND(S4>0,T4=0,U4=0),S4,IF(AND(S4=0,T4>0,U4=0),T4,IF(AND(S4=0,T4=0,U4>0),U4,IF(AND(S4>0,T4>0,U4=0),(S4+T4)/2,IF(AND(S4>0,T4=0,U4>0),(S4+U4)/2,IF(AND(S4=0,T4>0,U4>0),(T4+U4)/2,IF(AND(S4>0,T4>0,U4>0),(S4+T4+U4)/3,)))))))) -> 104160 | W4: =IF(R4=V4,V4,IF(R4/V4<70%,R4*1.18,IF(AND(R4/V4>=70%,R4/V4<75%),R4*1.15,IF(AND(R4/V4>=75%,R4/V4<80%),R4*1.12,IF(AND(R4/V4>=80%,R4/V4<85%),R4*1.09,IF(AND(R4/V4>=85%,R4/V4<90%),R4*1.06,IF(AND(R4/V4>=90%,R4/V4<95%),R4*1.03,IF(AND(R4/V4>=95%,R4/V4<105%),V4,IF(AND(R4/V4>=105%,R4/V4<110%),R4*0.97,IF(AND(R4/V4>=110%,R4/V4<115%),R4*0.94,IF(AND(R4/V4>=115%,R4/V4<120%),R4*0.91,IF(AND(R4/V4>=120%,R4/V4<125%),R4*0.88,IF(AND(R4/V4>=125%,R4/V4<130%),R4*0.85,IF(AND(R4/V4>=130%,R4/V4<135%),R4*0.82,IF(R4/V4>=135%,R4*0.8,))))))))))))))) -> 104160 | X4: =IF(N4=0,1,IF(N4<10000,N4*2.8,IF(AND(N4>=10000,N4<20000),N4*2.2,IF(AND(N4>=20000,N4<30000),N4*1.8,IF(AND(N4>=30000,N4<40000),N4*1.78,IF(AND(N4>=40000,N4<50000),N4*1.76,IF(AND(N4>=50000,N4<60000),N4*1.74,IF(AND(N4>=60000,N4<70000),N4*1.72,IF(AND(N4>=70000,N4<80000),N4*1.7,IF(AND(N4>=80000,N4<90000),N4*1.68,IF(AND(N4>=90000,N4<100000),N4*1.66,IF(AND(N4>=100000,N4<110000),N4*1.65,IF(AND(N4>=110000,N4<120000),N4*1.64,IF(AND(N4>=120000,N4<130000),N4*1.63,IF(AND(N4>=130000,N4<140000),N4*1.62,IF(AND(N4>=140000,N4<150000),N4*1.61,IF(AND(N4>=150000,N4<160000),N4*1.6,IF(AND(N4>=160000,N4<170000),N4*1.59,IF(AND(N4>=170000,N4<180000),N4*1.58,IF(AND(N4>=180000,N4<190000),N4*1.57,IF(AND(N4>=190000,N4<200000),N4*1.56,IF(AND(N4>=200000,N4<300000),N4*1.54,IF(AND(N4>=300000,N4<400000),N4*1.52,IF(AND(N4>=400000,N4<500000),N4*1.5,IF(AND(N4>=500000,N4<600000),N4*1.48,IF(AND(N4>=600000,N4<700000),N4*1.46,IF(AND(N4>=700000,N4<800000),N4*1.44,IF(AND(N4>=800000,N4<900000),N4*1.42,IF(AND(N4>=900000,N4<1000000),N4*1.4,IF(AND(N4>=1000000,N4<2000000),N4*1.39,IF(AND(N4>=2000000,N4<3000000),N4*1.38,IF(AND(N4>=3000000,N4<4000000),N4*1.37,IF(AND(N4>=4000000,N4<5000000),N4*1.36,IF(AND(N4>=5000000,N4<6000000),N4*1.35,IF(AND(N4>=6000000,N4<7000000),N4*1.34,IF(AND(N4>=7000000,N4<8000000),N4*1.33,IF(AND(N4>=8000000,N4<9000000),N4*1.32,IF(AND(N4>=9000000,N4<10000000),N4*1.31,IF(N4>=10000000,N4*1.3,""))))))))))))))))))))))))))))))))))))))) -> 111972 | Y4: =CEILING((R4+W4+X4)/3,1000) -> 107000 | Z4: 0 | AA4: =CEILING((Y4+Z4),1000) -> 107000 | AB4: =AA4-N4 -> 41900 | AC4: =AB4/AA4 -> 0.39158879 | AD4: 30 | AE4: =AD4/30 -> 1 | AF4: 10 | AG4: =AF4/30 -> 0.33333333 | AH4: 0.7 | AI4: =(AE4+AG4)*AH4 -> 0.93333333 | AJ4: =AI4*30 -> 28 | AK4: - | AL4: =K4 -> MOBIL Transmission Oil Dexron-VI ATF 1L | AM4: =_xlfn.XLOOKUP(AL4,ITEM!B:B,ITEM!AY:AY,0) -> 764 | AN4: =_xlfn.XLOOKUP(AL4,ITEM!B:B,ITEM!AZ:AZ,0) -> 103.5 | AO4: =_xlfn.XLOOKUP(AL4,ITEM!B:B,ITEM!BA:BA,0) -> 68.454545 | AP4: =AN4/AO4 -> 1.5119522 | AQ4: 0 | AR4: 0 | AS4: 0 | AT4: =AN4*$AI4 -> 96.6 | AU4: =AN4*(AE4+AG4+AI4) -> 234.6 | AV4: =_xlfn.XLOOKUP(AL4,ITEM!B:B,ITEM!BN:BN,0) -> 180 | AW4: 0 | AX4: 0 | AY4: =AU4-AV4-AW4+AX4 -> 54.6 | AZ4: 120 | BA4: =AZ4/BC4 -> 10 | BB4: =H4 -> 12*1L | BC4: 12 | BD4: - | BE4: - | BF4: ★★★ | BG4: - | BH4: =K4 -> MOBIL Transmission Oil Dexron-VI ATF 1L | BI4: =AM4 -> 764 | BJ4: =BZ4 -> 8 | BK4: =CK4 -> 112 | BL4: =CV4 -> 60 | BM4: =BJ4+BK4+BL4 -> 180 | BN4: =CC4 -> 76.244444 | BO4: =CN4 -> 38.355556 | BP4: =AY4 -> 54.6 | BQ4: 24 | BS4: =K4 -> MOBIL Transmission Oil Dexron-VI ATF 1L | BT4: =_xlfn.XLOOKUP(BS4,ITEM!B:B,ITEM!BB:BB,0) -> 37.166667 | BU4: =_xlfn.XLOOKUP(BS4,ITEM!B:B,ITEM!BC:BC,0) -> 32.272727 | BV4: =BT4/BU4 -> 1.1516432 | BW4: 0 | BX4: =BT4*$AI4 -> 34.688889 | BY4: =BT4*($AE4+$AG4+$AI4) -> 84.244444 | BZ4: =_xlfn.XLOOKUP(BS4,ITEM!B:B,ITEM!BK:BK,0) -> 8 | CA4: 0 | CB4: 0 | CC4: =BY4-BZ4-CA4+CB4 -> 76.244444 | CD4: 0 | CE4: =_xlfn.XLOOKUP(BS4,ITEM!B:B,ITEM!BE:BE,0) -> 66.333333 | CF4: =_xlfn.XLOOKUP(BS4,ITEM!B:B,ITEM!BF:BF,0) -> 66.333333 | CG4: =CE4/CF4 -> 1 | CH4: 0 | CI4: =CE4*$AI4 -> 61.911111 | CJ4: =CE4*($AE4+$AG4+$AI4) -> 150.35556 | CK4: =_xlfn.XLOOKUP(BS4,ITEM!B:B,ITEM!BL:BL,0) -> 112 | CL4: 0 | CM4: 0 | CN4: =CJ4-CK4-CL4+CM4 -> 38.355556 | CO4: 0 | CP4: =_xlfn.XLOOKUP(BS4,ITEM!B:B,ITEM!BH:BH,0) -> 0 | CQ4: =_xlfn.XLOOKUP(BS4,ITEM!B:B,ITEM!BI:BI,0) -> 0 | CR4: =CP4/CQ4 -> #DIV/0! | CS4: 0 | CT4: =CP4*$AI4 -> 0 | CU4: =CP4*($AE4+$AG4+$AI4) -> 0 | CV4: =_xlfn.XLOOKUP(BS4,ITEM!B:B,ITEM!BM:BM,0) -> 60 | CW4: 0 | CX4: 0 | CY4: =CU4-CV4-CW4+CX4 -> -60 | CZ4: 0 | DA4: =K4 -> MOBIL Transmission Oil Dexron-VI ATF 1L
A5: 12 | B5: 101753 | C5: CASTROL | D5: Brake Fluid | E5: DOT 3 | F5: - | G5: 500ml | H5: 0 | I5: 0 | J5: =C5&" "&D5&" "&E5&" "&F5&" "&G5 -> CASTROL Brake Fluid DOT 3 - 500ml | K5: CASTROL Brake Fluid DOT 3 - 500ml | L5: 1 | M5: 桶 | N5: 77900 | O5: 0.4 | P5: 0.2 | Q5: =O5+P5 -> 0.6 | R5: =N5*(1+Q5) -> 124640 | S5: 0 | T5: 0 | U5: 0 | V5: =IF((S5+T5+U5)=0,R5,IF(AND(S5>0,T5=0,U5=0),S5,IF(AND(S5=0,T5>0,U5=0),T5,IF(AND(S5=0,T5=0,U5>0),U5,IF(AND(S5>0,T5>0,U5=0),(S5+T5)/2,IF(AND(S5>0,T5=0,U5>0),(S5+U5)/2,IF(AND(S5=0,T5>0,U5>0),(T5+U5)/2,IF(AND(S5>0,T5>0,U5>0),(S5+T5+U5)/3,)))))))) -> 124640 | W5: =IF(R5=V5,V5,IF(R5/V5<70%,R5*1.18,IF(AND(R5/V5>=70%,R5/V5<75%),R5*1.15,IF(AND(R5/V5>=75%,R5/V5<80%),R5*1.12,IF(AND(R5/V5>=80%,R5/V5<85%),R5*1.09,IF(AND(R5/V5>=85%,R5/V5<90%),R5*1.06,IF(AND(R5/V5>=90%,R5/V5<95%),R5*1.03,IF(AND(R5/V5>=95%,R5/V5<105%),V5,IF(AND(R5/V5>=105%,R5/V5<110%),R5*0.97,IF(AND(R5/V5>=110%,R5/V5<115%),R5*0.94,IF(AND(R5/V5>=115%,R5/V5<120%),R5*0.91,IF(AND(R5/V5>=120%,R5/V5<125%),R5*0.88,IF(AND(R5/V5>=125%,R5/V5<130%),R5*0.85,IF(AND(R5/V5>=130%,R5/V5<135%),R5*0.82,IF(R5/V5>=135%,R5*0.8,))))))))))))))) -> 124640 | X5: =IF(N5=0,1,IF(N5<10000,N5*2.8,IF(AND(N5>=10000,N5<20000),N5*2.2,IF(AND(N5>=20000,N5<30000),N5*1.8,IF(AND(N5>=30000,N5<40000),N5*1.78,IF(AND(N5>=40000,N5<50000),N5*1.76,IF(AND(N5>=50000,N5<60000),N5*1.74,IF(AND(N5>=60000,N5<70000),N5*1.72,IF(AND(N5>=70000,N5<80000),N5*1.7,IF(AND(N5>=80000,N5<90000),N5*1.68,IF(AND(N5>=90000,N5<100000),N5*1.66,IF(AND(N5>=100000,N5<110000),N5*1.65,IF(AND(N5>=110000,N5<120000),N5*1.64,IF(AND(N5>=120000,N5<130000),N5*1.63,IF(AND(N5>=130000,N5<140000),N5*1.62,IF(AND(N5>=140000,N5<150000),N5*1.61,IF(AND(N5>=150000,N5<160000),N5*1.6,IF(AND(N5>=160000,N5<170000),N5*1.59,IF(AND(N5>=170000,N5<180000),N5*1.58,IF(AND(N5>=180000,N5<190000),N5*1.57,IF(AND(N5>=190000,N5<200000),N5*1.56,IF(AND(N5>=200000,N5<300000),N5*1.54,IF(AND(N5>=300000,N5<400000),N5*1.52,IF(AND(N5>=400000,N5<500000),N5*1.5,IF(AND(N5>=500000,N5<600000),N5*1.48,IF(AND(N5>=600000,N5<700000),N5*1.46,IF(AND(N5>=700000,N5<800000),N5*1.44,IF(AND(N5>=800000,N5<900000),N5*1.42,IF(AND(N5>=900000,N5<1000000),N5*1.4,IF(AND(N5>=1000000,N5<2000000),N5*1.39,IF(AND(N5>=2000000,N5<3000000),N5*1.38,IF(AND(N5>=3000000,N5<4000000),N5*1.37,IF(AND(N5>=4000000,N5<5000000),N5*1.36,IF(AND(N5>=5000000,N5<6000000),N5*1.35,IF(AND(N5>=6000000,N5<7000000),N5*1.34,IF(AND(N5>=7000000,N5<8000000),N5*1.33,IF(AND(N5>=8000000,N5<9000000),N5*1.32,IF(AND(N5>=9000000,N5<10000000),N5*1.31,IF(N5>=10000000,N5*1.3,""))))))))))))))))))))))))))))))))))))))) -> 132430 | Y5: =CEILING((R5+W5+X5)/3,1000) -> 128000 | Z5: 0 | AA5: =CEILING((Y5+Z5),1000) -> 128000 | AB5: =AA5-N5 -> 50100 | AC5: =AB5/AA5 -> 0.39140625 | AD5: 30 | AE5: =AD5/30 -> 1 | AF5: 10 | AG5: =AF5/30 -> 0.33333333 | AH5: 0.7 | AI5: =(AE5+AG5)*AH5 -> 0.93333333 | AJ5: =AI5*30 -> 28 | AK5: - | AL5: =K5 -> CASTROL Brake Fluid DOT 3 - 500ml | AM5: =_xlfn.XLOOKUP(AL5,ITEM!B:B,ITEM!AY:AY,0) -> 646 | AN5: =_xlfn.XLOOKUP(AL5,ITEM!B:B,ITEM!AZ:AZ,0) -> 66.833333 | AO5: =_xlfn.XLOOKUP(AL5,ITEM!B:B,ITEM!BA:BA,0) -> 58.363636 | AP5: =AN5/AO5 -> 1.1451194 | AQ5: 0 | AR5: 0 | AS5: 0 | AT5: =AN5*$AI5 -> 62.377778 | AU5: =AN5*(AE5+AG5+AI5) -> 151.48889 | AV5: =_xlfn.XLOOKUP(AL5,ITEM!B:B,ITEM!BN:BN,0) -> 1 | AW5: 0 | AX5: 0 | AY5: =AU5-AV5-AW5+AX5 -> 150.48889 | AZ5: 0 | BA5: =AZ5/BC5 -> #DIV/0! | BB5: =H5 -> 0 | BC5: 0 | BD5: - | BE5: - | BF5: ★★ | BG5: ★ | BH5: =K5 -> CASTROL Brake Fluid DOT 3 - 500ml | BI5: =AM5 -> 646 | BJ5: =BZ5 -> 0 | BK5: =CK5 -> 1 | BL5: =CV5 -> 0 | BM5: =BJ5+BK5+BL5 -> 1 | BN5: =CC5 -> 55.533333 | BO5: =CN5 -> 94.955556 | BP5: =AY5 -> 150.48889 | BQ5: - | BS5: =K5 -> CASTROL Brake Fluid DOT 3 - 500ml | BT5: =_xlfn.XLOOKUP(BS5,ITEM!B:B,ITEM!BB:BB,0) -> 24.5 | BU5: =_xlfn.XLOOKUP(BS5,ITEM!B:B,ITEM!BC:BC,0) -> 35.272727 | BV5: =BT5/BU5 -> 0.69458763 | BW5: 0 | BX5: =BT5*$AI5 -> 22.866667 | BY5: =BT5*($AE5+$AG5+$AI5) -> 55.533333 | BZ5: =_xlfn.XLOOKUP(BS5,ITEM!B:B,ITEM!BK:BK,0) -> 0 | CA5: 0 | CB5: 0 | CC5: =BY5-BZ5-CA5+CB5 -> 55.533333 | CD5: 0 | CE5: =_xlfn.XLOOKUP(BS5,ITEM!B:B,ITEM!BE:BE,0) -> 42.333333 | CF5: =_xlfn.XLOOKUP(BS5,ITEM!B:B,ITEM!BF:BF,0) -> 42.333333 | CG5: =CE5/CF5 -> 1 | CH5: 0 | CI5: =CE5*$AI5 -> 39.511111 | CJ5: =CE5*($AE5+$AG5+$AI5) -> 95.955556 | CK5: =_xlfn.XLOOKUP(BS5,ITEM!B:B,ITEM!BL:BL,0) -> 1 | CL5: 0 | CM5: 0 | CN5: =CJ5-CK5-CL5+CM5 -> 94.955556 | CO5: 0 | CP5: =_xlfn.XLOOKUP(BS5,ITEM!B:B,ITEM!BH:BH,0) -> 0 | CQ5: =_xlfn.XLOOKUP(BS5,ITEM!B:B,ITEM!BI:BI,0) -> 0 | CR5: =CP5/CQ5 -> #DIV/0! | CS5: 0 | CT5: =CP5*$AI5 -> 0 | CU5: =CP5*($AE5+$AG5+$AI5) -> 0 | CV5: =_xlfn.XLOOKUP(BS5,ITEM!B:B,ITEM!BM:BM,0) -> 0 | CW5: 0 | CX5: 0 | CY5: =CU5-CV5-CW5+CX5 -> 0 | CZ5: 0 | DA5: =K5 -> CASTROL Brake Fluid DOT 3 - 500ml
A6: 8 | B6: 108112 | C6: SHELL | D6: Transmission Oil | E6: Spirax | F6: ATF 6 | G6: 1L | H6: 12*1L | I6: 12 | J6: =C6&" "&D6&" "&E6&" "&F6&" "&G6 -> SHELL Transmission Oil Spirax ATF 6 1L | K6: SHELL Transmission Oil Spirax ATF 6 1L | L6: 1 | M6: 桶 | N6: 65229 | O6: 0.4 | P6: 0.2 | Q6: =O6+P6 -> 0.6 | R6: =N6*(1+Q6) -> 104366.4 | S6: 0 | T6: 0 | U6: 0 | V6: =IF((S6+T6+U6)=0,R6,IF(AND(S6>0,T6=0,U6=0),S6,IF(AND(S6=0,T6>0,U6=0),T6,IF(AND(S6=0,T6=0,U6>0),U6,IF(AND(S6>0,T6>0,U6=0),(S6+T6)/2,IF(AND(S6>0,T6=0,U6>0),(S6+U6)/2,IF(AND(S6=0,T6>0,U6>0),(T6+U6)/2,IF(AND(S6>0,T6>0,U6>0),(S6+T6+U6)/3,)))))))) -> 104366.4 | W6: =IF(R6=V6,V6,IF(R6/V6<70%,R6*1.18,IF(AND(R6/V6>=70%,R6/V6<75%),R6*1.15,IF(AND(R6/V6>=75%,R6/V6<80%),R6*1.12,IF(AND(R6/V6>=80%,R6/V6<85%),R6*1.09,IF(AND(R6/V6>=85%,R6/V6<90%),R6*1.06,IF(AND(R6/V6>=90%,R6/V6<95%),R6*1.03,IF(AND(R6/V6>=95%,R6/V6<105%),V6,IF(AND(R6/V6>=105%,R6/V6<110%),R6*0.97,IF(AND(R6/V6>=110%,R6/V6<115%),R6*0.94,IF(AND(R6/V6>=115%,R6/V6<120%),R6*0.91,IF(AND(R6/V6>=120%,R6/V6<125%),R6*0.88,IF(AND(R6/V6>=125%,R6/V6<130%),R6*0.85,IF(AND(R6/V6>=130%,R6/V6<135%),R6*0.82,IF(R6/V6>=135%,R6*0.8,))))))))))))))) -> 104366.4 | X6: =IF(N6=0,1,IF(N6<10000,N6*2.8,IF(AND(N6>=10000,N6<20000),N6*2.2,IF(AND(N6>=20000,N6<30000),N6*1.8,IF(AND(N6>=30000,N6<40000),N6*1.78,IF(AND(N6>=40000,N6<50000),N6*1.76,IF(AND(N6>=50000,N6<60000),N6*1.74,IF(AND(N6>=60000,N6<70000),N6*1.72,IF(AND(N6>=70000,N6<80000),N6*1.7,IF(AND(N6>=80000,N6<90000),N6*1.68,IF(AND(N6>=90000,N6<100000),N6*1.66,IF(AND(N6>=100000,N6<110000),N6*1.65,IF(AND(N6>=110000,N6<120000),N6*1.64,IF(AND(N6>=120000,N6<130000),N6*1.63,IF(AND(N6>=130000,N6<140000),N6*1.62,IF(AND(N6>=140000,N6<150000),N6*1.61,IF(AND(N6>=150000,N6<160000),N6*1.6,IF(AND(N6>=160000,N6<170000),N6*1.59,IF(AND(N6>=170000,N6<180000),N6*1.58,IF(AND(N6>=180000,N6<190000),N6*1.57,IF(AND(N6>=190000,N6<200000),N6*1.56,IF(AND(N6>=200000,N6<300000),N6*1.54,IF(AND(N6>=300000,N6<400000),N6*1.52,IF(AND(N6>=400000,N6<500000),N6*1.5,IF(AND(N6>=500000,N6<600000),N6*1.48,IF(AND(N6>=600000,N6<700000),N6*1.46,IF(AND(N6>=700000,N6<800000),N6*1.44,IF(AND(N6>=800000,N6<900000),N6*1.42,IF(AND(N6>=900000,N6<1000000),N6*1.4,IF(AND(N6>=1000000,N6<2000000),N6*1.39,IF(AND(N6>=2000000,N6<3000000),N6*1.38,IF(AND(N6>=3000000,N6<4000000),N6*1.37,IF(AND(N6>=4000000,N6<5000000),N6*1.36,IF(AND(N6>=5000000,N6<6000000),N6*1.35,IF(AND(N6>=6000000,N6<7000000),N6*1.34,IF(AND(N6>=7000000,N6<8000000),N6*1.33,IF(AND(N6>=8000000,N6<9000000),N6*1.32,IF(AND(N6>=9000000,N6<10000000),N6*1.31,IF(N6>=10000000,N6*1.3,""))))))))))))))))))))))))))))))))))))))) -> 112193.88 | Y6: =CEILING((R6+W6+X6)/3,1000) -> 107000 | Z6: 0 | AA6: =CEILING((Y6+Z6),1000) -> 107000 | AB6: =AA6-N6 -> 41771 | AC6: =AB6/AA6 -> 0.39038318 | AD6: 30 | AE6: =AD6/30 -> 1 | AF6: 10 | AG6: =AF6/30 -> 0.33333333 | AH6: 0.7 | AI6: =(AE6+AG6)*AH6 -> 0.93333333 | AJ6: =AI6*30 -> 28 | AK6: - | AL6: =K6 -> SHELL Transmission Oil Spirax ATF 6 1L | AM6: =_xlfn.XLOOKUP(AL6,ITEM!B:B,ITEM!AY:AY,0) -> 347 | AN6: =_xlfn.XLOOKUP(AL6,ITEM!B:B,ITEM!AZ:AZ,0) -> 52.333333 | AO6: =_xlfn.XLOOKUP(AL6,ITEM!B:B,ITEM!BA:BA,0) -> 31.545455 | AP6: =AN6/AO6 -> 1.6589817 | AQ6: 0 | AR6: 0 | AS6: 0 | AT6: =AN6*$AI6 -> 48.844444 | AU6: =AN6*(AE6+AG6+AI6) -> 118.62222 | AV6: =_xlfn.XLOOKUP(AL6,ITEM!B:B,ITEM!BN:BN,0) -> 110 | AW6: 0 | AX6: 0 | AY6: =AU6-AV6-AW6+AX6 -> 8.6222222 | AZ6: 60 | BA6: =AZ6/BC6 -> 5 | BB6: =H6 -> 12*1L | BC6: 12 | BD6: - | BE6: - | BF6: ★★★ | BG6: - | BH6: =K6 -> SHELL Transmission Oil Spirax ATF 6 1L | BI6: =AM6 -> 347 | BJ6: =BZ6 -> 3 | BK6: =CK6 -> 59 | BL6: =CV6 -> 48 | BM6: =BJ6+BK6+BL6 -> 110 | BN6: =CC6 -> 77.466667 | BO6: =CN6 -> -20.844444 | BP6: =AY6 -> 8.6222222 | BQ6: 24 | BS6: =K6 -> SHELL Transmission Oil Spirax ATF 6 1L | BT6: =_xlfn.XLOOKUP(BS6,ITEM!B:B,ITEM!BB:BB,0) -> 35.5 | BU6: =_xlfn.XLOOKUP(BS6,ITEM!B:B,ITEM!BC:BC,0) -> 22.363636 | BV6: =BT6/BU6 -> 1.5873984 | BW6: 0 | BX6: =BT6*$AI6 -> 33.133333 | BY6: =BT6*($AE6+$AG6+$AI6) -> 80.466667 | BZ6: =_xlfn.XLOOKUP(BS6,ITEM!B:B,ITEM!BK:BK,0) -> 3 | CA6: 0 | CB6: 0 | CC6: =BY6-BZ6-CA6+CB6 -> 77.466667 | CD6: 0 | CE6: =_xlfn.XLOOKUP(BS6,ITEM!B:B,ITEM!BE:BE,0) -> 16.833333 | CF6: =_xlfn.XLOOKUP(BS6,ITEM!B:B,ITEM!BF:BF,0) -> 16.833333 | CG6: =CE6/CF6 -> 1 | CH6: 0 | CI6: =CE6*$AI6 -> 15.711111 | CJ6: =CE6*($AE6+$AG6+$AI6) -> 38.155556 | CK6: =_xlfn.XLOOKUP(BS6,ITEM!B:B,ITEM!BL:BL,0) -> 59 | CL6: 0 | CM6: 0 | CN6: =CJ6-CK6-CL6+CM6 -> -20.844444 | CO6: 0 | CP6: =_xlfn.XLOOKUP(BS6,ITEM!B:B,ITEM!BH:BH,0) -> 0 | CQ6: =_xlfn.XLOOKUP(BS6,ITEM!B:B,ITEM!BI:BI,0) -> 0 | CR6: =CP6/CQ6 -> #DIV/0! | CS6: 0 | CT6: =CP6*$AI6 -> 0 | CU6: =CP6*($AE6+$AG6+$AI6) -> 0 | CV6: =_xlfn.XLOOKUP(BS6,ITEM!B:B,ITEM!BM:BM,0) -> 48 | CW6: 0 | CX6: 0 | CY6: =CU6-CV6-CW6+CX6 -> -48 | CZ6: 0 | DA6: =K6 -> SHELL Transmission Oil Spirax ATF 6 1L
A7: 3 | B7: 101760 | C7: MOBIL | D7: Gear Oil | E7: Mobilube-HD | F7: 80W-90 | G7: 1L | H7: 12*1L | I7: 12 | J7: =C7&" "&D7&" "&E7&" "&F7&" "&G7 -> MOBIL Gear Oil Mobilube-HD 80W-90 1L | K7: MOBIL Gear Oil Mobilube-HD 80W-90 1L | L7: 1 | M7: 桶 | N7: 51729 | O7: 0.4 | P7: 0.2 | Q7: =O7+P7 -> 0.6 | R7: =N7*(1+Q7) -> 82766.4 | S7: 0 | T7: 0 | U7: 0 | V7: =IF((S7+T7+U7)=0,R7,IF(AND(S7>0,T7=0,U7=0),S7,IF(AND(S7=0,T7>0,U7=0),T7,IF(AND(S7=0,T7=0,U7>0),U7,IF(AND(S7>0,T7>0,U7=0),(S7+T7)/2,IF(AND(S7>0,T7=0,U7>0),(S7+U7)/2,IF(AND(S7=0,T7>0,U7>0),(T7+U7)/2,IF(AND(S7>0,T7>0,U7>0),(S7+T7+U7)/3,)))))))) -> 82766.4 | W7: =IF(R7=V7,V7,IF(R7/V7<70%,R7*1.18,IF(AND(R7/V7>=70%,R7/V7<75%),R7*1.15,IF(AND(R7/V7>=75%,R7/V7<80%),R7*1.12,IF(AND(R7/V7>=80%,R7/V7<85%),R7*1.09,IF(AND(R7/V7>=85%,R7/V7<90%),R7*1.06,IF(AND(R7/V7>=90%,R7/V7<95%),R7*1.03,IF(AND(R7/V7>=95%,R7/V7<105%),V7,IF(AND(R7/V7>=105%,R7/V7<110%),R7*0.97,IF(AND(R7/V7>=110%,R7/V7<115%),R7*0.94,IF(AND(R7/V7>=115%,R7/V7<120%),R7*0.91,IF(AND(R7/V7>=120%,R7/V7<125%),R7*0.88,IF(AND(R7/V7>=125%,R7/V7<130%),R7*0.85,IF(AND(R7/V7>=130%,R7/V7<135%),R7*0.82,IF(R7/V7>=135%,R7*0.8,))))))))))))))) -> 82766.4 | X7: =IF(N7=0,1,IF(N7<10000,N7*2.8,IF(AND(N7>=10000,N7<20000),N7*2.2,IF(AND(N7>=20000,N7<30000),N7*1.8,IF(AND(N7>=30000,N7<40000),N7*1.78,IF(AND(N7>=40000,N7<50000),N7*1.76,IF(AND(N7>=50000,N7<60000),N7*1.74,IF(AND(N7>=60000,N7<70000),N7*1.72,IF(AND(N7>=70000,N7<80000),N7*1.7,IF(AND(N7>=80000,N7<90000),N7*1.68,IF(AND(N7>=90000,N7<100000),N7*1.66,IF(AND(N7>=100000,N7<110000),N7*1.65,IF(AND(N7>=110000,N7<120000),N7*1.64,IF(AND(N7>=120000,N7<130000),N7*1.63,IF(AND(N7>=130000,N7<140000),N7*1.62,IF(AND(N7>=140000,N7<150000),N7*1.61,IF(AND(N7>=150000,N7<160000),N7*1.6,IF(AND(N7>=160000,N7<170000),N7*1.59,IF(AND(N7>=170000,N7<180000),N7*1.58,IF(AND(N7>=180000,N7<190000),N7*1.57,IF(AND(N7>=190000,N7<200000),N7*1.56,IF(AND(N7>=200000,N7<300000),N7*1.54,IF(AND(N7>=300000,N7<400000),N7*1.52,IF(AND(N7>=400000,N7<500000),N7*1.5,IF(AND(N7>=500000,N7<600000),N7*1.48,IF(AND(N7>=600000,N7<700000),N7*1.46,IF(AND(N7>=700000,N7<800000),N7*1.44,IF(AND(N7>=800000,N7<900000),N7*1.42,IF(AND(N7>=900000,N7<1000000),N7*1.4,IF(AND(N7>=1000000,N7<2000000),N7*1.39,IF(AND(N7>=2000000,N7<3000000),N7*1.38,IF(AND(N7>=3000000,N7<4000000),N7*1.37,IF(AND(N7>=4000000,N7<5000000),N7*1.36,IF(AND(N7>=5000000,N7<6000000),N7*1.35,IF(AND(N7>=6000000,N7<7000000),N7*1.34,IF(AND(N7>=7000000,N7<8000000),N7*1.33,IF(AND(N7>=8000000,N7<9000000),N7*1.32,IF(AND(N7>=9000000,N7<10000000),N7*1.31,IF(N7>=10000000,N7*1.3,""))))))))))))))))))))))))))))))))))))))) -> 90008.46 | Y7: =CEILING((R7+W7+X7)/3,1000) -> 86000 | Z7: 0 | AA7: =CEILING((Y7+Z7),1000) -> 86000 | AB7: =AA7-N7 -> 34271 | AC7: =AB7/AA7 -> 0.3985 | AD7: 30 | AE7: =AD7/30 -> 1 | AF7: 10 | AG7: =AF7/30 -> 0.33333333 | AH7: 0.7 | AI7: =(AE7+AG7)*AH7 -> 0.93333333 | AJ7: =AI7*30 -> 28 | AK7: - | AL7: =K7 -> MOBIL Gear Oil Mobilube-HD 80W-90 1L | AM7: =_xlfn.XLOOKUP(AL7,ITEM!B:B,ITEM!AY:AY,0) -> 324 | AN7: =_xlfn.XLOOKUP(AL7,ITEM!B:B,ITEM!AZ:AZ,0) -> 18.333333 | AO7: =_xlfn.XLOOKUP(AL7,ITEM!B:B,ITEM!BA:BA,0) -> 29.181818 | AP7: =AN7/AO7 -> 0.62824507 | AQ7: 0 | AR7: 0 | AS7: 0 | AT7: =AN7*$AI7 -> 17.111111 | AU7: =AN7*(AE7+AG7+AI7) -> 41.555556 | AV7: =_xlfn.XLOOKUP(AL7,ITEM!B:B,ITEM!BN:BN,0) -> 78 | AW7: 0 | AX7: 0 | AY7: =AU7-AV7-AW7+AX7 -> -36.444444 | AZ7: 36 | BA7: =AZ7/BC7 -> 3 | BB7: =H7 -> 12*1L | BC7: 12 | BD7: - | BE7: - | BF7: ★★★ | BG7: - | BH7: =K7 -> MOBIL Gear Oil Mobilube-HD 80W-90 1L | BI7: =AM7 -> 324 | BJ7: =BZ7 -> 25 | BK7: =CK7 -> 17 | BL7: =CV7 -> 36 | BM7: =BJ7+BK7+BL7 -> 78 | BN7: =CC7 -> 9.3777778 | BO7: =CN7 -> -9.8222222 | BP7: =AY7 -> -36.444444 | BQ7: - | BS7: =K7 -> MOBIL Gear Oil Mobilube-HD 80W-90 1L | BT7: =_xlfn.XLOOKUP(BS7,ITEM!B:B,ITEM!BB:BB,0) -> 15.166667 | BU7: =_xlfn.XLOOKUP(BS7,ITEM!B:B,ITEM!BC:BC,0) -> 27.454545 | BV7: =BT7/BU7 -> 0.55242826 | BW7: 0 | BX7: =BT7*$AI7 -> 14.155556 | BY7: =BT7*($AE7+$AG7+$AI7) -> 34.377778 | BZ7: =_xlfn.XLOOKUP(BS7,ITEM!B:B,ITEM!BK:BK,0) -> 25 | CA7: 0 | CB7: 0 | CC7: =BY7-BZ7-CA7+CB7 -> 9.3777778 | CD7: 0 | CE7: =_xlfn.XLOOKUP(BS7,ITEM!B:B,ITEM!BE:BE,0) -> 3.1666667 | CF7: =_xlfn.XLOOKUP(BS7,ITEM!B:B,ITEM!BF:BF,0) -> 3.1666667 | CG7: =CE7/CF7 -> 1 | CH7: 0 | CI7: =CE7*$AI7 -> 2.9555556 | CJ7: =CE7*($AE7+$AG7+$AI7) -> 7.1777778 | CK7: =_xlfn.XLOOKUP(BS7,ITEM!B:B,ITEM!BL:BL,0) -> 17 | CL7: 0 | CM7: 0 | CN7: =CJ7-CK7-CL7+CM7 -> -9.8222222 | CO7: 0 | CP7: =_xlfn.XLOOKUP(BS7,ITEM!B:B,ITEM!BH:BH,0) -> 0 | CQ7: =_xlfn.XLOOKUP(BS7,ITEM!B:B,ITEM!BI:BI,0) -> 0 | CR7: =CP7/CQ7 -> #DIV/0! | CS7: 0 | CT7: =CP7*$AI7 -> 0 | CU7: =CP7*($AE7+$AG7+$AI7) -> 0 | CV7: =_xlfn.XLOOKUP(BS7,ITEM!B:B,ITEM!BM:BM,0) -> 36 | CW7: 0 | CX7: 0 | CY7: =CU7-CV7-CW7+CX7 -> -36 | CZ7: 0 | DA7: =K7 -> MOBIL Gear Oil Mobilube-HD 80W-90 1L
A8: 1 | B8: 108296 | C8: MOBIL | D8: Transmission Oil | E8: CVTF | F8: Multi-Vehicle | G8: 1L | H8: 12*1L | I8: 12 | J8: =C8&" "&D8&" "&E8&" "&F8&" "&G8 -> MOBIL Transmission Oil CVTF Multi-Vehicle 1L | K8: MOBIL Transmission Oil CVTF Multi-Vehicle 1L | L8: 1 | M8: 桶 | N8: 77900 | O8: 0.4 | P8: 0.2 | Q8: =O8+P8 -> 0.6 | R8: =N8*(1+Q8) -> 124640 | S8: 0 | T8: 0 | U8: 0 | V8: =IF((S8+T8+U8)=0,R8,IF(AND(S8>0,T8=0,U8=0),S8,IF(AND(S8=0,T8>0,U8=0),T8,IF(AND(S8=0,T8=0,U8>0),U8,IF(AND(S8>0,T8>0,U8=0),(S8+T8)/2,IF(AND(S8>0,T8=0,U8>0),(S8+U8)/2,IF(AND(S8=0,T8>0,U8>0),(T8+U8)/2,IF(AND(S8>0,T8>0,U8>0),(S8+T8+U8)/3,)))))))) -> 124640 | W8: =IF(R8=V8,V8,IF(R8/V8<70%,R8*1.18,IF(AND(R8/V8>=70%,R8/V8<75%),R8*1.15,IF(AND(R8/V8>=75%,R8/V8<80%),R8*1.12,IF(AND(R8/V8>=80%,R8/V8<85%),R8*1.09,IF(AND(R8/V8>=85%,R8/V8<90%),R8*1.06,IF(AND(R8/V8>=90%,R8/V8<95%),R8*1.03,IF(AND(R8/V8>=95%,R8/V8<105%),V8,IF(AND(R8/V8>=105%,R8/V8<110%),R8*0.97,IF(AND(R8/V8>=110%,R8/V8<115%),R8*0.94,IF(AND(R8/V8>=115%,R8/V8<120%),R8*0.91,IF(AND(R8/V8>=120%,R8/V8<125%),R8*0.88,IF(AND(R8/V8>=125%,R8/V8<130%),R8*0.85,IF(AND(R8/V8>=130%,R8/V8<135%),R8*0.82,IF(R8/V8>=135%,R8*0.8,))))))))))))))) -> 124640 | X8: =IF(N8=0,1,IF(N8<10000,N8*2.8,IF(AND(N8>=10000,N8<20000),N8*2.2,IF(AND(N8>=20000,N8<30000),N8*1.8,IF(AND(N8>=30000,N8<40000),N8*1.78,IF(AND(N8>=40000,N8<50000),N8*1.76,IF(AND(N8>=50000,N8<60000),N8*1.74,IF(AND(N8>=60000,N8<70000),N8*1.72,IF(AND(N8>=70000,N8<80000),N8*1.7,IF(AND(N8>=80000,N8<90000),N8*1.68,IF(AND(N8>=90000,N8<100000),N8*1.66,IF(AND(N8>=100000,N8<110000),N8*1.65,IF(AND(N8>=110000,N8<120000),N8*1.64,IF(AND(N8>=120000,N8<130000),N8*1.63,IF(AND(N8>=130000,N8<140000),N8*1.62,IF(AND(N8>=140000,N8<150000),N8*1.61,IF(AND(N8>=150000,N8<160000),N8*1.6,IF(AND(N8>=160000,N8<170000),N8*1.59,IF(AND(N8>=170000,N8<180000),N8*1.58,IF(AND(N8>=180000,N8<190000),N8*1.57,IF(AND(N8>=190000,N8<200000),N8*1.56,IF(AND(N8>=200000,N8<300000),N8*1.54,IF(AND(N8>=300000,N8<400000),N8*1.52,IF(AND(N8>=400000,N8<500000),N8*1.5,IF(AND(N8>=500000,N8<600000),N8*1.48,IF(AND(N8>=600000,N8<700000),N8*1.46,IF(AND(N8>=700000,N8<800000),N8*1.44,IF(AND(N8>=800000,N8<900000),N8*1.42,IF(AND(N8>=900000,N8<1000000),N8*1.4,IF(AND(N8>=1000000,N8<2000000),N8*1.39,IF(AND(N8>=2000000,N8<3000000),N8*1.38,IF(AND(N8>=3000000,N8<4000000),N8*1.37,IF(AND(N8>=4000000,N8<5000000),N8*1.36,IF(AND(N8>=5000000,N8<6000000),N8*1.35,IF(AND(N8>=6000000,N8<7000000),N8*1.34,IF(AND(N8>=7000000,N8<8000000),N8*1.33,IF(AND(N8>=8000000,N8<9000000),N8*1.32,IF(AND(N8>=9000000,N8<10000000),N8*1.31,IF(N8>=10000000,N8*1.3,""))))))))))))))))))))))))))))))))))))))) -> 132430 | Y8: =CEILING((R8+W8+X8)/3,1000) -> 128000 | Z8: 0 | AA8: =CEILING((Y8+Z8),1000) -> 128000 | AB8: =AA8-N8 -> 50100 | AC8: =AB8/AA8 -> 0.39140625 | AD8: 30 | AE8: =AD8/30 -> 1 | AF8: 10 | AG8: =AF8/30 -> 0.33333333 | AH8: 0.7 | AI8: =(AE8+AG8)*AH8 -> 0.93333333 | AJ8: =AI8*30 -> 28 | AK8: - | AL8: =K8 -> MOBIL Transmission Oil CVTF Multi-Vehicle 1L | AM8: =_xlfn.XLOOKUP(AL8,ITEM!B:B,ITEM!AY:AY,0) -> 288 | AN8: =_xlfn.XLOOKUP(AL8,ITEM!B:B,ITEM!AZ:AZ,0) -> 48 | AO8: =_xlfn.XLOOKUP(AL8,ITEM!B:B,ITEM!BA:BA,0) -> 26.181818 | AP8: =AN8/AO8 -> 1.8333333 | AQ8: 0 | AR8: 0 | AS8: 0 | AT8: =AN8*$AI8 -> 44.8 | AU8: =AN8*(AE8+AG8+AI8) -> 108.8 | AV8: =_xlfn.XLOOKUP(AL8,ITEM!B:B,ITEM!BN:BN,0) -> 66 | AW8: 0 | AX8: 0 | AY8: =AU8-AV8-AW8+AX8 -> 42.8 | AZ8: 120 | BA8: =AZ8/BC8 -> 10 | BB8: =H8 -> 12*1L | BC8: 12 | BD8: - | BE8: - | BF8: ★★★ | BG8: - | BH8: =K8 -> MOBIL Transmission Oil CVTF Multi-Vehicle 1L | BI8: =AM8 -> 288 | BJ8: =BZ8 -> 4 | BK8: =CK8 -> 14 | BL8: =CV8 -> 48 | BM8: =BJ8+BK8+BL8 -> 66 | BN8: =CC8 -> 41.333333 | BO8: =CN8 -> 48.333333 | BP8: =AY8 -> 42.8 | BQ8: 24 | BR8: 24 | BS8: =K8 -> MOBIL Transmission Oil CVTF Multi-Vehicle 1L | BT8: =_xlfn.XLOOKUP(BS8,ITEM!B:B,ITEM!BB:BB,0) -> 20 | BU8: =_xlfn.XLOOKUP(BS8,ITEM!B:B,ITEM!BC:BC,0) -> 10.909091 | BV8: =BT8/BU8 -> 1.8333333 | BW8: 0 | BX8: =BT8*$AI8 -> 18.666667 | BY8: =BT8*($AE8+$AG8+$AI8) -> 45.333333 | BZ8: =_xlfn.XLOOKUP(BS8,ITEM!B:B,ITEM!BK:BK,0) -> 4 | CA8: 0 | CB8: 0 | CC8: =BY8-BZ8-CA8+CB8 -> 41.333333 | CD8: 0 | CE8: =_xlfn.XLOOKUP(BS8,ITEM!B:B,ITEM!BE:BE,0) -> 27.5 | CF8: =_xlfn.XLOOKUP(BS8,ITEM!B:B,ITEM!BF:BF,0) -> 27.5 | CG8: =CE8/CF8 -> 1 | CH8: 0 | CI8: =CE8*$AI8 -> 25.666667 | CJ8: =CE8*($AE8+$AG8+$AI8) -> 62.333333 | CK8: =_xlfn.XLOOKUP(BS8,ITEM!B:B,ITEM!BL:BL,0) -> 14 | CL8: 0 | CM8: 0 | CN8: =CJ8-CK8-CL8+CM8 -> 48.333333 | CO8: 0 | CP8: =_xlfn.XLOOKUP(BS8,ITEM!B:B,ITEM!BH:BH,0) -> 0.5 | CQ8: =_xlfn.XLOOKUP(BS8,ITEM!B:B,ITEM!BI:BI,0) -> 0.5 | CR8: =CP8/CQ8 -> 1 | CS8: 0 | CT8: =CP8*$AI8 -> 0.46666667 | CU8: =CP8*($AE8+$AG8+$AI8) -> 1.1333333 | CV8: =_xlfn.XLOOKUP(BS8,ITEM!B:B,ITEM!BM:BM,0) -> 48 | CW8: 0 | CX8: 0 | CY8: =CU8-CV8-CW8+CX8 -> -46.866667 | CZ8: 0 | DA8: =K8 -> MOBIL Transmission Oil CVTF Multi-Vehicle 1L
A9: 16 | B9: 102253 | C9: PRESTONE | D9: Brake Fluid | E9: DOT 3 | F9: - | G9: 1000ml | H9: 0 | I9: 0 | J9: =C9&" "&D9&" "&E9&" "&F9&" "&G9 -> PRESTONE Brake Fluid DOT 3 - 1000ml | K9: PRESTONE Brake Fluid DOT 3 - 1000ml | L9: 1 | M9: 桶 | N9: 171570 | O9: 0.4 | P9: 0.2 | Q9: =O9+P9 -> 0.6 | R9: =N9*(1+Q9) -> 274512 | S9: 0 | T9: 0 | U9: 0 | V9: =IF((S9+T9+U9)=0,R9,IF(AND(S9>0,T9=0,U9=0),S9,IF(AND(S9=0,T9>0,U9=0),T9,IF(AND(S9=0,T9=0,U9>0),U9,IF(AND(S9>0,T9>0,U9=0),(S9+T9)/2,IF(AND(S9>0,T9=0,U9>0),(S9+U9)/2,IF(AND(S9=0,T9>0,U9>0),(T9+U9)/2,IF(AND(S9>0,T9>0,U9>0),(S9+T9+U9)/3,)))))))) -> 274512 | W9: =IF(R9=V9,V9,IF(R9/V9<70%,R9*1.18,IF(AND(R9/V9>=70%,R9/V9<75%),R9*1.15,IF(AND(R9/V9>=75%,R9/V9<80%),R9*1.12,IF(AND(R9/V9>=80%,R9/V9<85%),R9*1.09,IF(AND(R9/V9>=85%,R9/V9<90%),R9*1.06,IF(AND(R9/V9>=90%,R9/V9<95%),R9*1.03,IF(AND(R9/V9>=95%,R9/V9<105%),V9,IF(AND(R9/V9>=105%,R9/V9<110%),R9*0.97,IF(AND(R9/V9>=110%,R9/V9<115%),R9*0.94,IF(AND(R9/V9>=115%,R9/V9<120%),R9*0.91,IF(AND(R9/V9>=120%,R9/V9<125%),R9*0.88,IF(AND(R9/V9>=125%,R9/V9<130%),R9*0.85,IF(AND(R9/V9>=130%,R9/V9<135%),R9*0.82,IF(R9/V9>=135%,R9*0.8,))))))))))))))) -> 274512 | X9: =IF(N9=0,1,IF(N9<10000,N9*2.8,IF(AND(N9>=10000,N9<20000),N9*2.2,IF(AND(N9>=20000,N9<30000),N9*1.8,IF(AND(N9>=30000,N9<40000),N9*1.78,IF(AND(N9>=40000,N9<50000),N9*1.76,IF(AND(N9>=50000,N9<60000),N9*1.74,IF(AND(N9>=60000,N9<70000),N9*1.72,IF(AND(N9>=70000,N9<80000),N9*1.7,IF(AND(N9>=80000,N9<90000),N9*1.68,IF(AND(N9>=90000,N9<100000),N9*1.66,IF(AND(N9>=100000,N9<110000),N9*1.65,IF(AND(N9>=110000,N9<120000),N9*1.64,IF(AND(N9>=120000,N9<130000),N9*1.63,IF(AND(N9>=130000,N9<140000),N9*1.62,IF(AND(N9>=140000,N9<150000),N9*1.61,IF(AND(N9>=150000,N9<160000),N9*1.6,IF(AND(N9>=160000,N9<170000),N9*1.59,IF(AND(N9>=170000,N9<180000),N9*1.58,IF(AND(N9>=180000,N9<190000),N9*1.57,IF(AND(N9>=190000,N9<200000),N9*1.56,IF(AND(N9>=200000,N9<300000),N9*1.54,IF(AND(N9>=300000,N9<400000),N9*1.52,IF(AND(N9>=400000,N9<500000),N9*1.5,IF(AND(N9>=500000,N9<600000),N9*1.48,IF(AND(N9>=600000,N9<700000),N9*1.46,IF(AND(N9>=700000,N9<800000),N9*1.44,IF(AND(N9>=800000,N9<900000),N9*1.42,IF(AND(N9>=900000,N9<1000000),N9*1.4,IF(AND(N9>=1000000,N9<2000000),N9*1.39,IF(AND(N9>=2000000,N9<3000000),N9*1.38,IF(AND(N9>=3000000,N9<4000000),N9*1.37,IF(AND(N9>=4000000,N9<5000000),N9*1.36,IF(AND(N9>=5000000,N9<6000000),N9*1.35,IF(AND(N9>=6000000,N9<7000000),N9*1.34,IF(AND(N9>=7000000,N9<8000000),N9*1.33,IF(AND(N9>=8000000,N9<9000000),N9*1.32,IF(AND(N9>=9000000,N9<10000000),N9*1.31,IF(N9>=10000000,N9*1.3,""))))))))))))))))))))))))))))))))))))))) -> 271080.6 | Y9: =CEILING((R9+W9+X9)/3,1000) -> 274000 | Z9: 0 | AA9: =CEILING((Y9+Z9),1000) -> 274000 | AB9: =AA9-N9 -> 102430 | AC9: =AB9/AA9 -> 0.37383212 | AD9: 30 | AE9: =AD9/30 -> 1 | AF9: 10 | AG9: =AF9/30 -> 0.33333333 | AH9: 0.7 | AI9: =(AE9+AG9)*AH9 -> 0.93333333 | AJ9: =AI9*30 -> 28 | AK9: - | AL9: =K9 -> PRESTONE Brake Fluid DOT 3 - 1000ml | AM9: =_xlfn.XLOOKUP(AL9,ITEM!B:B,ITEM!AY:AY,0) -> 277 | AN9: =_xlfn.XLOOKUP(AL9,ITEM!B:B,ITEM!AZ:AZ,0) -> 35.833333 | AO9: =_xlfn.XLOOKUP(AL9,ITEM!B:B,ITEM!BA:BA,0) -> 25.181818 | AP9: =AN9/AO9 -> 1.4229844 | AQ9: 0 | AR9: 0 | AS9: 0 | AT9: =AN9*$AI9 -> 33.444444 | AU9: =AN9*(AE9+AG9+AI9) -> 81.222222 | AV9: =_xlfn.XLOOKUP(AL9,ITEM!B:B,ITEM!BN:BN,0) -> 0 | AW9: 0 | AX9: 0 | AY9: =AU9-AV9-AW9+AX9 -> 81.222222 | AZ9: 0 | BA9: =AZ9/BC9 -> #DIV/0! | BB9: =H9 -> 0 | BC9: 0 | BD9: - | BE9: - | BF9: ★ | BG9: ★ | BH9: =K9 -> PRESTONE Brake Fluid DOT 3 - 1000ml | BI9: =AM9 -> 277 | BJ9: =BZ9 -> 0 | BK9: =CK9 -> 0 | BL9: =CV9 -> 0 | BM9: =BJ9+BK9+BL9 -> 0 | BN9: =CC9 -> 60.444444 | BO9: =CN9 -> 20.777778 | BP9: =AY9 -> 81.222222 | BQ9: - | BS9: =K9 -> PRESTONE Brake Fluid DOT 3 - 1000ml | BT9: =_xlfn.XLOOKUP(BS9,ITEM!B:B,ITEM!BB:BB,0) -> 26.666667 | BU9: =_xlfn.XLOOKUP(BS9,ITEM!B:B,ITEM!BC:BC,0) -> 20.181818 | BV9: =BT9/BU9 -> 1.3213213 | BW9: 0 | BX9: =BT9*$AI9 -> 24.888889 | BY9: =BT9*($AE9+$AG9+$AI9) -> 60.444444 | BZ9: =_xlfn.XLOOKUP(BS9,ITEM!B:B,ITEM!BK:BK,0) -> 0 | CA9: 0 | CB9: 0 | CC9: =BY9-BZ9-CA9+CB9 -> 60.444444 | CD9: 0 | CE9: =_xlfn.XLOOKUP(BS9,ITEM!B:B,ITEM!BE:BE,0) -> 9.1666667 | CF9: =_xlfn.XLOOKUP(BS9,ITEM!B:B,ITEM!BF:BF,0) -> 9.1666667 | CG9: =CE9/CF9 -> 1 | CH9: 0 | CI9: =CE9*$AI9 -> 8.5555556 | CJ9: =CE9*($AE9+$AG9+$AI9) -> 20.777778 | CK9: =_xlfn.XLOOKUP(BS9,ITEM!B:B,ITEM!BL:BL,0) -> 0 | CL9: 0 | CM9: 0 | CN9: =CJ9-CK9-CL9+CM9 -> 20.777778 | CO9: 0 | CP9: =_xlfn.XLOOKUP(BS9,ITEM!B:B,ITEM!BH:BH,0) -> 0 | CQ9: =_xlfn.XLOOKUP(BS9,ITEM!B:B,ITEM!BI:BI,0) -> 0 | CR9: =CP9/CQ9 -> #DIV/0! | CS9: 0 | CT9: =CP9*$AI9 -> 0 | CU9: =CP9*($AE9+$AG9+$AI9) -> 0 | CV9: =_xlfn.XLOOKUP(BS9,ITEM!B:B,ITEM!BM:BM,0) -> 0 | CW9: 0 | CX9: 0 | CY9: =CU9-CV9-CW9+CX9 -> 0 | CZ9: 0 | DA9: =K9 -> PRESTONE Brake Fluid DOT 3 - 1000ml
A10: 10 | B10: 108237 | C10: SHELL | D10: Axle Oil | E10: Spirax | F10: S2 A 80W-90 | G10: 1L | H10: 12*1L | I10: 12 | J10: =C10&" "&D10&" "&E10&" "&F10&" "&G10 -> SHELL Axle Oil Spirax S2 A 80W-90 1L | K10: SHELL Axle Oil Spirax S2 A 80W-90 1L | L10: 1 | M10: 桶 | N10: 51524 | O10: 0.4 | P10: 0.2 | Q10: =O10+P10 -> 0.6 | R10: =N10*(1+Q10) -> 82438.4 | S10: 0 | T10: 0 | U10: 0 | V10: =IF((S10+T10+U10)=0,R10,IF(AND(S10>0,T10=0,U10=0),S10,IF(AND(S10=0,T10>0,U10=0),T10,IF(AND(S10=0,T10=0,U10>0),U10,IF(AND(S10>0,T10>0,U10=0),(S10+T10)/2,IF(AND(S10>0,T10=0,U10>0),(S10+U10)/2,IF(AND(S10=0,T10>0,U10>0),(T10+U10)/2,IF(AND(S10>0,T10>0,U10>0),(S10+T10+U10)/3,)))))))) -> 82438.4 | W10: =IF(R10=V10,V10,IF(R10/V10<70%,R10*1.18,IF(AND(R10/V10>=70%,R10/V10<75%),R10*1.15,IF(AND(R10/V10>=75%,R10/V10<80%),R10*1.12,IF(AND(R10/V10>=80%,R10/V10<85%),R10*1.09,IF(AND(R10/V10>=85%,R10/V10<90%),R10*1.06,IF(AND(R10/V10>=90%,R10/V10<95%),R10*1.03,IF(AND(R10/V10>=95%,R10/V10<105%),V10,IF(AND(R10/V10>=105%,R10/V10<110%),R10*0.97,IF(AND(R10/V10>=110%,R10/V10<115%),R10*0.94,IF(AND(R10/V10>=115%,R10/V10<120%),R10*0.91,IF(AND(R10/V10>=120%,R10/V10<125%),R10*0.88,IF(AND(R10/V10>=125%,R10/V10<130%),R10*0.85,IF(AND(R10/V10>=130%,R10/V10<135%),R10*0.82,IF(R10/V10>=135%,R10*0.8,))))))))))))))) -> 82438.4 | X10: =IF(N10=0,1,IF(N10<10000,N10*2.8,IF(AND(N10>=10000,N10<20000),N10*2.2,IF(AND(N10>=20000,N10<30000),N10*1.8,IF(AND(N10>=30000,N10<40000),N10*1.78,IF(AND(N10>=40000,N10<50000),N10*1.76,IF(AND(N10>=50000,N10<60000),N10*1.74,IF(AND(N10>=60000,N10<70000),N10*1.72,IF(AND(N10>=70000,N10<80000),N10*1.7,IF(AND(N10>=80000,N10<90000),N10*1.68,IF(AND(N10>=90000,N10<100000),N10*1.66,IF(AND(N10>=100000,N10<110000),N10*1.65,IF(AND(N10>=110000,N10<120000),N10*1.64,IF(AND(N10>=120000,N10<130000),N10*1.63,IF(AND(N10>=130000,N10<140000),N10*1.62,IF(AND(N10>=140000,N10<150000),N10*1.61,IF(AND(N10>=150000,N10<160000),N10*1.6,IF(AND(N10>=160000,N10<170000),N10*1.59,IF(AND(N10>=170000,N10<180000),N10*1.58,IF(AND(N10>=180000,N10<190000),N10*1.57,IF(AND(N10>=190000,N10<200000),N10*1.56,IF(AND(N10>=200000,N10<300000),N10*1.54,IF(AND(N10>=300000,N10<400000),N10*1.52,IF(AND(N10>=400000,N10<500000),N10*1.5,IF(AND(N10>=500000,N10<600000),N10*1.48,IF(AND(N10>=600000,N10<700000),N10*1.46,IF(AND(N10>=700000,N10<800000),N10*1.44,IF(AND(N10>=800000,N10<900000),N10*1.42,IF(AND(N10>=900000,N10<1000000),N10*1.4,IF(AND(N10>=1000000,N10<2000000),N10*1.39,IF(AND(N10>=2000000,N10<3000000),N10*1.38,IF(AND(N10>=3000000,N10<4000000),N10*1.37,IF(AND(N10>=4000000,N10<5000000),N10*1.36,IF(AND(N10>=5000000,N10<6000000),N10*1.35,IF(AND(N10>=6000000,N10<7000000),N10*1.34,IF(AND(N10>=7000000,N10<8000000),N10*1.33,IF(AND(N10>=8000000,N10<9000000),N10*1.32,IF(AND(N10>=9000000,N10<10000000),N10*1.31,IF(N10>=10000000,N10*1.3,""))))))))))))))))))))))))))))))))))))))) -> 89651.76 | Y10: =CEILING((R10+W10+X10)/3,1000) -> 85000 | Z10: 0 | AA10: =CEILING((Y10+Z10),1000) -> 85000 | AB10: =AA10-N10 -> 33476 | AC10: =AB10/AA10 -> 0.39383529 | AD10: 30 | AE10: =AD10/30 -> 1 | AF10: 10 | AG10: =AF10/30 -> 0.33333333 | AH10: 0.7 | AI10: =(AE10+AG10)*AH10 -> 0.93333333 | AJ10: =AI10*30 -> 28 | AK10: - | AL10: =K10 -> SHELL Axle Oil Spirax S2 A 80W-90 1L | AM10: =_xlfn.XLOOKUP(AL10,ITEM!B:B,ITEM!AY:AY,0) -> 276 | AN10: =_xlfn.XLOOKUP(AL10,ITEM!B:B,ITEM!AZ:AZ,0) -> 46 | AO10: =_xlfn.XLOOKUP(AL10,ITEM!B:B,ITEM!BA:BA,0) -> 25.090909 | AP10: =AN10/AO10 -> 1.8333333 | AQ10: 0 | AR10: 0 | AS10: 0 | AT10: =AN10*$AI10 -> 42.933333 | AU10: =AN10*(AE10+AG10+AI10) -> 104.26667 | AV10: =_xlfn.XLOOKUP(AL10,ITEM!B:B,ITEM!BN:BN,0) -> 109 | AW10: 0 | AX10: 0 | AY10: =AU10-AV10-AW10+AX10 -> -4.7333333 | AZ10: 24 | BA10: =AZ10/BC10 -> 2 | BB10: =H10 -> 12*1L | BC10: 12 | BD10: - | BE10: - | BF10: ★★★ | BG10: - | BH10: =K10 -> SHELL Axle Oil Spirax S2 A 80W-90 1L | BI10: =AM10 -> 276 | BJ10: =BZ10 -> 13 | BK10: =CK10 -> 48 | BL10: =CV10 -> 48 | BM10: =BJ10+BK10+BL10 -> 109 | BN10: =CC10 -> 44.422222 | BO10: =CN10 -> -1.1555556 | BP10: =AY10 -> -4.7333333 | BQ10: 24 | BS10: =K10 -> SHELL Axle Oil Spirax S2 A 80W-90 1L | BT10: =_xlfn.XLOOKUP(BS10,ITEM!B:B,ITEM!BB:BB,0) -> 25.333333 | BU10: =_xlfn.XLOOKUP(BS10,ITEM!B:B,ITEM!BC:BC,0) -> 13.818182 | BV10: =BT10/BU10 -> 1.8333333 | BW10: 0 | BX10: =BT10*$AI10 -> 23.644444 | BY10: =BT10*($AE10+$AG10+$AI10) -> 57.422222 | BZ10: =_xlfn.XLOOKUP(BS10,ITEM!B:B,ITEM!BK:BK,0) -> 13 | CA10: 0 | CB10: 0 | CC10: =BY10-BZ10-CA10+CB10 -> 44.422222 | CD10: 0 | CE10: =_xlfn.XLOOKUP(BS10,ITEM!B:B,ITEM!BE:BE,0) -> 20.666667 | CF10: =_xlfn.XLOOKUP(BS10,ITEM!B:B,ITEM!BF:BF,0) -> 20.666667 | CG10: =CE10/CF10 -> 1 | CH10: 0 | CI10: =CE10*$AI10 -> 19.288889 | CJ10: =CE10*($AE10+$AG10+$AI10) -> 46.844444 | CK10: =_xlfn.XLOOKUP(BS10,ITEM!B:B,ITEM!BL:BL,0) -> 48 | CL10: 0 | CM10: 0 | CN10: =CJ10-CK10-CL10+CM10 -> -1.1555556 | CO10: 0 | CP10: =_xlfn.XLOOKUP(BS10,ITEM!B:B,ITEM!BH:BH,0) -> 0 | CQ10: =_xlfn.XLOOKUP(BS10,ITEM!B:B,ITEM!BI:BI,0) -> 0 | CR10: =CP10/CQ10 -> #DIV/0! | CS10: 0 | CT10: =CP10*$AI10 -> 0 | CU10: =CP10*($AE10+$AG10+$AI10) -> 0 | CV10: =_xlfn.XLOOKUP(BS10,ITEM!B:B,ITEM!BM:BM,0) -> 48 | CW10: 0 | CX10: 0 | CY10: =CU10-CV10-CW10+CX10 -> -48 | CZ10: 0 | DA10: =K10 -> SHELL Axle Oil Spirax S2 A 80W-90 1L
A11: 13 | B11: 101754 | C11: CASTROL | D11: Brake Fluid | E11: DOT 4 | F11: - | G11: 500ml | H11: 0 | I11: 0 | J11: =C11&" "&D11&" "&E11&" "&F11&" "&G11 -> CASTROL Brake Fluid DOT 4 - 500ml | K11: CASTROL Brake Fluid DOT 4 - 500ml | L11: 1 | M11: 桶 | N11: 65100 | O11: 0.4 | P11: 0.2 | Q11: =O11+P11 -> 0.6 | R11: =N11*(1+Q11) -> 104160 | S11: 0 | T11: 0 | U11: 0 | V11: =IF((S11+T11+U11)=0,R11,IF(AND(S11>0,T11=0,U11=0),S11,IF(AND(S11=0,T11>0,U11=0),T11,IF(AND(S11=0,T11=0,U11>0),U11,IF(AND(S11>0,T11>0,U11=0),(S11+T11)/2,IF(AND(S11>0,T11=0,U11>0),(S11+U11)/2,IF(AND(S11=0,T11>0,U11>0),(T11+U11)/2,IF(AND(S11>0,T11>0,U11>0),(S11+T11+U11)/3,)))))))) -> 104160 | W11: =IF(R11=V11,V11,IF(R11/V11<70%,R11*1.18,IF(AND(R11/V11>=70%,R11/V11<75%),R11*1.15,IF(AND(R11/V11>=75%,R11/V11<80%),R11*1.12,IF(AND(R11/V11>=80%,R11/V11<85%),R11*1.09,IF(AND(R11/V11>=85%,R11/V11<90%),R11*1.06,IF(AND(R11/V11>=90%,R11/V11<95%),R11*1.03,IF(AND(R11/V11>=95%,R11/V11<105%),V11,IF(AND(R11/V11>=105%,R11/V11<110%),R11*0.97,IF(AND(R11/V11>=110%,R11/V11<115%),R11*0.94,IF(AND(R11/V11>=115%,R11/V11<120%),R11*0.91,IF(AND(R11/V11>=120%,R11/V11<125%),R11*0.88,IF(AND(R11/V11>=125%,R11/V11<130%),R11*0.85,IF(AND(R11/V11>=130%,R11/V11<135%),R11*0.82,IF(R11/V11>=135%,R11*0.8,))))))))))))))) -> 104160 | X11: =IF(N11=0,1,IF(N11<10000,N11*2.8,IF(AND(N11>=10000,N11<20000),N11*2.2,IF(AND(N11>=20000,N11<30000),N11*1.8,IF(AND(N11>=30000,N11<40000),N11*1.78,IF(AND(N11>=40000,N11<50000),N11*1.76,IF(AND(N11>=50000,N11<60000),N11*1.74,IF(AND(N11>=60000,N11<70000),N11*1.72,IF(AND(N11>=70000,N11<80000),N11*1.7,IF(AND(N11>=80000,N11<90000),N11*1.68,IF(AND(N11>=90000,N11<100000),N11*1.66,IF(AND(N11>=100000,N11<110000),N11*1.65,IF(AND(N11>=110000,N11<120000),N11*1.64,IF(AND(N11>=120000,N11<130000),N11*1.63,IF(AND(N11>=130000,N11<140000),N11*1.62,IF(AND(N11>=140000,N11<150000),N11*1.61,IF(AND(N11>=150000,N11<160000),N11*1.6,IF(AND(N11>=160000,N11<170000),N11*1.59,IF(AND(N11>=170000,N11<180000),N11*1.58,IF(AND(N11>=180000,N11<190000),N11*1.57,IF(AND(N11>=190000,N11<200000),N11*1.56,IF(AND(N11>=200000,N11<300000),N11*1.54,IF(AND(N11>=300000,N11<400000),N11*1.52,IF(AND(N11>=400000,N11<500000),N11*1.5,IF(AND(N11>=500000,N11<600000),N11*1.48,IF(AND(N11>=600000,N11<700000),N11*1.46,IF(AND(N11>=700000,N11<800000),N11*1.44,IF(AND(N11>=800000,N11<900000),N11*1.42,IF(AND(N11>=900000,N11<1000000),N11*1.4,IF(AND(N11>=1000000,N11<2000000),N11*1.39,IF(AND(N11>=2000000,N11<3000000),N11*1.38,IF(AND(N11>=3000000,N11<4000000),N11*1.37,IF(AND(N11>=4000000,N11<5000000),N11*1.36,IF(AND(N11>=5000000,N11<6000000),N11*1.35,IF(AND(N11>=6000000,N11<7000000),N11*1.34,IF(AND(N11>=7000000,N11<8000000),N11*1.33,IF(AND(N11>=8000000,N11<9000000),N11*1.32,IF(AND(N11>=9000000,N11<10000000),N11*1.31,IF(N11>=10000000,N11*1.3,""))))))))))))))))))))))))))))))))))))))) -> 111972 | Y11: =CEILING((R11+W11+X11)/3,1000) -> 107000 | Z11: 0 | AA11: =CEILING((Y11+Z11),1000) -> 107000 | AB11: =AA11-N11 -> 41900 | AC11: =AB11/AA11 -> 0.39158879 | AD11: 30 | AE11: =AD11/30 -> 1 | AF11: 10 | AG11: =AF11/30 -> 0.33333333 | AH11: 0.7 | AI11: =(AE11+AG11)*AH11 -> 0.93333333 | AJ11: =AI11*30 -> 28 | AK11: - | AL11: =K11 -> CASTROL Brake Fluid DOT 4 - 500ml | AM11: =_xlfn.XLOOKUP(AL11,ITEM!B:B,ITEM!AY:AY,0) -> 267 | AN11: =_xlfn.XLOOKUP(AL11,ITEM!B:B,ITEM!AZ:AZ,0) -> 32.833333 | AO11: =_xlfn.XLOOKUP(AL11,ITEM!B:B,ITEM!BA:BA,0) -> 24.272727 | AP11: =AN11/AO11 -> 1.3526841 | AQ11: 0 | AR11: 0 | AS11: 0 | AT11: =AN11*$AI11 -> 30.644444 | AU11: =AN11*(AE11+AG11+AI11) -> 74.422222 | AV11: =_xlfn.XLOOKUP(AL11,ITEM!B:B,ITEM!BN:BN,0) -> 53 | AW11: 0 | AX11: 0 | AY11: =AU11-AV11-AW11+AX11 -> 21.422222 | AZ11: 0 | BA11: =AZ11/BC11 -> #DIV/0! | BB11: =H11 -> 0 | BC11: 0 | BD11: - | BE11: - | BF11: ★★ | BG11: ★★ | BH11: =K11 -> CASTROL Brake Fluid DOT 4 - 500ml | BI11: =AM11 -> 267 | BJ11: =BZ11 -> 19 | BK11: =CK11 -> 22 | BL11: =CV11 -> 12 | BM11: =BJ11+BK11+BL11 -> 53 | BN11: =CC11 -> 5.5555556 | BO11: =CN11 -> 27.866667 | BP11: =AY11 -> 21.422222 | BQ11: - | BS11: =K11 -> CASTROL Brake Fluid DOT 4 - 500ml | BT11: =_xlfn.XLOOKUP(BS11,ITEM!B:B,ITEM!BB:BB,0) -> 10.833333 | BU11: =_xlfn.XLOOKUP(BS11,ITEM!B:B,ITEM!BC:BC,0) -> 12.272727 | BV11: =BT11/BU11 -> 0.88271605 | BW11: 0 | BX11: =BT11*$AI11 -> 10.111111 | BY11: =BT11*($AE11+$AG11+$AI11) -> 24.555556 | BZ11: =_xlfn.XLOOKUP(BS11,ITEM!B:B,ITEM!BK:BK,0) -> 19 | CA11: 0 | CB11: 0 | CC11: =BY11-BZ11-CA11+CB11 -> 5.5555556 | CD11: 0 | CE11: =_xlfn.XLOOKUP(BS11,ITEM!B:B,ITEM!BE:BE,0) -> 22 | CF11: =_xlfn.XLOOKUP(BS11,ITEM!B:B,ITEM!BF:BF,0) -> 22 | CG11: =CE11/CF11 -> 1 | CH11: 0 | CI11: =CE11*$AI11 -> 20.533333 | CJ11: =CE11*($AE11+$AG11+$AI11) -> 49.866667 | CK11: =_xlfn.XLOOKUP(BS11,ITEM!B:B,ITEM!BL:BL,0) -> 22 | CL11: 0 | CM11: 0 | CN11: =CJ11-CK11-CL11+CM11 -> 27.866667 | CO11: 0 | CP11: =_xlfn.XLOOKUP(BS11,ITEM!B:B,ITEM!BH:BH,0) -> 0 | CQ11: =_xlfn.XLOOKUP(BS11,ITEM!B:B,ITEM!BI:BI,0) -> 0 | CR11: =CP11/CQ11 -> #DIV/0! | CS11: 0 | CT11: =CP11*$AI11 -> 0 | CU11: =CP11*($AE11+$AG11+$AI11) -> 0 | CV11: =_xlfn.XLOOKUP(BS11,ITEM!B:B,ITEM!BM:BM,0) -> 12 | CW11: 0 | CX11: 0 | CY11: =CU11-CV11-CW11+CX11 -> -12 | CZ11: 0 | DA11: =K11 -> CASTROL Brake Fluid DOT 4 - 500ml
A12: 11 | B12: 108238 | C12: SHELL | D12: Gear Oil | E12: Spirax | F12: S2 G 80W-90 | G12: 1L | H12: 12*1L | I12: 12 | J12: =C12&" "&D12&" "&E12&" "&F12&" "&G12 -> SHELL Gear Oil Spirax S2 G 80W-90 1L | K12: SHELL Gear Oil Spirax S2 G 80W-90 1L | L12: 1 | M12: 桶 | N12: 51414 | O12: 0.4 | P12: 0.2 | Q12: =O12+P12 -> 0.6 | R12: =N12*(1+Q12) -> 82262.4 | S12: 0 | T12: 0 | U12: 0 | V12: =IF((S12+T12+U12)=0,R12,IF(AND(S12>0,T12=0,U12=0),S12,IF(AND(S12=0,T12>0,U12=0),T12,IF(AND(S12=0,T12=0,U12>0),U12,IF(AND(S12>0,T12>0,U12=0),(S12+T12)/2,IF(AND(S12>0,T12=0,U12>0),(S12+U12)/2,IF(AND(S12=0,T12>0,U12>0),(T12+U12)/2,IF(AND(S12>0,T12>0,U12>0),(S12+T12+U12)/3,)))))))) -> 82262.4 | W12: =IF(R12=V12,V12,IF(R12/V12<70%,R12*1.18,IF(AND(R12/V12>=70%,R12/V12<75%),R12*1.15,IF(AND(R12/V12>=75%,R12/V12<80%),R12*1.12,IF(AND(R12/V12>=80%,R12/V12<85%),R12*1.09,IF(AND(R12/V12>=85%,R12/V12<90%),R12*1.06,IF(AND(R12/V12>=90%,R12/V12<95%),R12*1.03,IF(AND(R12/V12>=95%,R12/V12<105%),V12,IF(AND(R12/V12>=105%,R12/V12<110%),R12*0.97,IF(AND(R12/V12>=110%,R12/V12<115%),R12*0.94,IF(AND(R12/V12>=115%,R12/V12<120%),R12*0.91,IF(AND(R12/V12>=120%,R12/V12<125%),R12*0.88,IF(AND(R12/V12>=125%,R12/V12<130%),R12*0.85,IF(AND(R12/V12>=130%,R12/V12<135%),R12*0.82,IF(R12/V12>=135%,R12*0.8,))))))))))))))) -> 82262.4 | X12: =IF(N12=0,1,IF(N12<10000,N12*2.8,IF(AND(N12>=10000,N12<20000),N12*2.2,IF(AND(N12>=20000,N12<30000),N12*1.8,IF(AND(N12>=30000,N12<40000),N12*1.78,IF(AND(N12>=40000,N12<50000),N12*1.76,IF(AND(N12>=50000,N12<60000),N12*1.74,IF(AND(N12>=60000,N12<70000),N12*1.72,IF(AND(N12>=70000,N12<80000),N12*1.7,IF(AND(N12>=80000,N12<90000),N12*1.68,IF(AND(N12>=90000,N12<100000),N12*1.66,IF(AND(N12>=100000,N12<110000),N12*1.65,IF(AND(N12>=110000,N12<120000),N12*1.64,IF(AND(N12>=120000,N12<130000),N12*1.63,IF(AND(N12>=130000,N12<140000),N12*1.62,IF(AND(N12>=140000,N12<150000),N12*1.61,IF(AND(N12>=150000,N12<160000),N12*1.6,IF(AND(N12>=160000,N12<170000),N12*1.59,IF(AND(N12>=170000,N12<180000),N12*1.58,IF(AND(N12>=180000,N12<190000),N12*1.57,IF(AND(N12>=190000,N12<200000),N12*1.56,IF(AND(N12>=200000,N12<300000),N12*1.54,IF(AND(N12>=300000,N12<400000),N12*1.52,IF(AND(N12>=400000,N12<500000),N12*1.5,IF(AND(N12>=500000,N12<600000),N12*1.48,IF(AND(N12>=600000,N12<700000),N12*1.46,IF(AND(N12>=700000,N12<800000),N12*1.44,IF(AND(N12>=800000,N12<900000),N12*1.42,IF(AND(N12>=900000,N12<1000000),N12*1.4,IF(AND(N12>=1000000,N12<2000000),N12*1.39,IF(AND(N12>=2000000,N12<3000000),N12*1.38,IF(AND(N12>=3000000,N12<4000000),N12*1.37,IF(AND(N12>=4000000,N12<5000000),N12*1.36,IF(AND(N12>=5000000,N12<6000000),N12*1.35,IF(AND(N12>=6000000,N12<7000000),N12*1.34,IF(AND(N12>=7000000,N12<8000000),N12*1.33,IF(AND(N12>=8000000,N12<9000000),N12*1.32,IF(AND(N12>=9000000,N12<10000000),N12*1.31,IF(N12>=10000000,N12*1.3,""))))))))))))))))))))))))))))))))))))))) -> 89460.36 | Y12: =CEILING((R12+W12+X12)/3,1000) -> 85000 | Z12: 0 | AA12: =CEILING((Y12+Z12),1000) -> 85000 | AB12: =AA12-N12 -> 33586 | AC12: =AB12/AA12 -> 0.39512941 | AD12: 30 | AE12: =AD12/30 -> 1 | AF12: 10 | AG12: =AF12/30 -> 0.33333333 | AH12: 0.7 | AI12: =(AE12+AG12)*AH12 -> 0.93333333 | AJ12: =AI12*30 -> 28 | AK12: - | AL12: =K12 -> SHELL Gear Oil Spirax S2 G 80W-90 1L | AM12: =_xlfn.XLOOKUP(AL12,ITEM!B:B,ITEM!AY:AY,0) -> 242 | AN12: =_xlfn.XLOOKUP(AL12,ITEM!B:B,ITEM!AZ:AZ,0) -> 40.333333 | AO12: =_xlfn.XLOOKUP(AL12,ITEM!B:B,ITEM!BA:BA,0) -> 22 | AP12: =AN12/AO12 -> 1.8333333 | AQ12: 0 | AR12: 0 | AS12: 0 | AT12: =AN12*$AI12 -> 37.644444 | AU12: =AN12*(AE12+AG12+AI12) -> 91.422222 | AV12: =_xlfn.XLOOKUP(AL12,ITEM!B:B,ITEM!BN:BN,0) -> 73 | AW12: 0 | AX12: 0 | AY12: =AU12-AV12-AW12+AX12 -> 18.422222 | AZ12: 60 | BA12: =AZ12/BC12 -> 5 | BB12: =H12 -> 12*1L | BC12: 12 | BD12: - | BE12: - | BF12: ★★★ | BG12: - | BH12: =K12 -> SHELL Gear Oil Spirax S2 G 80W-90 1L | BI12: =AM12 -> 242 | BJ12: =BZ12 -> 16 | BK12: =CK12 -> 32 | BL12: =CV12 -> 25 | BM12: =BJ12+BK12+BL12 -> 73 | BN12: =CC12 -> 37.266667 | BO12: =CN12 -> 6.1555556 | BP12: =AY12 -> 18.422222 | BQ12: - | BS12: =K12 -> SHELL Gear Oil Spirax S2 G 80W-90 1L | BT12: =_xlfn.XLOOKUP(BS12,ITEM!B:B,ITEM!BB:BB,0) -> 23.5 | BU12: =_xlfn.XLOOKUP(BS12,ITEM!B:B,ITEM!BC:BC,0) -> 12.818182 | BV12: =BT12/BU12 -> 1.8333333 | BW12: 0 | BX12: =BT12*$AI12 -> 21.933333 | BY12: =BT12*($AE12+$AG12+$AI12) -> 53.266667 | BZ12: =_xlfn.XLOOKUP(BS12,ITEM!B:B,ITEM!BK:BK,0) -> 16 | CA12: 0 | CB12: 0 | CC12: =BY12-BZ12-CA12+CB12 -> 37.266667 | CD12: 0 | CE12: =_xlfn.XLOOKUP(BS12,ITEM!B:B,ITEM!BE:BE,0) -> 16.833333 | CF12: =_xlfn.XLOOKUP(BS12,ITEM!B:B,ITEM!BF:BF,0) -> 16.833333 | CG12: =CE12/CF12 -> 1 | CH12: 0 | CI12: =CE12*$AI12 -> 15.711111 | CJ12: =CE12*($AE12+$AG12+$AI12) -> 38.155556 | CK12: =_xlfn.XLOOKUP(BS12,ITEM!B:B,ITEM!BL:BL,0) -> 32 | CL12: 0 | CM12: 0 | CN12: =CJ12-CK12-CL12+CM12 -> 6.1555556 | CO12: 0 | CP12: =_xlfn.XLOOKUP(BS12,ITEM!B:B,ITEM!BH:BH,0) -> 0 | CQ12: =_xlfn.XLOOKUP(BS12,ITEM!B:B,ITEM!BI:BI,0) -> 0 | CR12: =CP12/CQ12 -> #DIV/0! | CS12: 0 | CT12: =CP12*$AI12 -> 0 | CU12: =CP12*($AE12+$AG12+$AI12) -> 0 | CV12: =_xlfn.XLOOKUP(BS12,ITEM!B:B,ITEM!BM:BM,0) -> 25 | CW12: 0 | CX12: 0 | CY12: =CU12-CV12-CW12+CX12 -> -25 | CZ12: 0 | DA12: =K12 -> SHELL Gear Oil Spirax S2 G 80W-90 1L
A13: 9 | B13: 108111 | C13: SHELL | D13: Transmission Oil | E13: Spirax | F13: S5 CVTX | G13: 1L | H13: 12*1L | I13: 12 | J13: =C13&" "&D13&" "&E13&" "&F13&" "&G13 -> SHELL Transmission Oil Spirax S5 CVTX 1L | K13: SHELL Transmission Oil Spirax S5 CVTX 1L | L13: 1 | M13: 桶 | N13: 77510 | O13: 0.4 | P13: 0.2 | Q13: =O13+P13 -> 0.6 | R13: =N13*(1+Q13) -> 124016 | S13: 0 | T13: 0 | U13: 0 | V13: =IF((S13+T13+U13)=0,R13,IF(AND(S13>0,T13=0,U13=0),S13,IF(AND(S13=0,T13>0,U13=0),T13,IF(AND(S13=0,T13=0,U13>0),U13,IF(AND(S13>0,T13>0,U13=0),(S13+T13)/2,IF(AND(S13>0,T13=0,U13>0),(S13+U13)/2,IF(AND(S13=0,T13>0,U13>0),(T13+U13)/2,IF(AND(S13>0,T13>0,U13>0),(S13+T13+U13)/3,)))))))) -> 124016 | W13: =IF(R13=V13,V13,IF(R13/V13<70%,R13*1.18,IF(AND(R13/V13>=70%,R13/V13<75%),R13*1.15,IF(AND(R13/V13>=75%,R13/V13<80%),R13*1.12,IF(AND(R13/V13>=80%,R13/V13<85%),R13*1.09,IF(AND(R13/V13>=85%,R13/V13<90%),R13*1.06,IF(AND(R13/V13>=90%,R13/V13<95%),R13*1.03,IF(AND(R13/V13>=95%,R13/V13<105%),V13,IF(AND(R13/V13>=105%,R13/V13<110%),R13*0.97,IF(AND(R13/V13>=110%,R13/V13<115%),R13*0.94,IF(AND(R13/V13>=115%,R13/V13<120%),R13*0.91,IF(AND(R13/V13>=120%,R13/V13<125%),R13*0.88,IF(AND(R13/V13>=125%,R13/V13<130%),R13*0.85,IF(AND(R13/V13>=130%,R13/V13<135%),R13*0.82,IF(R13/V13>=135%,R13*0.8,))))))))))))))) -> 124016 | X13: =IF(N13=0,1,IF(N13<10000,N13*2.8,IF(AND(N13>=10000,N13<20000),N13*2.2,IF(AND(N13>=20000,N13<30000),N13*1.8,IF(AND(N13>=30000,N13<40000),N13*1.78,IF(AND(N13>=40000,N13<50000),N13*1.76,IF(AND(N13>=50000,N13<60000),N13*1.74,IF(AND(N13>=60000,N13<70000),N13*1.72,IF(AND(N13>=70000,N13<80000),N13*1.7,IF(AND(N13>=80000,N13<90000),N13*1.68,IF(AND(N13>=90000,N13<100000),N13*1.66,IF(AND(N13>=100000,N13<110000),N13*1.65,IF(AND(N13>=110000,N13<120000),N13*1.64,IF(AND(N13>=120000,N13<130000),N13*1.63,IF(AND(N13>=130000,N13<140000),N13*1.62,IF(AND(N13>=140000,N13<150000),N13*1.61,IF(AND(N13>=150000,N13<160000),N13*1.6,IF(AND(N13>=160000,N13<170000),N13*1.59,IF(AND(N13>=170000,N13<180000),N13*1.58,IF(AND(N13>=180000,N13<190000),N13*1.57,IF(AND(N13>=190000,N13<200000),N13*1.56,IF(AND(N13>=200000,N13<300000),N13*1.54,IF(AND(N13>=300000,N13<400000),N13*1.52,IF(AND(N13>=400000,N13<500000),N13*1.5,IF(AND(N13>=500000,N13<600000),N13*1.48,IF(AND(N13>=600000,N13<700000),N13*1.46,IF(AND(N13>=700000,N13<800000),N13*1.44,IF(AND(N13>=800000,N13<900000),N13*1.42,IF(AND(N13>=900000,N13<1000000),N13*1.4,IF(AND(N13>=1000000,N13<2000000),N13*1.39,IF(AND(N13>=2000000,N13<3000000),N13*1.38,IF(AND(N13>=3000000,N13<4000000),N13*1.37,IF(AND(N13>=4000000,N13<5000000),N13*1.36,IF(AND(N13>=5000000,N13<6000000),N13*1.35,IF(AND(N13>=6000000,N13<7000000),N13*1.34,IF(AND(N13>=7000000,N13<8000000),N13*1.33,IF(AND(N13>=8000000,N13<9000000),N13*1.32,IF(AND(N13>=9000000,N13<10000000),N13*1.31,IF(N13>=10000000,N13*1.3,""))))))))))))))))))))))))))))))))))))))) -> 131767 | Y13: =CEILING((R13+W13+X13)/3,1000) -> 127000 | Z13: 0 | AA13: =CEILING((Y13+Z13),1000) -> 127000 | AB13: =AA13-N13 -> 49490 | AC13: =AB13/AA13 -> 0.38968504 | AD13: 30 | AE13: =AD13/30 -> 1 | AF13: 10 | AG13: =AF13/30 -> 0.33333333 | AH13: 0.7 | AI13: =(AE13+AG13)*AH13 -> 0.93333333 | AJ13: =AI13*30 -> 28 | AK13: - | AL13: =K13 -> SHELL Transmission Oil Spirax S5 CVTX 1L | AM13: =_xlfn.XLOOKUP(AL13,ITEM!B:B,ITEM!AY:AY,0) -> 220 | AN13: =_xlfn.XLOOKUP(AL13,ITEM!B:B,ITEM!AZ:AZ,0) -> 31.333333 | AO13: =_xlfn.XLOOKUP(AL13,ITEM!B:B,ITEM!BA:BA,0) -> 20 | AP13: =AN13/AO13 -> 1.5666667 | AQ13: 0 | AR13: 0 | AS13: 0 | AT13: =AN13*$AI13 -> 29.244444 | AU13: =AN13*(AE13+AG13+AI13) -> 71.022222 | AV13: =_xlfn.XLOOKUP(AL13,ITEM!B:B,ITEM!BN:BN,0) -> 41 | AW13: 0 | AX13: 0 | AY13: =AU13-AV13-AW13+AX13 -> 30.022222 | AZ13: 120 | BA13: =AZ13/BC13 -> 10 | BB13: =H13 -> 12*1L | BC13: 12 | BD13: - | BE13: - | BF13: ★★★ | BG13: - | BH13: =K13 -> SHELL Transmission Oil Spirax S5 CVTX 1L | BI13: =AM13 -> 220 | BJ13: =BZ13 -> 5 | BK13: =CK13 -> 36 | BL13: =CV13 -> 0 | BM13: =BJ13+BK13+BL13 -> 41 | BN13: =CC13 -> 58.466667 | BO13: =CN13 -> -28.444444 | BP13: =AY13 -> 30.022222 | BQ13: 12 | BS13: =K13 -> SHELL Transmission Oil Spirax S5 CVTX 1L | BT13: =_xlfn.XLOOKUP(BS13,ITEM!B:B,ITEM!BB:BB,0) -> 28 | BU13: =_xlfn.XLOOKUP(BS13,ITEM!B:B,ITEM!BC:BC,0) -> 18.181818 | BV13: =BT13/BU13 -> 1.54 | BW13: 0 | BX13: =BT13*$AI13 -> 26.133333 | BY13: =BT13*($AE13+$AG13+$AI13) -> 63.466667 | BZ13: =_xlfn.XLOOKUP(BS13,ITEM!B:B,ITEM!BK:BK,0) -> 5 | CA13: 0 | CB13: 0 | CC13: =BY13-BZ13-CA13+CB13 -> 58.466667 | CD13: 0 | CE13: =_xlfn.XLOOKUP(BS13,ITEM!B:B,ITEM!BE:BE,0) -> 3.3333333 | CF13: =_xlfn.XLOOKUP(BS13,ITEM!B:B,ITEM!BF:BF,0) -> 3.3333333 | CG13: =CE13/CF13 -> 1 | CH13: 0 | CI13: =CE13*$AI13 -> 3.1111111 | CJ13: =CE13*($AE13+$AG13+$AI13) -> 7.5555556 | CK13: =_xlfn.XLOOKUP(BS13,ITEM!B:B,ITEM!BL:BL,0) -> 36 | CL13: 0 | CM13: 0 | CN13: =CJ13-CK13-CL13+CM13 -> -28.444444 | CO13: 0 | CP13: =_xlfn.XLOOKUP(BS13,ITEM!B:B,ITEM!BH:BH,0) -> 0 | CQ13: =_xlfn.XLOOKUP(BS13,ITEM!B:B,ITEM!BI:BI,0) -> 0 | CR13: =CP13/CQ13 -> #DIV/0! | CS13: 0 | CT13: =CP13*$AI13 -> 0 | CU13: =CP13*($AE13+$AG13+$AI13) -> 0 | CV13: =_xlfn.XLOOKUP(BS13,ITEM!B:B,ITEM!BM:BM,0) -> 0 | CW13: 0 | CX13: 0 | CY13: =CU13-CV13-CW13+CX13 -> 0 | CZ13: 0 | DA13: =K13 -> SHELL Transmission Oil Spirax S5 CVTX 1L
A14: 5 | B14: 101844 | C14: MOTUL | D14: Transmission Oil | E14: Multi | F14: CVTF | G14: 1L | H14: 12*1L | I14: 12 | J14: =C14&" "&D14&" "&E14&" "&F14&" "&G14 -> MOTUL Transmission Oil Multi CVTF 1L | K14: MOTUL Transmission Oil Multi CVTF 1L | L14: 1 | M14: 桶 | N14: 171570 | O14: 0.4 | P14: 0.2 | Q14: =O14+P14 -> 0.6 | R14: =N14*(1+Q14) -> 274512 | S14: 0 | T14: 0 | U14: 0 | V14: =IF((S14+T14+U14)=0,R14,IF(AND(S14>0,T14=0,U14=0),S14,IF(AND(S14=0,T14>0,U14=0),T14,IF(AND(S14=0,T14=0,U14>0),U14,IF(AND(S14>0,T14>0,U14=0),(S14+T14)/2,IF(AND(S14>0,T14=0,U14>0),(S14+U14)/2,IF(AND(S14=0,T14>0,U14>0),(T14+U14)/2,IF(AND(S14>0,T14>0,U14>0),(S14+T14+U14)/3,)))))))) -> 274512 | W14: =IF(R14=V14,V14,IF(R14/V14<70%,R14*1.18,IF(AND(R14/V14>=70%,R14/V14<75%),R14*1.15,IF(AND(R14/V14>=75%,R14/V14<80%),R14*1.12,IF(AND(R14/V14>=80%,R14/V14<85%),R14*1.09,IF(AND(R14/V14>=85%,R14/V14<90%),R14*1.06,IF(AND(R14/V14>=90%,R14/V14<95%),R14*1.03,IF(AND(R14/V14>=95%,R14/V14<105%),V14,IF(AND(R14/V14>=105%,R14/V14<110%),R14*0.97,IF(AND(R14/V14>=110%,R14/V14<115%),R14*0.94,IF(AND(R14/V14>=115%,R14/V14<120%),R14*0.91,IF(AND(R14/V14>=120%,R14/V14<125%),R14*0.88,IF(AND(R14/V14>=125%,R14/V14<130%),R14*0.85,IF(AND(R14/V14>=130%,R14/V14<135%),R14*0.82,IF(R14/V14>=135%,R14*0.8,))))))))))))))) -> 274512 | X14: =IF(N14=0,1,IF(N14<10000,N14*2.8,IF(AND(N14>=10000,N14<20000),N14*2.2,IF(AND(N14>=20000,N14<30000),N14*1.8,IF(AND(N14>=30000,N14<40000),N14*1.78,IF(AND(N14>=40000,N14<50000),N14*1.76,IF(AND(N14>=50000,N14<60000),N14*1.74,IF(AND(N14>=60000,N14<70000),N14*1.72,IF(AND(N14>=70000,N14<80000),N14*1.7,IF(AND(N14>=80000,N14<90000),N14*1.68,IF(AND(N14>=90000,N14<100000),N14*1.66,IF(AND(N14>=100000,N14<110000),N14*1.65,IF(AND(N14>=110000,N14<120000),N14*1.64,IF(AND(N14>=120000,N14<130000),N14*1.63,IF(AND(N14>=130000,N14<140000),N14*1.62,IF(AND(N14>=140000,N14<150000),N14*1.61,IF(AND(N14>=150000,N14<160000),N14*1.6,IF(AND(N14>=160000,N14<170000),N14*1.59,IF(AND(N14>=170000,N14<180000),N14*1.58,IF(AND(N14>=180000,N14<190000),N14*1.57,IF(AND(N14>=190000,N14<200000),N14*1.56,IF(AND(N14>=200000,N14<300000),N14*1.54,IF(AND(N14>=300000,N14<400000),N14*1.52,IF(AND(N14>=400000,N14<500000),N14*1.5,IF(AND(N14>=500000,N14<600000),N14*1.48,IF(AND(N14>=600000,N14<700000),N14*1.46,IF(AND(N14>=700000,N14<800000),N14*1.44,IF(AND(N14>=800000,N14<900000),N14*1.42,IF(AND(N14>=900000,N14<1000000),N14*1.4,IF(AND(N14>=1000000,N14<2000000),N14*1.39,IF(AND(N14>=2000000,N14<3000000),N14*1.38,IF(AND(N14>=3000000,N14<4000000),N14*1.37,IF(AND(N14>=4000000,N14<5000000),N14*1.36,IF(AND(N14>=5000000,N14<6000000),N14*1.35,IF(AND(N14>=6000000,N14<7000000),N14*1.34,IF(AND(N14>=7000000,N14<8000000),N14*1.33,IF(AND(N14>=8000000,N14<9000000),N14*1.32,IF(AND(N14>=9000000,N14<10000000),N14*1.31,IF(N14>=10000000,N14*1.3,""))))))))))))))))))))))))))))))))))))))) -> 271080.6 | Y14: =CEILING((R14+W14+X14)/3,1000) -> 274000 | Z14: 0 | AA14: =CEILING((Y14+Z14),1000) -> 274000 | AB14: =AA14-N14 -> 102430 | AC14: =AB14/AA14 -> 0.37383212 | AD14: 30 | AE14: =AD14/30 -> 1 | AF14: 10 | AG14: =AF14/30 -> 0.33333333 | AH14: 0.7 | AI14: =(AE14+AG14)*AH14 -> 0.93333333 | AJ14: =AI14*30 -> 28 | AK14: - | AL14: =K14 -> MOTUL Transmission Oil Multi CVTF 1L | AM14: =_xlfn.XLOOKUP(AL14,ITEM!B:B,ITEM!AY:AY,0) -> 200 | AN14: =_xlfn.XLOOKUP(AL14,ITEM!B:B,ITEM!AZ:AZ,0) -> 6.6666667 | AO14: =_xlfn.XLOOKUP(AL14,ITEM!B:B,ITEM!BA:BA,0) -> 17.818182 | AP14: =AN14/AO14 -> 0.37414966 | AQ14: 0 | AR14: 0 | AS14: 0 | AT14: =AN14*$AI14 -> 6.2222222 | AU14: =AN14*(AE14+AG14+AI14) -> 15.111111 | AV14: =_xlfn.XLOOKUP(AL14,ITEM!B:B,ITEM!BN:BN,0) -> 73 | AW14: 0 | AX14: 0 | AY14: =AU14-AV14-AW14+AX14 -> -57.888889 | AZ14: 0 | BA14: =AZ14/BC14 -> 0 | BB14: =H14 -> 12*1L | BC14: 12 | BD14: - | BE14: - | BF14: ★ | BG14: - | BH14: =K14 -> MOTUL Transmission Oil Multi CVTF 1L | BI14: =AM14 -> 200 | BJ14: =BZ14 -> 28 | BK14: =CK14 -> 20 | BL14: =CV14 -> 25 | BM14: =BJ14+BK14+BL14 -> 73 | BN14: =CC14 -> -21.955556 | BO14: =CN14 -> -10.933333 | BP14: =AY14 -> -57.888889 | BQ14: - | BS14: =K14 -> MOTUL Transmission Oil Multi CVTF 1L | BT14: =_xlfn.XLOOKUP(BS14,ITEM!B:B,ITEM!BB:BB,0) -> 2.6666667 | BU14: =_xlfn.XLOOKUP(BS14,ITEM!B:B,ITEM!BC:BC,0) -> 15.636364 | BV14: =BT14/BU14 -> 0.17054264 | BW14: 0 | BX14: =BT14*$AI14 -> 2.4888889 | BY14: =BT14*($AE14+$AG14+$AI14) -> 6.0444444 | BZ14: =_xlfn.XLOOKUP(BS14,ITEM!B:B,ITEM!BK:BK,0) -> 28 | CA14: 0 | CB14: 0 | CC14: =BY14-BZ14-CA14+CB14 -> -21.955556 | CD14: 0 | CE14: =_xlfn.XLOOKUP(BS14,ITEM!B:B,ITEM!BE:BE,0) -> 4 | CF14: =_xlfn.XLOOKUP(BS14,ITEM!B:B,ITEM!BF:BF,0) -> 4 | CG14: =CE14/CF14 -> 1 | CH14: 0 | CI14: =CE14*$AI14 -> 3.7333333 | CJ14: =CE14*($AE14+$AG14+$AI14) -> 9.0666667 | CK14: =_xlfn.XLOOKUP(BS14,ITEM!B:B,ITEM!BL:BL,0) -> 20 | CL14: 0 | CM14: 0 | CN14: =CJ14-CK14-CL14+CM14 -> -10.933333 | CO14: 0 | CP14: =_xlfn.XLOOKUP(BS14,ITEM!B:B,ITEM!BH:BH,0) -> 0 | CQ14: =_xlfn.XLOOKUP(BS14,ITEM!B:B,ITEM!BI:BI,0) -> 0 | CR14: =CP14/CQ14 -> #DIV/0! | CS14: 0 | CT14: =CP14*$AI14 -> 0 | CU14: =CP14*($AE14+$AG14+$AI14) -> 0 | CV14: =_xlfn.XLOOKUP(BS14,ITEM!B:B,ITEM!BM:BM,0) -> 25 | CW14: 0 | CX14: 0 | CY14: =CU14-CV14-CW14+CX14 -> -25 | CZ14: 0 | DA14: =K14 -> MOTUL Transmission Oil Multi CVTF 1L
