Workbook

Sheet Master
B1: PRODUCT NAME | C1: Pit Stop 3 | D1: Subur Makmur Ban | E1: Bengkel Pegasus | F1: Autocraft | G1: Autones | H1: ADS Prima | I1: Auto Mekanika | J1: Bengkel Multi Variasi | K1: Euro Galleria | L1: Drivewell | M1: Mersi | N1: K | O1: Auto Service (no sales yet) | P1: CV Sun | Q1: Sumber Timur | R1: Honda Auto Duren Sawit | S1: Lavender Car Solution | T1: Total Demand from all franchise | U1: PRICE | V1: TOTAL AMOUNT | W1: Bosch Part Number
A2: =VLOOKUP(B2,#REF!,5,0) -> #REF! | B2: MOTUL Engine Oil MUGEN MS-A 5W-30 1L | C2: =_xlfn.XLOOKUP(B2,'Pit Stop (cleaned)'!A:A,'Pit Stop (cleaned)'!B:B,0) -> 0 | D2: =_xlfn.XLOOKUP(B2,'Subur Makmur Ban (Agg)'!$F$1:$F$5,'Subur Makmur Ban (Agg)'!$L$1:$L$5,0) -> 0 | E2: =_xlfn.XLOOKUP(B2,'Bengkel Pegasus (Agg)'!F:F,'Bengkel Pegasus (Agg)'!L:L,0) -> 0 | F2: =_xlfn.XLOOKUP(B2,'Autocraft (agg)'!F:F,'Autocraft (agg)'!L:L,0) -> 0 | G2: =_xlfn.XLOOKUP(B2,'Autones (cleaned)'!A:A,'Autones (cleaned)'!B:B,0) -> 0 | H2: =_xlfn.XLOOKUP(B2,'ADS Prima (cleaned)'!A:A,'ADS Prima (cleaned)'!B:B,0) -> 0 | I2: =_xlfn.XLOOKUP(B2,'Auto Mekanika (cleaned)'!A:A,'Auto Mekanika (cleaned)'!B:B,0) -> 0 | J2: =_xlfn.XLOOKUP(B2,'Bengkel Multi Var (cleaned)'!A:A,'Bengkel Multi Var (cleaned)'!B:B,0) -> 0 | K2: 0 | L2: =_xlfn.XLOOKUP(B2,'Drivewell (cleaned)'!A:A,'Drivewell (cleaned)'!B:B,0) -> 0 | M2: 0 | N2: 0 | O2: 0 | P2: =_xlfn.XLOOKUP(B2,'CV Sun (cleaned)'!A:A,'CV Sun (cleaned)'!B:B,0) -> 0 | Q2: =_xlfn.XLOOKUP(B2,'Sumber Timur (clean)'!F:F,'Sumber Timur (clean)'!L:L,0) -> 0 | R2: =_xlfn.XLOOKUP(B2,'Honda Duren (clean)'!F:F,'Honda Duren (clean)'!L:L,0) -> 0 | S2: 0 | T2: =SUM(C2:S2) -> 0
A3: =VLOOKUP(B3,#REF!,5,0) -> #REF! | B3: DENSO Air Filter DXA-1059 | C3: =_xlfn.XLOOKUP(B3,'Pit Stop (cleaned)'!A:A,'Pit Stop (cleaned)'!B:B,0) -> 0 | D3: =_xlfn.XLOOKUP(B3,'Subur Makmur Ban (Agg)'!$F$1:$F$5,'Subur Makmur Ban (Agg)'!$L$1:$L$5,0) -> 0 | E3: =_xlfn.XLOOKUP(B3,'Bengkel Pegasus (Agg)'!F:F,'Bengkel Pegasus (Agg)'!L:L,0) -> 0 | F3: =_xlfn.XLOOKUP(B3,'Autocraft (agg)'!F:F,'Autocraft (agg)'!L:L,0) -> 0 | G3: =_xlfn.XLOOKUP(B3,'Autones (cleaned)'!A:A,'Autones (cleaned)'!B:B,0) -> 0 | H3: =_xlfn.XLOOKUP(B3,'ADS Prima (cleaned)'!A:A,'ADS Prima (cleaned)'!B:B,0) -> 0 | I3: =_xlfn.XLOOKUP(B3,'Auto Mekanika (cleaned)'!A:A,'Auto Mekanika (cleaned)'!B:B,0) -> 0 | J3: =_xlfn.XLOOKUP(B3,'Bengkel Multi Var (cleaned)'!A:A,'Bengkel Multi Var (cleaned)'!B:B,0) -> 0 | K3: 0 | L3: =_xlfn.XLOOKUP(B3,'Drivewell (cleaned)'!A:A,'Drivewell (cleaned)'!B:B,0) -> 0 | M3: 0 | N3: 0 | O3: 0 | P3: =_xlfn.XLOOKUP(B3,'CV Sun (cleaned)'!A:A,'CV Sun (cleaned)'!B:B,0) -> 0 | Q3: =_xlfn.XLOOKUP(B3,'Sumber Timur (clean)'!F:F,'Sumber Timur (clean)'!L:L,0) -> 0 | R3: =_xlfn.XLOOKUP(B3,'Honda Duren (clean)'!F:F,'Honda Duren (clean)'!L:L,0) -> 0 | S3: 0 | T3: =SUM(C3:S3) -> 0
A4: =VLOOKUP(B4,#REF!,5,0) -> #REF! | B4: BOSCH Oil Filter O 1506 | C4: =_xlfn.XLOOKUP(B4,'Pit Stop (cleaned)'!A:A,'Pit Stop (cleaned)'!B:B,0) -> 0 | D4: =_xlfn.XLOOKUP(B4,'Subur Makmur Ban (Agg)'!$F$1:$F$5,'Subur Makmur Ban (Agg)'!$L$1:$L$5,0) -> 0 | E4: =_xlfn.XLOOKUP(B4,'Bengkel Pegasus (Agg)'!F:F,'Bengkel Pegasus (Agg)'!L:L,0) -> 0 | F4: =_xlfn.XLOOKUP(B4,'Autocraft (agg)'!F:F,'Autocraft (agg)'!L:L,0) -> 0 | G4: =_xlfn.XLOOKUP(B4,'Autones (cleaned)'!A:A,'Autones (cleaned)'!B:B,0) -> 0 | H4: =_xlfn.XLOOKUP(B4,'ADS Prima (cleaned)'!A:A,'ADS Prima (cleaned)'!B:B,0) -> 0 | I4: =_xlfn.XLOOKUP(B4,'Auto Mekanika (cleaned)'!A:A,'Auto Mekanika (cleaned)'!B:B,0) -> 0 | J4: =_xlfn.XLOOKUP(B4,'Bengkel Multi Var (cleaned)'!A:A,'Bengkel Multi Var (cleaned)'!B:B,0) -> 0 | K4: 0 | L4: =_xlfn.XLOOKUP(B4,'Drivewell (cleaned)'!A:A,'Drivewell (cleaned)'!B:B,0) -> 0 | M4: 0 | N4: 0 | O4: 0 | P4: =_xlfn.XLOOKUP(B4,'CV Sun (cleaned)'!A:A,'CV Sun (cleaned)'!B:B,0) -> 0 | Q4: =_xlfn.XLOOKUP(B4,'Sumber Timur (clean)'!F:F,'Sumber Timur (clean)'!L:L,0) -> 0 | R4: =_xlfn.XLOOKUP(B4,'Honda Duren (clean)'!F:F,'Honda Duren (clean)'!L:L,0) -> 0 | S4: 0 | T4: =SUM(C4:S4) -> 0
A5: =VLOOKUP(B5,#REF!,5,0) -> #REF! | B5: SHELL Engine Oil HELIX Ultra 5W-30 4L | C5: =_xlfn.XLOOKUP(B5,'Pit Stop (cleaned)'!A:A,'Pit Stop (cleaned)'!B:B,0) -> 0 | D5: =_xlfn.XLOOKUP(B5,'Subur Makmur Ban (Agg)'!$F$1:$F$5,'Subur Makmur Ban (Agg)'!$L$1:$L$5,0) -> 0 | E5: =_xlfn.XLOOKUP(B5,'Bengkel Pegasus (Agg)'!F:F,'Bengkel Pegasus (Agg)'!L:L,0) -> 0 | F5: =_xlfn.XLOOKUP(B5,'Autocraft (agg)'!F:F,'Autocraft (agg)'!L:L,0) -> 0 | G5: =_xlfn.XLOOKUP(B5,'Autones (cleaned)'!A:A,'Autones (cleaned)'!B:B,0) -> 0 | H5: =_xlfn.XLOOKUP(B5,'ADS Prima (cleaned)'!A:A,'ADS Prima (cleaned)'!B:B,0) -> 0 | I5: =_xlfn.XLOOKUP(B5,'Auto Mekanika (cleaned)'!A:A,'Auto Mekanika (cleaned)'!B:B,0) -> 0 | J5: =_xlfn.XLOOKUP(B5,'Bengkel Multi Var (cleaned)'!A:A,'Bengkel Multi Var (cleaned)'!B:B,0) -> 0 | K5: 0 | L5: =_xlfn.XLOOKUP(B5,'Drivewell (cleaned)'!A:A,'Drivewell (cleaned)'!B:B,0) -> 0 | M5: 0 | N5: 0 | O5: 0 | P5: =_xlfn.XLOOKUP(B5,'CV Sun (cleaned)'!A:A,'CV Sun (cleaned)'!B:B,0) -> 0 | Q5: =_xlfn.XLOOKUP(B5,'Sumber Timur (clean)'!F:F,'Sumber Timur (clean)'!L:L,0) -> 0 | R5: =_xlfn.XLOOKUP(B5,'Honda Duren (clean)'!F:F,'Honda Duren (clean)'!L:L,0) -> 0 | S5: 0 | T5: =SUM(C5:S5) -> 0
A6: =VLOOKUP(B6,#REF!,5,0) -> #REF! | B6: DENSO Spark Plug IK16TT - Iridium | C6: =_xlfn.XLOOKUP(B6,'Pit Stop (cleaned)'!A:A,'Pit Stop (cleaned)'!B:B,0) -> 0 | D6: =_xlfn.XLOOKUP(B6,'Subur Makmur Ban (Agg)'!$F$1:$F$5,'Subur Makmur Ban (Agg)'!$L$1:$L$5,0) -> 0 | E6: =_xlfn.XLOOKUP(B6,'Bengkel Pegasus (Agg)'!F:F,'Bengkel Pegasus (Agg)'!L:L,0) -> 0 | F6: =_xlfn.XLOOKUP(B6,'Autocraft (agg)'!F:F,'Autocraft (agg)'!L:L,0) -> 0 | G6: =_xlfn.XLOOKUP(B6,'Autones (cleaned)'!A:A,'Autones (cleaned)'!B:B,0) -> 0 | H6: =_xlfn.XLOOKUP(B6,'ADS Prima (cleaned)'!A:A,'ADS Prima (cleaned)'!B:B,0) -> 0 | I6: =_xlfn.XLOOKUP(B6,'Auto Mekanika (cleaned)'!A:A,'Auto Mekanika (cleaned)'!B:B,0) -> 0 | J6: =_xlfn.XLOOKUP(B6,'Bengkel Multi Var (cleaned)'!A:A,'Bengkel Multi Var (cleaned)'!B:B,0) -> 0 | K6: 0 | L6: =_xlfn.XLOOKUP(B6,'Drivewell (cleaned)'!A:A,'Drivewell (cleaned)'!B:B,0) -> 0 | M6: 0 | N6: 0 | O6: 0 | P6: =_xlfn.XLOOKUP(B6,'CV Sun (cleaned)'!A:A,'CV Sun (cleaned)'!B:B,0) -> 0 | Q6: =_xlfn.XLOOKUP(B6,'Sumber Timur (clean)'!F:F,'Sumber Timur (clean)'!L:L,0) -> 0 | R6: =_xlfn.XLOOKUP(B6,'Honda Duren (clean)'!F:F,'Honda Duren (clean)'!L:L,0) -> 0 | S6: 0 | T6: =SUM(C6:S6) -> 0
A7: =VLOOKUP(B7,#REF!,5,0) -> #REF! | B7: BOSCH Spark Plug YR7PP30 - Iridium | C7: =_xlfn.XLOOKUP(B7,'Pit Stop (cleaned)'!A:A,'Pit Stop (cleaned)'!B:B,0) -> 0 | D7: =_xlfn.XLOOKUP(B7,'Subur Makmur Ban (Agg)'!$F$1:$F$5,'Subur Makmur Ban (Agg)'!$L$1:$L$5,0) -> 0 | E7: =_xlfn.XLOOKUP(B7,'Bengkel Pegasus (Agg)'!F:F,'Bengkel Pegasus (Agg)'!L:L,0) -> 0 | F7: =_xlfn.XLOOKUP(B7,'Autocraft (agg)'!F:F,'Autocraft (agg)'!L:L,0) -> 0 | G7: =_xlfn.XLOOKUP(B7,'Autones (cleaned)'!A:A,'Autones (cleaned)'!B:B,0) -> 0 | H7: =_xlfn.XLOOKUP(B7,'ADS Prima (cleaned)'!A:A,'ADS Prima (cleaned)'!B:B,0) -> 0 | I7: =_xlfn.XLOOKUP(B7,'Auto Mekanika (cleaned)'!A:A,'Auto Mekanika (cleaned)'!B:B,0) -> 0 | J7: =_xlfn.XLOOKUP(B7,'Bengkel Multi Var (cleaned)'!A:A,'Bengkel Multi Var (cleaned)'!B:B,0) -> 0 | K7: 0 | L7: =_xlfn.XLOOKUP(B7,'Drivewell (cleaned)'!A:A,'Drivewell (cleaned)'!B:B,0) -> 0 | M7: 0 | N7: 0 | O7: 0 | P7: =_xlfn.XLOOKUP(B7,'CV Sun (cleaned)'!A:A,'CV Sun (cleaned)'!B:B,0) -> 0 | Q7: =_xlfn.XLOOKUP(B7,'Sumber Timur (clean)'!F:F,'Sumber Timur (clean)'!L:L,0) -> 0 | R7: =_xlfn.XLOOKUP(B7,'Honda Duren (clean)'!F:F,'Honda Duren (clean)'!L:L,0) -> 0 | S7: 0 | T7: =SUM(C7:S7) -> 0
A8: =VLOOKUP(B8,#REF!,5,0) -> #REF! | B8: BOSCH Air Filter A 2180 | C8: =_xlfn.XLOOKUP(B8,'Pit Stop (cleaned)'!A:A,'Pit Stop (cleaned)'!B:B,0) -> 0 | D8: =_xlfn.XLOOKUP(B8,'Subur Makmur Ban (Agg)'!$F$1:$F$5,'Subur Makmur Ban (Agg)'!$L$1:$L$5,0) -> 0 | E8: =_xlfn.XLOOKUP(B8,'Bengkel Pegasus (Agg)'!F:F,'Bengkel Pegasus (Agg)'!L:L,0) -> 0 | F8: =_xlfn.XLOOKUP(B8,'Autocraft (agg)'!F:F,'Autocraft (agg)'!L:L,0) -> 0 | G8: =_xlfn.XLOOKUP(B8,'Autones (cleaned)'!A:A,'Autones (cleaned)'!B:B,0) -> 0 | H8: =_xlfn.XLOOKUP(B8,'ADS Prima (cleaned)'!A:A,'ADS Prima (cleaned)'!B:B,0) -> 0 | I8: =_xlfn.XLOOKUP(B8,'Auto Mekanika (cleaned)'!A:A,'Auto Mekanika (cleaned)'!B:B,0) -> 0 | J8: =_xlfn.XLOOKUP(B8,'Bengkel Multi Var (cleaned)'!A:A,'Bengkel Multi Var (cleaned)'!B:B,0) -> 0 | K8: =_xlfn.XLOOKUP(B8,'[2]EURO GALLARIA'!F:F,'[2]EURO GALLARIA'!L:L,0) -> 0 | L8: =_xlfn.XLOOKUP(B8,'Drivewell (cleaned)'!A:A,'Drivewell (cleaned)'!B:B,0) -> 0 | M8: =_xlfn.XLOOKUP(B8,'[2]Mersi (CLEAN)'!D:D,'[2]Mersi (CLEAN)'!E:E,0) -> 0 | N8: 0 | O8: 0 | P8: =_xlfn.XLOOKUP(B8,'CV Sun (cleaned)'!A:A,'CV Sun (cleaned)'!B:B,0) -> 0 | Q8: =_xlfn.XLOOKUP(B8,'Sumber Timur (clean)'!F:F,'Sumber Timur (clean)'!L:L,0) -> 0 | R8: =_xlfn.XLOOKUP(B8,'Honda Duren (clean)'!F:F,'Honda Duren (clean)'!L:L,0) -> 0 | S8: =_xlfn.XLOOKUP(B8,'[2]LAVANDER CLEAN'!A:A,'[2]LAVANDER CLEAN'!B:B,0) -> 0 | T8: =SUM(C8:S8) -> 0 | U8: 157950 | V8: =IF(T8*U8=0,"",T8*U8) | W8: 0986AF2180
A9: =VLOOKUP(B9,#REF!,5,0) -> #REF! | B9: DENSO Oil Filter DXE-1001 | C9: =_xlfn.XLOOKUP(B9,'Pit Stop (cleaned)'!A:A,'Pit Stop (cleaned)'!B:B,0) -> 0 | D9: =_xlfn.XLOOKUP(B9,'Subur Makmur Ban (Agg)'!$F$1:$F$5,'Subur Makmur Ban (Agg)'!$L$1:$L$5,0) -> 0 | E9: =_xlfn.XLOOKUP(B9,'Bengkel Pegasus (Agg)'!F:F,'Bengkel Pegasus (Agg)'!L:L,0) -> 0 | F9: =_xlfn.XLOOKUP(B9,'Autocraft (agg)'!F:F,'Autocraft (agg)'!L:L,0) -> 0 | G9: =_xlfn.XLOOKUP(B9,'Autones (cleaned)'!A:A,'Autones (cleaned)'!B:B,0) -> 0 | H9: =_xlfn.XLOOKUP(B9,'ADS Prima (cleaned)'!A:A,'ADS Prima (cleaned)'!B:B,0) -> 0 | I9: =_xlfn.XLOOKUP(B9,'Auto Mekanika (cleaned)'!A:A,'Auto Mekanika (cleaned)'!B:B,0) -> 0 | J9: =_xlfn.XLOOKUP(B9,'Bengkel Multi Var (cleaned)'!A:A,'Bengkel Multi Var (cleaned)'!B:B,0) -> 0 | K9: 0 | L9: =_xlfn.XLOOKUP(B9,'Drivewell (cleaned)'!A:A,'Drivewell (cleaned)'!B:B,0) -> 0 | M9: 0 | N9: 0 | O9: 0 | P9: =_xlfn.XLOOKUP(B9,'CV Sun (cleaned)'!A:A,'CV Sun (cleaned)'!B:B,0) -> 0 | Q9: =_xlfn.XLOOKUP(B9,'Sumber Timur (clean)'!F:F,'Sumber Timur (clean)'!L:L,0) -> 0 | R9: =_xlfn.XLOOKUP(B9,'Honda Duren (clean)'!F:F,'Honda Duren (clean)'!L:L,0) -> 0 | S9: 0 | T9: =SUM(C9:S9) -> 0
A10: =VLOOKUP(B10,#REF!,5,0) -> #REF! | B10: BOSCH Spark Plug F6TC(W8DC) - Standard | C10: =_xlfn.XLOOKUP(B10,'Pit Stop (cleaned)'!A:A,'Pit Stop (cleaned)'!B:B,0) -> 0 | D10: =_xlfn.XLOOKUP(B10,'Subur Makmur Ban (Agg)'!$F$1:$F$5,'Subur Makmur Ban (Agg)'!$L$1:$L$5,0) -> 0 | E10: =_xlfn.XLOOKUP(B10,'Bengkel Pegasus (Agg)'!F:F,'Bengkel Pegasus (Agg)'!L:L,0) -> 0 | F10: =_xlfn.XLOOKUP(B10,'Autocraft (agg)'!F:F,'Autocraft (agg)'!L:L,0) -> 0 | G10: =_xlfn.XLOOKUP(B10,'Autones (cleaned)'!A:A,'Autones (cleaned)'!B:B,0) -> 0 | H10: =_xlfn.XLOOKUP(B10,'ADS Prima (cleaned)'!A:A,'ADS Prima (cleaned)'!B:B,0) -> 0 | I10: =_xlfn.XLOOKUP(B10,'Auto Mekanika (cleaned)'!A:A,'Auto Mekanika (cleaned)'!B:B,0) -> 0 | J10: =_xlfn.XLOOKUP(B10,'Bengkel Multi Var (cleaned)'!A:A,'Bengkel Multi Var (cleaned)'!B:B,0) -> 0 | K10: 0 | L10: =_xlfn.XLOOKUP(B10,'Drivewell (cleaned)'!A:A,'Drivewell (cleaned)'!B:B,0) -> 0 | M10: 0 | N10: 0 | O10: 0 | P10: =_xlfn.XLOOKUP(B10,'CV Sun (cleaned)'!A:A,'CV Sun (cleaned)'!B:B,0) -> 0 | Q10: =_xlfn.XLOOKUP(B10,'Sumber Timur (clean)'!F:F,'Sumber Timur (clean)'!L:L,0) -> 0 | R10: =_xlfn.XLOOKUP(B10,'Honda Duren (clean)'!F:F,'Honda Duren (clean)'!L:L,0) -> 0 | S10: 0 | T10: =SUM(C10:S10) -> 0
A11: =VLOOKUP(B11,#REF!,5,0) -> #REF! | B11: BOSCH Battery MF Blue 80D23L 12V-70Ah | C11: =_xlfn.XLOOKUP(B11,'Pit Stop (cleaned)'!A:A,'Pit Stop (cleaned)'!B:B,0) -> 0 | D11: =_xlfn.XLOOKUP(B11,'Subur Makmur Ban (Agg)'!$F$1:$F$5,'Subur Makmur Ban (Agg)'!$L$1:$L$5,0) -> 0 | E11: =_xlfn.XLOOKUP(B11,'Bengkel Pegasus (Agg)'!F:F,'Bengkel Pegasus (Agg)'!L:L,0) -> 0 | F11: =_xlfn.XLOOKUP(B11,'Autocraft (agg)'!F:F,'Autocraft (agg)'!L:L,0) -> 0 | G11: =_xlfn.XLOOKUP(B11,'Autones (cleaned)'!A:A,'Autones (cleaned)'!B:B,0) -> 0 | H11: =_xlfn.XLOOKUP(B11,'ADS Prima (cleaned)'!A:A,'ADS Prima (cleaned)'!B:B,0) -> 0 | I11: =_xlfn.XLOOKUP(B11,'Auto Mekanika (cleaned)'!A:A,'Auto Mekanika (cleaned)'!B:B,0) -> 0 | J11: =_xlfn.XLOOKUP(B11,'Bengkel Multi Var (cleaned)'!A:A,'Bengkel Multi Var (cleaned)'!B:B,0) -> 0 | K11: 0 | L11: =_xlfn.XLOOKUP(B11,'Drivewell (cleaned)'!A:A,'Drivewell (cleaned)'!B:B,0) -> 0 | M11: 0 | N11: 0 | O11: 0 | P11: =_xlfn.XLOOKUP(B11,'CV Sun (cleaned)'!A:A,'CV Sun (cleaned)'!B:B,0) -> 0 | Q11: =_xlfn.XLOOKUP(B11,'Sumber Timur (clean)'!F:F,'Sumber Timur (clean)'!L:L,0) -> 0 | R11: =_xlfn.XLOOKUP(B11,'Honda Duren (clean)'!F:F,'Honda Duren (clean)'!L:L,0) -> 0 | S11: 0 | T11: =SUM(C11:S11) -> 0
A12: =VLOOKUP(B12,#REF!,5,0) -> #REF! | B12: BOSCH Battery MF Blue NS60 46B24R 12V-42Ah | C12: =_xlfn.XLOOKUP(B12,'Pit Stop (cleaned)'!A:A,'Pit Stop (cleaned)'!B:B,0) -> 0 | D12: =_xlfn.XLOOKUP(B12,'Subur Makmur Ban (Agg)'!$F$1:$F$5,'Subur Makmur Ban (Agg)'!$L$1:$L$5,0) -> 0 | E12: =_xlfn.XLOOKUP(B12,'Bengkel Pegasus (Agg)'!F:F,'Bengkel Pegasus (Agg)'!L:L,0) -> 0 | F12: =_xlfn.XLOOKUP(B12,'Autocraft (agg)'!F:F,'Autocraft (agg)'!L:L,0) -> 0 | G12: =_xlfn.XLOOKUP(B12,'Autones (cleaned)'!A:A,'Autones (cleaned)'!B:B,0) -> 0 | H12: =_xlfn.XLOOKUP(B12,'ADS Prima (cleaned)'!A:A,'ADS Prima (cleaned)'!B:B,0) -> 0 | I12: =_xlfn.XLOOKUP(B12,'Auto Mekanika (cleaned)'!A:A,'Auto Mekanika (cleaned)'!B:B,0) -> 0 | J12: =_xlfn.XLOOKUP(B12,'Bengkel Multi Var (cleaned)'!A:A,'Bengkel Multi Var (cleaned)'!B:B,0) -> 0 | K12: =_xlfn.XLOOKUP(B12,'[2]EURO GALLARIA'!F:F,'[2]EURO GALLARIA'!L:L,0) -> 0 | L12: =_xlfn.XLOOKUP(B12,'Drivewell (cleaned)'!A:A,'Drivewell (cleaned)'!B:B,0) -> 0 | M12: =_xlfn.XLOOKUP(B12,'[2]Mersi (CLEAN)'!D:D,'[2]Mersi (CLEAN)'!E:E,0) -> 0 | N12: 0 | O12: 0 | P12: =_xlfn.XLOOKUP(B12,'CV Sun (cleaned)'!A:A,'CV Sun (cleaned)'!B:B,0) -> 0 | Q12: =_xlfn.XLOOKUP(B12,'Sumber Timur (clean)'!F:F,'Sumber Timur (clean)'!L:L,0) -> 0 | R12: =_xlfn.XLOOKUP(B12,'Honda Duren (clean)'!F:F,'Honda Duren (clean)'!L:L,0) -> 0 | S12: =_xlfn.XLOOKUP(B12,'[2]LAVANDER CLEAN'!A:A,'[2]LAVANDER CLEAN'!B:B,0) -> 0 | T12: =SUM(C12:S12) -> 0 | U12: 675660 | V12: =IF(T12*U12=0,"",T12*U12) | W12: 0986A00362
A13: =VLOOKUP(B13,#REF!,5,0) -> #REF! | B13: BOSCH Battery MF Blue NS60LS 46B24LS 12V-42Ah | C13: =_xlfn.XLOOKUP(B13,'Pit Stop (cleaned)'!A:A,'Pit Stop (cleaned)'!B:B,0) -> 0 | D13: =_xlfn.XLOOKUP(B13,'Subur Makmur Ban (Agg)'!$F$1:$F$5,'Subur Makmur Ban (Agg)'!$L$1:$L$5,0) -> 0 | E13: =_xlfn.XLOOKUP(B13,'Bengkel Pegasus (Agg)'!F:F,'Bengkel Pegasus (Agg)'!L:L,0) -> 0 | F13: =_xlfn.XLOOKUP(B13,'Autocraft (agg)'!F:F,'Autocraft (agg)'!L:L,0) -> 0 | G13: =_xlfn.XLOOKUP(B13,'Autones (cleaned)'!A:A,'Autones (cleaned)'!B:B,0) -> 5 | H13: =_xlfn.XLOOKUP(B13,'ADS Prima (cleaned)'!A:A,'ADS Prima (cleaned)'!B:B,0) -> 0 | I13: =_xlfn.XLOOKUP(B13,'Auto Mekanika (cleaned)'!A:A,'Auto Mekanika (cleaned)'!B:B,0) -> 0 | J13: =_xlfn.XLOOKUP(B13,'Bengkel Multi Var (cleaned)'!A:A,'Bengkel Multi Var (cleaned)'!B:B,0) -> 0 | K13: =_xlfn.XLOOKUP(B13,'[2]EURO GALLARIA'!F:F,'[2]EURO GALLARIA'!L:L,0) -> 0 | L13: =_xlfn.XLOOKUP(B13,'Drivewell (cleaned)'!A:A,'Drivewell (cleaned)'!B:B,0) -> 0 | M13: =_xlfn.XLOOKUP(B13,'[2]Mersi (CLEAN)'!D:D,'[2]Mersi (CLEAN)'!E:E,0) -> 0 | N13: 0 | O13: 0 | P13: =_xlfn.XLOOKUP(B13,'CV Sun (cleaned)'!A:A,'CV Sun (cleaned)'!B:B,0) -> 0 | Q13: =_xlfn.XLOOKUP(B13,'Sumber Timur (clean)'!F:F,'Sumber Timur (clean)'!L:L,0) -> 0 | R13: =_xlfn.XLOOKUP(B13,'Honda Duren (clean)'!F:F,'Honda Duren (clean)'!L:L,0) -> 0 | S13: =_xlfn.XLOOKUP(B13,'[2]LAVANDER CLEAN'!A:A,'[2]LAVANDER CLEAN'!B:B,0) -> 0 | T13: =SUM(C13:S13) -> 5 | U13: 675660 | V13: =IF(T13*U13=0,"",T13*U13) -> 3378300 | W13: 0986A00365
A14: =VLOOKUP(B14,#REF!,5,0) -> #REF! | B14: BOSCH Battery MF Blue NX11005L 80D26L 12V-70Ah | C14: =_xlfn.XLOOKUP(B14,'Pit Stop (cleaned)'!A:A,'Pit Stop (cleaned)'!B:B,0) -> 0 | D14: =_xlfn.XLOOKUP(B14,'Subur Makmur Ban (Agg)'!$F$1:$F$5,'Subur Makmur Ban (Agg)'!$L$1:$L$5,0) -> 0 | E14: =_xlfn.XLOOKUP(B14,'Bengkel Pegasus (Agg)'!F:F,'Bengkel Pegasus (Agg)'!L:L,0) -> 0 | F14: =_xlfn.XLOOKUP(B14,'Autocraft (agg)'!F:F,'Autocraft (agg)'!L:L,0) -> 0 | G14: =_xlfn.XLOOKUP(B14,'Autones (cleaned)'!A:A,'Autones (cleaned)'!B:B,0) -> 0 | H14: =_xlfn.XLOOKUP(B14,'ADS Prima (cleaned)'!A:A,'ADS Prima (cleaned)'!B:B,0) -> 0 | I14: =_xlfn.XLOOKUP(B14,'Auto Mekanika (cleaned)'!A:A,'Auto Mekanika (cleaned)'!B:B,0) -> 0 | J14: =_xlfn.XLOOKUP(B14,'Bengkel Multi Var (cleaned)'!A:A,'Bengkel Multi Var (cleaned)'!B:B,0) -> 0 | K14: 0 | L14: =_xlfn.XLOOKUP(B14,'Drivewell (cleaned)'!A:A,'Drivewell (cleaned)'!B:B,0) -> 0 | M14: 0 | N14: 0 | O14: 0 | P14: =_xlfn.XLOOKUP(B14,'CV Sun (cleaned)'!A:A,'CV Sun (cleaned)'!B:B,0) -> 0 | Q14: =_xlfn.XLOOKUP(B14,'Sumber Timur (clean)'!F:F,'Sumber Timur (clean)'!L:L,0) -> 0 | R14: =_xlfn.XLOOKUP(B14,'Honda Duren (clean)'!F:F,'Honda Duren (clean)'!L:L,0) -> 0 | S14: 0 | T14: =SUM(C14:S14) -> 0
A15: =VLOOKUP(B15,#REF!,5,0) -> #REF! | B15: MONROE Shock Absorber 744683SP Front-LH | C15: =_xlfn.XLOOKUP(B15,'Pit Stop (cleaned)'!A:A,'Pit Stop (cleaned)'!B:B,0) -> 0 | D15: =_xlfn.XLOOKUP(B15,'Subur Makmur Ban (Agg)'!$F$1:$F$5,'Subur Makmur Ban (Agg)'!$L$1:$L$5,0) -> 0 | E15: =_xlfn.XLOOKUP(B15,'Bengkel Pegasus (Agg)'!F:F,'Bengkel Pegasus (Agg)'!L:L,0) -> 0 | F15: =_xlfn.XLOOKUP(B15,'Autocraft (agg)'!F:F,'Autocraft (agg)'!L:L,0) -> 0 | G15: =_xlfn.XLOOKUP(B15,'Autones (cleaned)'!A:A,'Autones (cleaned)'!B:B,0) -> 0 | H15: =_xlfn.XLOOKUP(B15,'ADS Prima (cleaned)'!A:A,'ADS Prima (cleaned)'!B:B,0) -> 0 | I15: =_xlfn.XLOOKUP(B15,'Auto Mekanika (cleaned)'!A:A,'Auto Mekanika (cleaned)'!B:B,0) -> 0 | J15: =_xlfn.XLOOKUP(B15,'Bengkel Multi Var (cleaned)'!A:A,'Bengkel Multi Var (cleaned)'!B:B,0) -> 0 | K15: 0 | L15: =_xlfn.XLOOKUP(B15,'Drivewell (cleaned)'!A:A,'Drivewell (cleaned)'!B:B,0) -> 0 | M15: 0 | N15: 0 | O15: 0 | P15: =_xlfn.XLOOKUP(B15,'CV Sun (cleaned)'!A:A,'CV Sun (cleaned)'!B:B,0) -> 0 | Q15: =_xlfn.XLOOKUP(B15,'Sumber Timur (clean)'!F:F,'Sumber Timur (clean)'!L:L,0) -> 0 | R15: =_xlfn.XLOOKUP(B15,'Honda Duren (clean)'!F:F,'Honda Duren (clean)'!L:L,0) -> 0 | S15: 0 | T15: =SUM(C15:S15) -> 0
A16: =VLOOKUP(B16,#REF!,5,0) -> #REF! | B16: MONROE Shock Absorber 744682SP Front-RH | C16: =_xlfn.XLOOKUP(B16,'Pit Stop (cleaned)'!A:A,'Pit Stop (cleaned)'!B:B,0) -> 0 | D16: =_xlfn.XLOOKUP(B16,'Subur Makmur Ban (Agg)'!$F$1:$F$5,'Subur Makmur Ban (Agg)'!$L$1:$L$5,0) -> 0 | E16: =_xlfn.XLOOKUP(B16,'Bengkel Pegasus (Agg)'!F:F,'Bengkel Pegasus (Agg)'!L:L,0) -> 0 | F16: =_xlfn.XLOOKUP(B16,'Autocraft (agg)'!F:F,'Autocraft (agg)'!L:L,0) -> 0 | G16: =_xlfn.XLOOKUP(B16,'Autones (cleaned)'!A:A,'Autones (cleaned)'!B:B,0) -> 0 | H16: =_xlfn.XLOOKUP(B16,'ADS Prima (cleaned)'!A:A,'ADS Prima (cleaned)'!B:B,0) -> 0 | I16: =_xlfn.XLOOKUP(B16,'Auto Mekanika (cleaned)'!A:A,'Auto Mekanika (cleaned)'!B:B,0) -> 0 | J16: =_xlfn.XLOOKUP(B16,'Bengkel Multi Var (cleaned)'!A:A,'Bengkel Multi Var (cleaned)'!B:B,0) -> 0 | K16: 0 | L16: =_xlfn.XLOOKUP(B16,'Drivewell (cleaned)'!A:A,'Drivewell (cleaned)'!B:B,0) -> 0 | M16: 0 | N16: 0 | O16: 0 | P16: =_xlfn.XLOOKUP(B16,'CV Sun (cleaned)'!A:A,'CV Sun (cleaned)'!B:B,0) -> 0 | Q16: =_xlfn.XLOOKUP(B16,'Sumber Timur (clean)'!F:F,'Sumber Timur (clean)'!L:L,0) -> 0 | R16: =_xlfn.XLOOKUP(B16,'Honda Duren (clean)'!F:F,'Honda Duren (clean)'!L:L,0) -> 0 | S16: 0 | T16: =SUM(C16:S16) -> 0
A17: =VLOOKUP(B17,#REF!,5,0) -> #REF! | B17: MONROE Shock Absorber 744641SP Front-LH | C17: =_xlfn.XLOOKUP(B17,'Pit Stop (cleaned)'!A:A,'Pit Stop (cleaned)'!B:B,0) -> 0 | D17: =_xlfn.XLOOKUP(B17,'Subur Makmur Ban (Agg)'!$F$1:$F$5,'Subur Makmur Ban (Agg)'!$L$1:$L$5,0) -> 0 | E17: =_xlfn.XLOOKUP(B17,'Bengkel Pegasus (Agg)'!F:F,'Bengkel Pegasus (Agg)'!L:L,0) -> 0 | F17: =_xlfn.XLOOKUP(B17,'Autocraft (agg)'!F:F,'Autocraft (agg)'!L:L,0) -> 0 | G17: =_xlfn.XLOOKUP(B17,'Autones (cleaned)'!A:A,'Autones (cleaned)'!B:B,0) -> 0 | H17: =_xlfn.XLOOKUP(B17,'ADS Prima (cleaned)'!A:A,'ADS Prima (cleaned)'!B:B,0) -> 0 | I17: =_xlfn.XLOOKUP(B17,'Auto Mekanika (cleaned)'!A:A,'Auto Mekanika (cleaned)'!B:B,0) -> 0 | J17: =_xlfn.XLOOKUP(B17,'Bengkel Multi Var (cleaned)'!A:A,'Bengkel Multi Var (cleaned)'!B:B,0) -> 0 | K17: 0 | L17: =_xlfn.XLOOKUP(B17,'Drivewell (cleaned)'!A:A,'Drivewell (cleaned)'!B:B,0) -> 0 | M17: 0 | N17: 0 | O17: 0 | P17: =_xlfn.XLOOKUP(B17,'CV Sun (cleaned)'!A:A,'CV Sun (cleaned)'!B:B,0) -> 0 | Q17: =_xlfn.XLOOKUP(B17,'Sumber Timur (clean)'!F:F,'Sumber Timur (clean)'!L:L,0) -> 0 | R17: =_xlfn.XLOOKUP(B17,'Honda Duren (clean)'!F:F,'Honda Duren (clean)'!L:L,0) -> 0 | S17: 0 | T17: =SUM(C17:S17) -> 0
A18: =VLOOKUP(B18,#REF!,5,0) -> #REF! | B18: MONROE Shock Absorber 744640SP Front-RH | C18: =_xlfn.XLOOKUP(B18,'Pit Stop (cleaned)'!A:A,'Pit Stop (cleaned)'!B:B,0) -> 0 | D18: =_xlfn.XLOOKUP(B18,'Subur Makmur Ban (Agg)'!$F$1:$F$5,'Subur Makmur Ban (Agg)'!$L$1:$L$5,0) -> 0 | E18: =_xlfn.XLOOKUP(B18,'Bengkel Pegasus (Agg)'!F:F,'Bengkel Pegasus (Agg)'!L:L,0) -> 0 | F18: =_xlfn.XLOOKUP(B18,'Autocraft (agg)'!F:F,'Autocraft (agg)'!L:L,0) -> 0 | G18: =_xlfn.XLOOKUP(B18,'Autones (cleaned)'!A:A,'Autones (cleaned)'!B:B,0) -> 0 | H18: =_xlfn.XLOOKUP(B18,'ADS Prima (cleaned)'!A:A,'ADS Prima (cleaned)'!B:B,0) -> 0 | I18: =_xlfn.XLOOKUP(B18,'Auto Mekanika (cleaned)'!A:A,'Auto Mekanika (cleaned)'!B:B,0) -> 0 | J18: =_xlfn.XLOOKUP(B18,'Bengkel Multi Var (cleaned)'!A:A,'Bengkel Multi Var (cleaned)'!B:B,0) -> 0 | K18: 0 | L18: =_xlfn.XLOOKUP(B18,'Drivewell (cleaned)'!A:A,'Drivewell (cleaned)'!B:B,0) -> 0 | M18: 0 | N18: 0 | O18: 0 | P18: =_xlfn.XLOOKUP(B18,'CV Sun (cleaned)'!A:A,'CV Sun (cleaned)'!B:B,0) -> 0 | Q18: =_xlfn.XLOOKUP(B18,'Sumber Timur (clean)'!F:F,'Sumber Timur (clean)'!L:L,0) -> 0 | R18: =_xlfn.XLOOKUP(B18,'Honda Duren (clean)'!F:F,'Honda Duren (clean)'!L:L,0) -> 0 | S18: 0 | T18: =SUM(C18:S18) -> 0
A19: =VLOOKUP(B19,#REF!,5,0) -> #REF! | B19: MONROE Shock Absorber 744563SP Front-LH | C19: =_xlfn.XLOOKUP(B19,'Pit Stop (cleaned)'!A:A,'Pit Stop (cleaned)'!B:B,0) -> 0 | D19: =_xlfn.XLOOKUP(B19,'Subur Makmur Ban (Agg)'!$F$1:$F$5,'Subur Makmur Ban (Agg)'!$L$1:$L$5,0) -> 0 | E19: =_xlfn.XLOOKUP(B19,'Bengkel Pegasus (Agg)'!F:F,'Bengkel Pegasus (Agg)'!L:L,0) -> 0 | F19: =_xlfn.XLOOKUP(B19,'Autocraft (agg)'!F:F,'Autocraft (agg)'!L:L,0) -> 0 | G19: =_xlfn.XLOOKUP(B19,'Autones (cleaned)'!A:A,'Autones (cleaned)'!B:B,0) -> 0 | H19: =_xlfn.XLOOKUP(B19,'ADS Prima (cleaned)'!A:A,'ADS Prima (cleaned)'!B:B,0) -> 0 | I19: =_xlfn.XLOOKUP(B19,'Auto Mekanika (cleaned)'!A:A,'Auto Mekanika (cleaned)'!B:B,0) -> 0 | J19: =_xlfn.XLOOKUP(B19,'Bengkel Multi Var (cleaned)'!A:A,'Bengkel Multi Var (cleaned)'!B:B,0) -> 0 | K19: 0 | L19: =_xlfn.XLOOKUP(B19,'Drivewell (cleaned)'!A:A,'Drivewell (cleaned)'!B:B,0) -> 0 | M19: 0 | N19: 0 | O19: 0 | P19: =_xlfn.XLOOKUP(B19,'CV Sun (cleaned)'!A:A,'CV Sun (cleaned)'!B:B,0) -> 0 | Q19: =_xlfn.XLOOKUP(B19,'Sumber Timur (clean)'!F:F,'Sumber Timur (clean)'!L:L,0) -> 0 | R19: =_xlfn.XLOOKUP(B19,'Honda Duren (clean)'!F:F,'Honda Duren (clean)'!L:L,0) -> 0 | S19: 0 | T19: =SUM(C19:S19) -> 0
A20: =VLOOKUP(B20,#REF!,5,0) -> #REF! | B20: MASSIV Battery Thunder(MF)-DIN 66 566LN3 12V-66Ah | C20: =_xlfn.XLOOKUP(B20,'Pit Stop (cleaned)'!A:A,'Pit Stop (cleaned)'!B:B,0) -> 0 | D20: =_xlfn.XLOOKUP(B20,'Subur Makmur Ban (Agg)'!$F$1:$F$5,'Subur Makmur Ban (Agg)'!$L$1:$L$5,0) -> 0 | E20: =_xlfn.XLOOKUP(B20,'Bengkel Pegasus (Agg)'!F:F,'Bengkel Pegasus (Agg)'!L:L,0) -> 0 | F20: =_xlfn.XLOOKUP(B20,'Autocraft (agg)'!F:F,'Autocraft (agg)'!L:L,0) -> 0 | G20: =_xlfn.XLOOKUP(B20,'Autones (cleaned)'!A:A,'Autones (cleaned)'!B:B,0) -> 0 | H20: =_xlfn.XLOOKUP(B20,'ADS Prima (cleaned)'!A:A,'ADS Prima (cleaned)'!B:B,0) -> 0 | I20: =_xlfn.XLOOKUP(B20,'Auto Mekanika (cleaned)'!A:A,'Auto Mekanika (cleaned)'!B:B,0) -> 0 | J20: =_xlfn.XLOOKUP(B20,'Bengkel Multi Var (cleaned)'!A:A,'Bengkel Multi Var (cleaned)'!B:B,0) -> 0 | K20: 0 | L20: =_xlfn.XLOOKUP(B20,'Drivewell (cleaned)'!A:A,'Drivewell (cleaned)'!B:B,0) -> 0 | M20: 0 | N20: 0 | O20: 0 | P20: =_xlfn.XLOOKUP(B20,'CV Sun (cleaned)'!A:A,'CV Sun (cleaned)'!B:B,0) -> 0 | Q20: =_xlfn.XLOOKUP(B20,'Sumber Timur (clean)'!F:F,'Sumber Timur (clean)'!L:L,0) -> 0 | R20: =_xlfn.XLOOKUP(B20,'Honda Duren (clean)'!F:F,'Honda Duren (clean)'!L:L,0) -> 0 | S20: 0 | T20: =SUM(C20:S20) -> 0
A21: =VLOOKUP(B21,#REF!,5,0) -> #REF! | B21: MONROE Shock Absorber 744562SP Front-RH | C21: =_xlfn.XLOOKUP(B21,'Pit Stop (cleaned)'!A:A,'Pit Stop (cleaned)'!B:B,0) -> 0 | D21: =_xlfn.XLOOKUP(B21,'Subur Makmur Ban (Agg)'!$F$1:$F$5,'Subur Makmur Ban (Agg)'!$L$1:$L$5,0) -> 0 | E21: =_xlfn.XLOOKUP(B21,'Bengkel Pegasus (Agg)'!F:F,'Bengkel Pegasus (Agg)'!L:L,0) -> 0 | F21: =_xlfn.XLOOKUP(B21,'Autocraft (agg)'!F:F,'Autocraft (agg)'!L:L,0) -> 0 | G21: =_xlfn.XLOOKUP(B21,'Autones (cleaned)'!A:A,'Autones (cleaned)'!B:B,0) -> 0 | H21: =_xlfn.XLOOKUP(B21,'ADS Prima (cleaned)'!A:A,'ADS Prima (cleaned)'!B:B,0) -> 0 | I21: =_xlfn.XLOOKUP(B21,'Auto Mekanika (cleaned)'!A:A,'Auto Mekanika (cleaned)'!B:B,0) -> 0 | J21: =_xlfn.XLOOKUP(B21,'Bengkel Multi Var (cleaned)'!A:A,'Bengkel Multi Var (cleaned)'!B:B,0) -> 0 | K21: 0 | L21: =_xlfn.XLOOKUP(B21,'Drivewell (cleaned)'!A:A,'Drivewell (cleaned)'!B:B,0) -> 0 | M21: 0 | N21: 0 | O21: 0 | P21: =_xlfn.XLOOKUP(B21,'CV Sun (cleaned)'!A:A,'CV Sun (cleaned)'!B:B,0) -> 0 | Q21: =_xlfn.XLOOKUP(B21,'Sumber Timur (clean)'!F:F,'Sumber Timur (clean)'!L:L,0) -> 0 | R21: =_xlfn.XLOOKUP(B21,'Honda Duren (clean)'!F:F,'Honda Duren (clean)'!L:L,0) -> 0 | S21: 0 | T21: =SUM(C21:S21) -> 0
A22: =VLOOKUP(B22,#REF!,5,0) -> #REF! | B22: BOSCH Oil Filter P 9762 | C22: =_xlfn.XLOOKUP(B22,'Pit Stop (cleaned)'!A:A,'Pit Stop (cleaned)'!B:B,0) -> 0 | D22: =_xlfn.XLOOKUP(B22,'Subur Makmur Ban (Agg)'!$F$1:$F$5,'Subur Makmur Ban (Agg)'!$L$1:$L$5,0) -> 0 | E22: =_xlfn.XLOOKUP(B22,'Bengkel Pegasus (Agg)'!F:F,'Bengkel Pegasus (Agg)'!L:L,0) -> 0 | F22: =_xlfn.XLOOKUP(B22,'Autocraft (agg)'!F:F,'Autocraft (agg)'!L:L,0) -> 0 | G22: =_xlfn.XLOOKUP(B22,'Autones (cleaned)'!A:A,'Autones (cleaned)'!B:B,0) -> 0 | H22: =_xlfn.XLOOKUP(B22,'ADS Prima (cleaned)'!A:A,'ADS Prima (cleaned)'!B:B,0) -> 0 | I22: =_xlfn.XLOOKUP(B22,'Auto Mekanika (cleaned)'!A:A,'Auto Mekanika (cleaned)'!B:B,0) -> 0 | J22: =_xlfn.XLOOKUP(B22,'Bengkel Multi Var (cleaned)'!A:A,'Bengkel Multi Var (cleaned)'!B:B,0) -> 0 | K22: 0 | L22: =_xlfn.XLOOKUP(B22,'Drivewell (cleaned)'!A:A,'Drivewell (cleaned)'!B:B,0) -> 0 | M22: 0 | N22: 0 | O22: 0 | P22: =_xlfn.XLOOKUP(B22,'CV Sun (cleaned)'!A:A,'CV Sun (cleaned)'!B:B,0) -> 0 | Q22: =_xlfn.XLOOKUP(B22,'Sumber Timur (clean)'!F:F,'Sumber Timur (clean)'!L:L,0) -> 0 | R22: =_xlfn.XLOOKUP(B22,'Honda Duren (clean)'!F:F,'Honda Duren (clean)'!L:L,0) -> 0 | S22: 0 | T22: =SUM(C22:S22) -> 0
A23: =VLOOKUP(B23,#REF!,5,0) -> #REF! | B23: BOSCH Battery MF Blue 58014 12V-80Ah | C23: =_xlfn.XLOOKUP(B23,'Pit Stop (cleaned)'!A:A,'Pit Stop (cleaned)'!B:B,0) -> 0 | D23: =_xlfn.XLOOKUP(B23,'Subur Makmur Ban (Agg)'!$F$1:$F$5,'Subur Makmur Ban (Agg)'!$L$1:$L$5,0) -> 0 | E23: =_xlfn.XLOOKUP(B23,'Bengkel Pegasus (Agg)'!F:F,'Bengkel Pegasus (Agg)'!L:L,0) -> 0 | F23: =_xlfn.XLOOKUP(B23,'Autocraft (agg)'!F:F,'Autocraft (agg)'!L:L,0) -> 0 | G23: =_xlfn.XLOOKUP(B23,'Autones (cleaned)'!A:A,'Autones (cleaned)'!B:B,0) -> 0 | H23: =_xlfn.XLOOKUP(B23,'ADS Prima (cleaned)'!A:A,'ADS Prima (cleaned)'!B:B,0) -> 0 | I23: =_xlfn.XLOOKUP(B23,'Auto Mekanika (cleaned)'!A:A,'Auto Mekanika (cleaned)'!B:B,0) -> 0 | J23: =_xlfn.XLOOKUP(B23,'Bengkel Multi Var (cleaned)'!A:A,'Bengkel Multi Var (cleaned)'!B:B,0) -> 0 | K23: 0 | L23: =_xlfn.XLOOKUP(B23,'Drivewell (cleaned)'!A:A,'Drivewell (cleaned)'!B:B,0) -> 0 | M23: 0 | N23: 0 | O23: 0 | P23: =_xlfn.XLOOKUP(B23,'CV Sun (cleaned)'!A:A,'CV Sun (cleaned)'!B:B,0) -> 0 | Q23: =_xlfn.XLOOKUP(B23,'Sumber Timur (clean)'!F:F,'Sumber Timur (clean)'!L:L,0) -> 0 | R23: =_xlfn.XLOOKUP(B23,'Honda Duren (clean)'!F:F,'Honda Duren (clean)'!L:L,0) -> 0 | S23: 0 | T23: =SUM(C23:S23) -> 0
A24: =VLOOKUP(B24,#REF!,5,0) -> #REF! | B24: MONROE Shock Absorber 744515SP Front-LH | C24: =_xlfn.XLOOKUP(B24,'Pit Stop (cleaned)'!A:A,'Pit Stop (cleaned)'!B:B,0) -> 0 | D24: =_xlfn.XLOOKUP(B24,'Subur Makmur Ban (Agg)'!$F$1:$F$5,'Subur Makmur Ban (Agg)'!$L$1:$L$5,0) -> 0 | E24: =_xlfn.XLOOKUP(B24,'Bengkel Pegasus (Agg)'!F:F,'Bengkel Pegasus (Agg)'!L:L,0) -> 0 | F24: =_xlfn.XLOOKUP(B24,'Autocraft (agg)'!F:F,'Autocraft (agg)'!L:L,0) -> 0 | G24: =_xlfn.XLOOKUP(B24,'Autones (cleaned)'!A:A,'Autones (cleaned)'!B:B,0) -> 0 | H24: =_xlfn.XLOOKUP(B24,'ADS Prima (cleaned)'!A:A,'ADS Prima (cleaned)'!B:B,0) -> 0 | I24: =_xlfn.XLOOKUP(B24,'Auto Mekanika (cleaned)'!A:A,'Auto Mekanika (cleaned)'!B:B,0) -> 0 | J24: =_xlfn.XLOOKUP(B24,'Bengkel Multi Var (cleaned)'!A:A,'Bengkel Multi Var (cleaned)'!B:B,0) -> 0 | K24: 0 | L24: =_xlfn.XLOOKUP(B24,'Drivewell (cleaned)'!A:A,'Drivewell (cleaned)'!B:B,0) -> 0 | M24: 0 | N24: 0 | O24: 0 | P24: =_xlfn.XLOOKUP(B24,'CV Sun (cleaned)'!A:A,'CV Sun (cleaned)'!B:B,0) -> 0 | Q24: =_xlfn.XLOOKUP(B24,'Sumber Timur (clean)'!F:F,'Sumber Timur (clean)'!L:L,0) -> 0 | R24: =_xlfn.XLOOKUP(B24,'Honda Duren (clean)'!F:F,'Honda Duren (clean)'!L:L,0) -> 0 | S24: 0 | T24: =SUM(C24:S24) -> 0
A25: =VLOOKUP(B25,#REF!,5,0) -> #REF! | B25: MONROE Shock Absorber 744514SP Front-RH | C25: =_xlfn.XLOOKUP(B25,'Pit Stop (cleaned)'!A:A,'Pit Stop (cleaned)'!B:B,0) -> 0 | D25: =_xlfn.XLOOKUP(B25,'Subur Makmur Ban (Agg)'!$F$1:$F$5,'Subur Makmur Ban (Agg)'!$L$1:$L$5,0) -> 0 | E25: =_xlfn.XLOOKUP(B25,'Bengkel Pegasus (Agg)'!F:F,'Bengkel Pegasus (Agg)'!L:L,0) -> 0 | F25: =_xlfn.XLOOKUP(B25,'Autocraft (agg)'!F:F,'Autocraft (agg)'!L:L,0) -> 0 | G25: =_xlfn.XLOOKUP(B25,'Autones (cleaned)'!A:A,'Autones (cleaned)'!B:B,0) -> 0 | H25: =_xlfn.XLOOKUP(B25,'ADS Prima (cleaned)'!A:A,'ADS Prima (cleaned)'!B:B,0) -> 0 | I25: =_xlfn.XLOOKUP(B25,'Auto Mekanika (cleaned)'!A:A,'Auto Mekanika (cleaned)'!B:B,0) -> 0 | J25: =_xlfn.XLOOKUP(B25,'Bengkel Multi Var (cleaned)'!A:A,'Bengkel Multi Var (cleaned)'!B:B,0) -> 0 | K25: 0 | L25: =_xlfn.XLOOKUP(B25,'Drivewell (cleaned)'!A:A,'Drivewell (cleaned)'!B:B,0) -> 0 | M25: 0 | N25: 0 | O25: 0 | P25: =_xlfn.XLOOKUP(B25,'CV Sun (cleaned)'!A:A,'CV Sun (cleaned)'!B:B,0) -> 0 | Q25: =_xlfn.XLOOKUP(B25,'Sumber Timur (clean)'!F:F,'Sumber Timur (clean)'!L:L,0) -> 0 | R25: =_xlfn.XLOOKUP(B25,'Honda Duren (clean)'!F:F,'Honda Duren (clean)'!L:L,0) -> 0 | S25: 0 | T25: =SUM(C25:S25) -> 0
... A40: =VLOOKUP(B40,#REF!,5,0) -> #REF! | B40: DENSO Spark Plug IT20 - Iridium | C40: =_xlfn.XLOOKUP(B40,'Pit Stop (cleaned)'!A:A,'Pit Stop (cleaned)'!B:B,0) -> 0 | D40: =_xlfn.XLOOKUP(B40,'Subur Makmur Ban (Agg)'!$F$1:$F$5,'Subur Makmur Ban (Agg)'!$L$1:$L$5,0) -> 0 | E40: =_xlfn.XLOOKUP(B40,'Bengkel Pegasus (Agg)'!F:F,'Bengkel Pegasus (Agg)'!L:L,0) -> 0 | F40: =_xlfn.XLOOKUP(B40,'Autocraft (agg)'!F:F,'Autocraft (agg)'!L:L,0) -> 0 | G40: =_xlfn.XLOOKUP(B40,'Autones (cleaned)'!A:A,'Autones (cleaned)'!B:B,0) -> 0 | H40: =_xlfn.XLOOKUP(B40,'ADS Prima (cleaned)'!A:A,'ADS Prima (cleaned)'!B:B,0) -> 0 | I40: =_xlfn.XLOOKUP(B40,'Auto Mekanika (cleaned)'!A:A,'Auto Mekanika (cleaned)'!B:B,0) -> 0 | J40: =_xlfn.XLOOKUP(B40,'Bengkel Multi Var (cleaned)'!A:A,'Bengkel Multi Var (cleaned)'!B:B,0) -> 0 | K40: 0 | L40: =_xlfn.XLOOKUP(B40,'Drivewell (cleaned)'!A:A,'Drivewell (cleaned)'!B:B,0) -> 0 | M40: 0 | N40: 0 | O40: 0 | P40: =_xlfn.XLOOKUP(B40,'CV Sun (cleaned)'!A:A,'CV Sun (cleaned)'!B:B,0) -> 0 | Q40: =_xlfn.XLOOKUP(B40,'Sumber Timur (clean)'!F:F,'Sumber Timur (clean)'!L:L,0) -> 0 | R40: =_xlfn.XLOOKUP(B40,'Honda Duren (clean)'!F:F,'Honda Duren (clean)'!L:L,0) -> 0 | S40: 0 | T40: =SUM(C40:S40) -> 0
A41: =VLOOKUP(B41,#REF!,5,0) -> #REF! | B41: BOSCH Battery MF Blue NX100-S6L 55B24L 12V-45Ah | C41: =_xlfn.XLOOKUP(B41,'Pit Stop (cleaned)'!A:A,'Pit Stop (cleaned)'!B:B,0) -> 0 | D41: =_xlfn.XLOOKUP(B41,'Subur Makmur Ban (Agg)'!$F$1:$F$5,'Subur Makmur Ban (Agg)'!$L$1:$L$5,0) -> 0 | E41: =_xlfn.XLOOKUP(B41,'Bengkel Pegasus (Agg)'!F:F,'Bengkel Pegasus (Agg)'!L:L,0) -> 0 | F41: =_xlfn.XLOOKUP(B41,'Autocraft (agg)'!F:F,'Autocraft (agg)'!L:L,0) -> 0 | G41: =_xlfn.XLOOKUP(B41,'Autones (cleaned)'!A:A,'Autones (cleaned)'!B:B,0) -> 0 | H41: =_xlfn.XLOOKUP(B41,'ADS Prima (cleaned)'!A:A,'ADS Prima (cleaned)'!B:B,0) -> 0 | I41: =_xlfn.XLOOKUP(B41,'Auto Mekanika (cleaned)'!A:A,'Auto Mekanika (cleaned)'!B:B,0) -> 5 | J41: =_xlfn.XLOOKUP(B41,'Bengkel Multi Var (cleaned)'!A:A,'Bengkel Multi Var (cleaned)'!B:B,0) -> 0 | K41: =_xlfn.XLOOKUP(B41,'[2]EURO GALLARIA'!F:F,'[2]EURO GALLARIA'!L:L,0) -> 0 | L41: =_xlfn.XLOOKUP(B41,'Drivewell (cleaned)'!A:A,'Drivewell (cleaned)'!B:B,0) -> 0 | M41: =_xlfn.XLOOKUP(B41,'[2]Mersi (CLEAN)'!D:D,'[2]Mersi (CLEAN)'!E:E,0) -> 0 | N41: 0 | O41: 0 | P41: =_xlfn.XLOOKUP(B41,'CV Sun (cleaned)'!A:A,'CV Sun (cleaned)'!B:B,0) -> 0 | Q41: =_xlfn.XLOOKUP(B41,'Sumber Timur (clean)'!F:F,'Sumber Timur (clean)'!L:L,0) -> 0 | R41: =_xlfn.XLOOKUP(B41,'Honda Duren (clean)'!F:F,'Honda Duren (clean)'!L:L,0) -> 3 | S41: =_xlfn.XLOOKUP(B41,'[2]LAVANDER CLEAN'!A:A,'[2]LAVANDER CLEAN'!B:B,0) -> 0 | T41: =SUM(C41:S41) -> 8 | U41: 705060 | V41: =IF(T41*U41=0,"",T41*U41) -> 5640480 | W41: 0986A00406
A42: =VLOOKUP(B42,#REF!,5,0) -> #REF! | B42: BOSCH Battery MF Blue NX100-S6 55B24R 12V-45Ah | C42: =_xlfn.XLOOKUP(B42,'Pit Stop (cleaned)'!A:A,'Pit Stop (cleaned)'!B:B,0) -> 0 | D42: =_xlfn.XLOOKUP(B42,'Subur Makmur Ban (Agg)'!$F$1:$F$5,'Subur Makmur Ban (Agg)'!$L$1:$L$5,0) -> 0 | E42: =_xlfn.XLOOKUP(B42,'Bengkel Pegasus (Agg)'!F:F,'Bengkel Pegasus (Agg)'!L:L,0) -> 0 | F42: =_xlfn.XLOOKUP(B42,'Autocraft (agg)'!F:F,'Autocraft (agg)'!L:L,0) -> 0 | G42: =_xlfn.XLOOKUP(B42,'Autones (cleaned)'!A:A,'Autones (cleaned)'!B:B,0) -> 0 | H42: =_xlfn.XLOOKUP(B42,'ADS Prima (cleaned)'!A:A,'ADS Prima (cleaned)'!B:B,0) -> 0 | I42: =_xlfn.XLOOKUP(B42,'Auto Mekanika (cleaned)'!A:A,'Auto Mekanika (cleaned)'!B:B,0) -> 15 | J42: =_xlfn.XLOOKUP(B42,'Bengkel Multi Var (cleaned)'!A:A,'Bengkel Multi Var (cleaned)'!B:B,0) -> 0 | K42: =_xlfn.XLOOKUP(B42,'[2]EURO GALLARIA'!F:F,'[2]EURO GALLARIA'!L:L,0) -> 0 | L42: =_xlfn.XLOOKUP(B42,'Drivewell (cleaned)'!A:A,'Drivewell (cleaned)'!B:B,0) -> 0 | M42: =_xlfn.XLOOKUP(B42,'[2]Mersi (CLEAN)'!D:D,'[2]Mersi (CLEAN)'!E:E,0) -> 0 | N42: 0 | O42: 0 | P42: =_xlfn.XLOOKUP(B42,'CV Sun (cleaned)'!A:A,'CV Sun (cleaned)'!B:B,0) -> 0 | Q42: =_xlfn.XLOOKUP(B42,'Sumber Timur (clean)'!F:F,'Sumber Timur (clean)'!L:L,0) -> 0 | R42: =_xlfn.XLOOKUP(B42,'Honda Duren (clean)'!F:F,'Honda Duren (clean)'!L:L,0) -> 0 | S42: =_xlfn.XLOOKUP(B42,'[2]LAVANDER CLEAN'!A:A,'[2]LAVANDER CLEAN'!B:B,0) -> 0 | T42: =SUM(C42:S42) -> 15 | U42: 705060 | V42: =IF(T42*U42=0,"",T42*U42) -> 10575900 | W42: 0986A00407
A43: =VLOOKUP(B43,#REF!,5,0) -> #REF! | B43: MONROE Shock Absorber 744453SP Rear-LH | C43: =_xlfn.XLOOKUP(B43,'Pit Stop (cleaned)'!A:A,'Pit Stop (cleaned)'!B:B,0) -> 0 | D43: =_xlfn.XLOOKUP(B43,'Subur Makmur Ban (Agg)'!$F$1:$F$5,'Subur Makmur Ban (Agg)'!$L$1:$L$5,0) -> 0 | E43: =_xlfn.XLOOKUP(B43,'Bengkel Pegasus (Agg)'!F:F,'Bengkel Pegasus (Agg)'!L:L,0) -> 0 | F43: =_xlfn.XLOOKUP(B43,'Autocraft (agg)'!F:F,'Autocraft (agg)'!L:L,0) -> 0 | G43: =_xlfn.XLOOKUP(B43,'Autones (cleaned)'!A:A,'Autones (cleaned)'!B:B,0) -> 0 | H43: =_xlfn.XLOOKUP(B43,'ADS Prima (cleaned)'!A:A,'ADS Prima (cleaned)'!B:B,0) -> 0 | I43: =_xlfn.XLOOKUP(B43,'Auto Mekanika (cleaned)'!A:A,'Auto Mekanika (cleaned)'!B:B,0) -> 0 | J43: =_xlfn.XLOOKUP(B43,'Bengkel Multi Var (cleaned)'!A:A,'Bengkel Multi Var (cleaned)'!B:B,0) -> 0 | K43: 0 | L43: =_xlfn.XLOOKUP(B43,'Drivewell (cleaned)'!A:A,'Drivewell (cleaned)'!B:B,0) -> 0 | M43: 0 | N43: 0 | O43: 0 | P43: =_xlfn.XLOOKUP(B43,'CV Sun (cleaned)'!A:A,'CV Sun (cleaned)'!B:B,0) -> 0 | Q43: =_xlfn.XLOOKUP(B43,'Sumber Timur (clean)'!F:F,'Sumber Timur (clean)'!L:L,0) -> 0 | R43: =_xlfn.XLOOKUP(B43,'Honda Duren (clean)'!F:F,'Honda Duren (clean)'!L:L,0) -> 0 | S43: 0 | T43: =SUM(C43:S43) -> 0
A44: =VLOOKUP(B44,#REF!,5,0) -> #REF! | B44: MONROE Shock Absorber 744452SP Rear-RH | C44: =_xlfn.XLOOKUP(B44,'Pit Stop (cleaned)'!A:A,'Pit Stop (cleaned)'!B:B,0) -> 0 | D44: =_xlfn.XLOOKUP(B44,'Subur Makmur Ban (Agg)'!$F$1:$F$5,'Subur Makmur Ban (Agg)'!$L$1:$L$5,0) -> 0 | E44: =_xlfn.XLOOKUP(B44,'Bengkel Pegasus (Agg)'!F:F,'Bengkel Pegasus (Agg)'!L:L,0) -> 0 | F44: =_xlfn.XLOOKUP(B44,'Autocraft (agg)'!F:F,'Autocraft (agg)'!L:L,0) -> 0 | G44: =_xlfn.XLOOKUP(B44,'Autones (cleaned)'!A:A,'Autones (cleaned)'!B:B,0) -> 0 | H44: =_xlfn.XLOOKUP(B44,'ADS Prima (cleaned)'!A:A,'ADS Prima (cleaned)'!B:B,0) -> 0 | I44: =_xlfn.XLOOKUP(B44,'Auto Mekanika (cleaned)'!A:A,'Auto Mekanika (cleaned)'!B:B,0) -> 0 | J44: =_xlfn.XLOOKUP(B44,'Bengkel Multi Var (cleaned)'!A:A,'Bengkel Multi Var (cleaned)'!B:B,0) -> 0 | K44: 0 | L44: =_xlfn.XLOOKUP(B44,'Drivewell (cleaned)'!A:A,'Drivewell (cleaned)'!B:B,0) -> 0 | M44: 0 | N44: 0 | O44: 0 | P44: =_xlfn.XLOOKUP(B44,'CV Sun (cleaned)'!A:A,'CV Sun (cleaned)'!B:B,0) -> 0 | Q44: =_xlfn.XLOOKUP(B44,'Sumber Timur (clean)'!F:F,'Sumber Timur (clean)'!L:L,0) -> 0 | R44: =_xlfn.XLOOKUP(B44,'Honda Duren (clean)'!F:F,'Honda Duren (clean)'!L:L,0) -> 0 | S44: 0 | T44: =SUM(C44:S44) -> 0
A45: =VLOOKUP(B45,#REF!,5,0) -> #REF! | B45: MONROE Shock Absorber 744451SP Front-LH | C45: =_xlfn.XLOOKUP(B45,'Pit Stop (cleaned)'!A:A,'Pit Stop (cleaned)'!B:B,0) -> 0 | D45: =_xlfn.XLOOKUP(B45,'Subur Makmur Ban (Agg)'!$F$1:$F$5,'Subur Makmur Ban (Agg)'!$L$1:$L$5,0) -> 0 | E45: =_xlfn.XLOOKUP(B45,'Bengkel Pegasus (Agg)'!F:F,'Bengkel Pegasus (Agg)'!L:L,0) -> 0 | F45: =_xlfn.XLOOKUP(B45,'Autocraft (agg)'!F:F,'Autocraft (agg)'!L:L,0) -> 0 | G45: =_xlfn.XLOOKUP(B45,'Autones (cleaned)'!A:A,'Autones (cleaned)'!B:B,0) -> 0 | H45: =_xlfn.XLOOKUP(B45,'ADS Prima (cleaned)'!A:A,'ADS Prima (cleaned)'!B:B,0) -> 0 | I45: =_xlfn.XLOOKUP(B45,'Auto Mekanika (cleaned)'!A:A,'Auto Mekanika (cleaned)'!B:B,0) -> 0 | J45: =_xlfn.XLOOKUP(B45,'Bengkel Multi Var (cleaned)'!A:A,'Bengkel Multi Var (cleaned)'!B:B,0) -> 0 | K45: 0 | L45: =_xlfn.XLOOKUP(B45,'Drivewell (cleaned)'!A:A,'Drivewell (cleaned)'!B:B,0) -> 0 | M45: 0 | N45: 0 | O45: 0 | P45: =_xlfn.XLOOKUP(B45,'CV Sun (cleaned)'!A:A,'CV Sun (cleaned)'!B:B,0) -> 0 | Q45: =_xlfn.XLOOKUP(B45,'Sumber Timur (clean)'!F:F,'Sumber Timur (clean)'!L:L,0) -> 0 | R45: =_xlfn.XLOOKUP(B45,'Honda Duren (clean)'!F:F,'Honda Duren (clean)'!L:L,0) -> 0 | S45: 0 | T45: =SUM(C45:S45) -> 0
A46: =VLOOKUP(B46,#REF!,5,0) -> #REF! | B46: MONROE Shock Absorber 744450SP Front-RH | C46: =_xlfn.XLOOKUP(B46,'Pit Stop (cleaned)'!A:A,'Pit Stop (cleaned)'!B:B,0) -> 0 | D46: =_xlfn.XLOOKUP(B46,'Subur Makmur Ban (Agg)'!$F$1:$F$5,'Subur Makmur Ban (Agg)'!$L$1:$L$5,0) -> 0 | E46: =_xlfn.XLOOKUP(B46,'Bengkel Pegasus (Agg)'!F:F,'Bengkel Pegasus (Agg)'!L:L,0) -> 0 | F46: =_xlfn.XLOOKUP(B46,'Autocraft (agg)'!F:F,'Autocraft (agg)'!L:L,0) -> 0 | G46: =_xlfn.XLOOKUP(B46,'Autones (cleaned)'!A:A,'Autones (cleaned)'!B:B,0) -> 0 | H46: =_xlfn.XLOOKUP(B46,'ADS Prima (cleaned)'!A:A,'ADS Prima (cleaned)'!B:B,0) -> 0 | I46: =_xlfn.XLOOKUP(B46,'Auto Mekanika (cleaned)'!A:A,'Auto Mekanika (cleaned)'!B:B,0) -> 0 | J46: =_xlfn.XLOOKUP(B46,'Bengkel Multi Var (cleaned)'!A:A,'Bengkel Multi Var (cleaned)'!B:B,0) -> 0 | K46: 0 | L46: =_xlfn.XLOOKUP(B46,'Drivewell (cleaned)'!A:A,'Drivewell (cleaned)'!B:B,0) -> 0 | M46: 0 | N46: 0 | O46: 0 | P46: =_xlfn.XLOOKUP(B46,'CV Sun (cleaned)'!A:A,'CV Sun (cleaned)'!B:B,0) -> 0 | Q46: =_xlfn.XLOOKUP(B46,'Sumber Timur (clean)'!F:F,'Sumber Timur (clean)'!L:L,0) -> 0 | R46: =_xlfn.XLOOKUP(B46,'Honda Duren (clean)'!F:F,'Honda Duren (clean)'!L:L,0) -> 0 | S46: 0 | T46: =SUM(C46:S46) -> 0
A47: =VLOOKUP(B47,#REF!,5,0) -> #REF! | B47: MONROE Shock Absorber 744445SP Front | C47: =_xlfn.XLOOKUP(B47,'Pit Stop (cleaned)'!A:A,'Pit Stop (cleaned)'!B:B,0) -> 0 | D47: =_xlfn.XLOOKUP(B47,'Subur Makmur Ban (Agg)'!$F$1:$F$5,'Subur Makmur Ban (Agg)'!$L$1:$L$5,0) -> 0 | E47: =_xlfn.XLOOKUP(B47,'Bengkel Pegasus (Agg)'!F:F,'Bengkel Pegasus (Agg)'!L:L,0) -> 0 | F47: =_xlfn.XLOOKUP(B47,'Autocraft (agg)'!F:F,'Autocraft (agg)'!L:L,0) -> 0 | G47: =_xlfn.XLOOKUP(B47,'Autones (cleaned)'!A:A,'Autones (cleaned)'!B:B,0) -> 0 | H47: =_xlfn.XLOOKUP(B47,'ADS Prima (cleaned)'!A:A,'ADS Prima (cleaned)'!B:B,0) -> 0 | I47: =_xlfn.XLOOKUP(B47,'Auto Mekanika (cleaned)'!A:A,'Auto Mekanika (cleaned)'!B:B,0) -> 0 | J47: =_xlfn.XLOOKUP(B47,'Bengkel Multi Var (cleaned)'!A:A,'Bengkel Multi Var (cleaned)'!B:B,0) -> 0 | K47: 0 | L47: =_xlfn.XLOOKUP(B47,'Drivewell (cleaned)'!A:A,'Drivewell (cleaned)'!B:B,0) -> 0 | M47: 0 | N47: 0 | O47: 0 | P47: =_xlfn.XLOOKUP(B47,'CV Sun (cleaned)'!A:A,'CV Sun (cleaned)'!B:B,0) -> 0 | Q47: =_xlfn.XLOOKUP(B47,'Sumber Timur (clean)'!F:F,'Sumber Timur (clean)'!L:L,0) -> 0 | R47: =_xlfn.XLOOKUP(B47,'Honda Duren (clean)'!F:F,'Honda Duren (clean)'!L:L,0) -> 0 | S47: 0 | T47: =SUM(C47:S47) -> 0
A48: =VLOOKUP(B48,#REF!,5,0) -> #REF! | B48: MONROE Shock Absorber 744444SP Rear | C48: =_xlfn.XLOOKUP(B48,'Pit Stop (cleaned)'!A:A,'Pit Stop (cleaned)'!B:B,0) -> 0 | D48: =_xlfn.XLOOKUP(B48,'Subur Makmur Ban (Agg)'!$F$1:$F$5,'Subur Makmur Ban (Agg)'!$L$1:$L$5,0) -> 0 | E48: =_xlfn.XLOOKUP(B48,'Bengkel Pegasus (Agg)'!F:F,'Bengkel Pegasus (Agg)'!L:L,0) -> 0 | F48: =_xlfn.XLOOKUP(B48,'Autocraft (agg)'!F:F,'Autocraft (agg)'!L:L,0) -> 0 | G48: =_xlfn.XLOOKUP(B48,'Autones (cleaned)'!A:A,'Autones (cleaned)'!B:B,0) -> 0 | H48: =_xlfn.XLOOKUP(B48,'ADS Prima (cleaned)'!A:A,'ADS Prima (cleaned)'!B:B,0) -> 0 | I48: =_xlfn.XLOOKUP(B48,'Auto Mekanika (cleaned)'!A:A,'Auto Mekanika (cleaned)'!B:B,0) -> 0 | J48: =_xlfn.XLOOKUP(B48,'Bengkel Multi Var (cleaned)'!A:A,'Bengkel Multi Var (cleaned)'!B:B,0) -> 0 | K48: 0 | L48: =_xlfn.XLOOKUP(B48,'Drivewell (cleaned)'!A:A,'Drivewell (cleaned)'!B:B,0) -> 0 | M48: 0 | N48: 0 | O48: 0 | P48: =_xlfn.XLOOKUP(B48,'CV Sun (cleaned)'!A:A,'CV Sun (cleaned)'!B:B,0) -> 0 | Q48: =_xlfn.XLOOKUP(B48,'Sumber Timur (clean)'!F:F,'Sumber Timur (clean)'!L:L,0) -> 0 | R48: =_xlfn.XLOOKUP(B48,'Honda Duren (clean)'!F:F,'Honda Duren (clean)'!L:L,0) -> 0 | S48: 0 | T48: =SUM(C48:S48) -> 0
A49: =VLOOKUP(B49,#REF!,5,0) -> #REF! | B49: MOBIL Gear Oil Mobilube-HD 80W-90 1L | C49: =_xlfn.XLOOKUP(B49,'Pit Stop (cleaned)'!A:A,'Pit Stop (cleaned)'!B:B,0) -> 0 | D49: =_xlfn.XLOOKUP(B49,'Subur Makmur Ban (Agg)'!$F$1:$F$5,'Subur Makmur Ban (Agg)'!$L$1:$L$5,0) -> 0 | E49: =_xlfn.XLOOKUP(B49,'Bengkel Pegasus (Agg)'!F:F,'Bengkel Pegasus (Agg)'!L:L,0) -> 0 | F49: =_xlfn.XLOOKUP(B49,'Autocraft (agg)'!F:F,'Autocraft (agg)'!L:L,0) -> 0 | G49: =_xlfn.XLOOKUP(B49,'Autones (cleaned)'!A:A,'Autones (cleaned)'!B:B,0) -> 0 | H49: =_xlfn.XLOOKUP(B49,'ADS Prima (cleaned)'!A:A,'ADS Prima (cleaned)'!B:B,0) -> 0 | I49: =_xlfn.XLOOKUP(B49,'Auto Mekanika (cleaned)'!A:A,'Auto Mekanika (cleaned)'!B:B,0) -> 0 | J49: =_xlfn.XLOOKUP(B49,'Bengkel Multi Var (cleaned)'!A:A,'Bengkel Multi Var (cleaned)'!B:B,0) -> 0 | K49: 0 | L49: =_xlfn.XLOOKUP(B49,'Drivewell (cleaned)'!A:A,'Drivewell (cleaned)'!B:B,0) -> 0 | M49: 0 | N49: 0 | O49: 0 | P49: =_xlfn.XLOOKUP(B49,'CV Sun (cleaned)'!A:A,'CV Sun (cleaned)'!B:B,0) -> 0 | Q49: =_xlfn.XLOOKUP(B49,'Sumber Timur (clean)'!F:F,'Sumber Timur (clean)'!L:L,0) -> 0 | R49: =_xlfn.XLOOKUP(B49,'Honda Duren (clean)'!F:F,'Honda Duren (clean)'!L:L,0) -> 0 | S49: 0 | T49: =SUM(C49:S49) -> 0
A50: =VLOOKUP(B50,#REF!,5,0) -> #REF! | B50: BOSCH Oil Filter O 0203 | C50: =_xlfn.XLOOKUP(B50,'Pit Stop (cleaned)'!A:A,'Pit Stop (cleaned)'!B:B,0) -> 0 | D50: =_xlfn.XLOOKUP(B50,'Subur Makmur Ban (Agg)'!$F$1:$F$5,'Subur Makmur Ban (Agg)'!$L$1:$L$5,0) -> 0 | E50: =_xlfn.XLOOKUP(B50,'Bengkel Pegasus (Agg)'!F:F,'Bengkel Pegasus (Agg)'!L:L,0) -> 0 | F50: =_xlfn.XLOOKUP(B50,'Autocraft (agg)'!F:F,'Autocraft (agg)'!L:L,0) -> 0 | G50: =_xlfn.XLOOKUP(B50,'Autones (cleaned)'!A:A,'Autones (cleaned)'!B:B,0) -> 0 | H50: =_xlfn.XLOOKUP(B50,'ADS Prima (cleaned)'!A:A,'ADS Prima (cleaned)'!B:B,0) -> 0 | I50: =_xlfn.XLOOKUP(B50,'Auto Mekanika (cleaned)'!A:A,'Auto Mekanika (cleaned)'!B:B,0) -> 0 | J50: =_xlfn.XLOOKUP(B50,'Bengkel Multi Var (cleaned)'!A:A,'Bengkel Multi Var (cleaned)'!B:B,0) -> 0 | K50: 0 | L50: =_xlfn.XLOOKUP(B50,'Drivewell (cleaned)'!A:A,'Drivewell (cleaned)'!B:B,0) -> 0 | M50: 0 | N50: 0 | O50: 0 | P50: =_xlfn.XLOOKUP(B50,'CV Sun (cleaned)'!A:A,'CV Sun (cleaned)'!B:B,0) -> 0 | Q50: =_xlfn.XLOOKUP(B50,'Sumber Timur (clean)'!F:F,'Sumber Timur (clean)'!L:L,0) -> 0 | R50: =_xlfn.XLOOKUP(B50,'Honda Duren (clean)'!F:F,'Honda Duren (clean)'!L:L,0) -> 0 | S50: 0 | T50: =SUM(C50:S50) -> 0
A51: =VLOOKUP(B51,#REF!,5,0) -> #REF! | B51: CASTROL Engine Oil MAGNATEC 10W-40 4L | C51: =_xlfn.XLOOKUP(B51,'Pit Stop (cleaned)'!A:A,'Pit Stop (cleaned)'!B:B,0) -> 0 | D51: =_xlfn.XLOOKUP(B51,'Subur Makmur Ban (Agg)'!$F$1:$F$5,'Subur Makmur Ban (Agg)'!$L$1:$L$5,0) -> 0 | E51: =_xlfn.XLOOKUP(B51,'Bengkel Pegasus (Agg)'!F:F,'Bengkel Pegasus (Agg)'!L:L,0) -> 0 | F51: =_xlfn.XLOOKUP(B51,'Autocraft (agg)'!F:F,'Autocraft (agg)'!L:L,0) -> 0 | G51: =_xlfn.XLOOKUP(B51,'Autones (cleaned)'!A:A,'Autones (cleaned)'!B:B,0) -> 0 | H51: =_xlfn.XLOOKUP(B51,'ADS Prima (cleaned)'!A:A,'ADS Prima (cleaned)'!B:B,0) -> 0 | I51: =_xlfn.XLOOKUP(B51,'Auto Mekanika (cleaned)'!A:A,'Auto Mekanika (cleaned)'!B:B,0) -> 0 | J51: =_xlfn.XLOOKUP(B51,'Bengkel Multi Var (cleaned)'!A:A,'Bengkel Multi Var (cleaned)'!B:B,0) -> 0 | K51: 0 | L51: =_xlfn.XLOOKUP(B51,'Drivewell (cleaned)'!A:A,'Drivewell (cleaned)'!B:B,0) -> 0 | M51: 0 | N51: 0 | O51: 0 | P51: =_xlfn.XLOOKUP(B51,'CV Sun (cleaned)'!A:A,'CV Sun (cleaned)'!B:B,0) -> 0 | Q51: =_xlfn.XLOOKUP(B51,'Sumber Timur (clean)'!F:F,'Sumber Timur (clean)'!L:L,0) -> 0 | R51: =_xlfn.XLOOKUP(B51,'Honda Duren (clean)'!F:F,'Honda Duren (clean)'!L:L,0) -> 0 | S51: 0 | T51: =SUM(C51:S51) -> 0
A52: =VLOOKUP(B52,#REF!,5,0) -> #REF! | B52: BOSCH Spark Plug FR7NPP332 - Platinum | C52: =_xlfn.XLOOKUP(B52,'Pit Stop (cleaned)'!A:A,'Pit Stop (cleaned)'!B:B,0) -> 0 | D52: =_xlfn.XLOOKUP(B52,'Subur Makmur Ban (Agg)'!$F$1:$F$5,'Subur Makmur Ban (Agg)'!$L$1:$L$5,0) -> 0 | E52: =_xlfn.XLOOKUP(B52,'Bengkel Pegasus (Agg)'!F:F,'Bengkel Pegasus (Agg)'!L:L,0) -> 0 | F52: =_xlfn.XLOOKUP(B52,'Autocraft (agg)'!F:F,'Autocraft (agg)'!L:L,0) -> 0 | G52: =_xlfn.XLOOKUP(B52,'Autones (cleaned)'!A:A,'Autones (cleaned)'!B:B,0) -> 0 | H52: =_xlfn.XLOOKUP(B52,'ADS Prima (cleaned)'!A:A,'ADS Prima (cleaned)'!B:B,0) -> 0 | I52: =_xlfn.XLOOKUP(B52,'Auto Mekanika (cleaned)'!A:A,'Auto Mekanika (cleaned)'!B:B,0) -> 0 | J52: =_xlfn.XLOOKUP(B52,'Bengkel Multi Var (cleaned)'!A:A,'Bengkel Multi Var (cleaned)'!B:B,0) -> 0 | K52: 0 | L52: =_xlfn.XLOOKUP(B52,'Drivewell (cleaned)'!A:A,'Drivewell (cleaned)'!B:B,0) -> 0 | M52: 0 | N52: 0 | O52: 0 | P52: =_xlfn.XLOOKUP(B52,'CV Sun (cleaned)'!A:A,'CV Sun (cleaned)'!B:B,0) -> 0 | Q52: =_xlfn.XLOOKUP(B52,'Sumber Timur (clean)'!F:F,'Sumber Timur (clean)'!L:L,0) -> 0 | R52: =_xlfn.XLOOKUP(B52,'Honda Duren (clean)'!F:F,'Honda Duren (clean)'!L:L,0) -> 0 | S52: 0 | T52: =SUM(C52:S52) -> 0
A53: =VLOOKUP(B53,#REF!,5,0) -> #REF! | B53: BOSCH Oil Filter O 0209 | C53: =_xlfn.XLOOKUP(B53,'Pit Stop (cleaned)'!A:A,'Pit Stop (cleaned)'!B:B,0) -> 0 | D53: =_xlfn.XLOOKUP(B53,'Subur Makmur Ban (Agg)'!$F$1:$F$5,'Subur Makmur Ban (Agg)'!$L$1:$L$5,0) -> 0 | E53: =_xlfn.XLOOKUP(B53,'Bengkel Pegasus (Agg)'!F:F,'Bengkel Pegasus (Agg)'!L:L,0) -> 0 | F53: =_xlfn.XLOOKUP(B53,'Autocraft (agg)'!F:F,'Autocraft (agg)'!L:L,0) -> 0 | G53: =_xlfn.XLOOKUP(B53,'Autones (cleaned)'!A:A,'Autones (cleaned)'!B:B,0) -> 0 | H53: =_xlfn.XLOOKUP(B53,'ADS Prima (cleaned)'!A:A,'ADS Prima (cleaned)'!B:B,0) -> 0 | I53: =_xlfn.XLOOKUP(B53,'Auto Mekanika (cleaned)'!A:A,'Auto Mekanika (cleaned)'!B:B,0) -> 0 | J53: =_xlfn.XLOOKUP(B53,'Bengkel Multi Var (cleaned)'!A:A,'Bengkel Multi Var (cleaned)'!B:B,0) -> 0 | K53: 0 | L53: =_xlfn.XLOOKUP(B53,'Drivewell (cleaned)'!A:A,'Drivewell (cleaned)'!B:B,0) -> 0 | M53: 0 | N53: 0 | O53: 0 | P53: =_xlfn.XLOOKUP(B53,'CV Sun (cleaned)'!A:A,'CV Sun (cleaned)'!B:B,0) -> 0 | Q53: =_xlfn.XLOOKUP(B53,'Sumber Timur (clean)'!F:F,'Sumber Timur (clean)'!L:L,0) -> 0 | R53: =_xlfn.XLOOKUP(B53,'Honda Duren (clean)'!F:F,'Honda Duren (clean)'!L:L,0) -> 0 | S53: 0 | T53: =SUM(C53:S53) -> 0
A54: =VLOOKUP(B54,#REF!,5,0) -> #REF! | B54: DENSO Air Filter DXA-1039 | C54: =_xlfn.XLOOKUP(B54,'Pit Stop (cleaned)'!A:A,'Pit Stop (cleaned)'!B:B,0) -> 0 | D54: =_xlfn.XLOOKUP(B54,'Subur Makmur Ban (Agg)'!$F$1:$F$5,'Subur Makmur Ban (Agg)'!$L$1:$L$5,0) -> 0 | E54: =_xlfn.XLOOKUP(B54,'Bengkel Pegasus (Agg)'!F:F,'Bengkel Pegasus (Agg)'!L:L,0) -> 0 | F54: =_xlfn.XLOOKUP(B54,'Autocraft (agg)'!F:F,'Autocraft (agg)'!L:L,0) -> 0 | G54: =_xlfn.XLOOKUP(B54,'Autones (cleaned)'!A:A,'Autones (cleaned)'!B:B,0) -> 0 | H54: =_xlfn.XLOOKUP(B54,'ADS Prima (cleaned)'!A:A,'ADS Prima (cleaned)'!B:B,0) -> 0 | I54: =_xlfn.XLOOKUP(B54,'Auto Mekanika (cleaned)'!A:A,'Auto Mekanika (cleaned)'!B:B,0) -> 0 | J54: =_xlfn.XLOOKUP(B54,'Bengkel Multi Var (cleaned)'!A:A,'Bengkel Multi Var (cleaned)'!B:B,0) -> 0 | K54: 0 | L54: =_xlfn.XLOOKUP(B54,'Drivewell (cleaned)'!A:A,'Drivewell (cleaned)'!B:B,0) -> 0 | M54: 0 | N54: 0 | O54: 0 | P54: =_xlfn.XLOOKUP(B54,'CV Sun (cleaned)'!A:A,'CV Sun (cleaned)'!B:B,0) -> 0 | Q54: =_xlfn.XLOOKUP(B54,'Sumber Timur (clean)'!F:F,'Sumber Timur (clean)'!L:L,0) -> 0 | R54: =_xlfn.XLOOKUP(B54,'Honda Duren (clean)'!F:F,'Honda Duren (clean)'!L:L,0) -> 0 | S54: 0 | T54: =SUM(C54:S54) -> 0
...

Sheet FRANCHISEE PER MONTH
F6: SALES DATE EXCLUDE TAX
G7: NOV | H7: DEC | I7: JAN | J7: FEB | K7: Total
F8: Pit Stop 3 | G8: =SUMIF('Pit Stop (Agregated)'!$A:$A,G$7,'Pit Stop (Agregated)'!$AA:$AA) -> 23002681 | H8: =SUMIF('Pit Stop (Agregated)'!$A:$A,H$7,'Pit Stop (Agregated)'!$AA:$AA) -> 4520100 | I8: =SUMIF('Pit Stop (Agregated)'!$A:$A,I$7,'Pit Stop (Agregated)'!$AA:$AA) -> 5970536 | J8: =SUMIF('Pit Stop (Agregated)'!$A:$A,J$7,'Pit Stop (Agregated)'!$AA:$AA) -> 0 | K8: =SUM(G8:J8) -> 33493317
F9: Subur Makmur Ban | G9: =SUMIF('Subur Makmur Ban (Agg)'!$A:$A,G$7,'Subur Makmur Ban (Agg)'!$AA:$AA) -> 0 | H9: =SUMIF('Subur Makmur Ban (Agg)'!$A:$A,H$7,'Subur Makmur Ban (Agg)'!$AA:$AA) -> 0 | I9: =SUMIF('Subur Makmur Ban (Agg)'!$A:$A,I$7,'Subur Makmur Ban (Agg)'!$AA:$AA) -> 5648170 | J9: =SUMIF('Subur Makmur Ban (Agg)'!$A:$A,J$7,'Subur Makmur Ban (Agg)'!$AA:$AA) -> 0 | K9: =SUM(G9:J9) -> 5648170
F10: Bengkel Pegasus | G10: =SUMIF('Bengkel Pegasus (Agg)'!$A:$A,G$7,'Bengkel Pegasus (Agg)'!$AA:$AA) -> 0 | H10: =SUMIF('Bengkel Pegasus (Agg)'!$A:$A,H$7,'Bengkel Pegasus (Agg)'!$AA:$AA) -> 0 | I10: =SUMIF('Bengkel Pegasus (Agg)'!$A:$A,I$7,'Bengkel Pegasus (Agg)'!$AA:$AA) -> 1337960 | J10: =SUMIF('Bengkel Pegasus (Agg)'!$A:$A,J$7,'Bengkel Pegasus (Agg)'!$AA:$AA) -> 14226024 | K10: =SUM(G10:J10) -> 15563984
F11: Autocraft | G11: =SUMIF('Autocraft (agg)'!$A:$A,G$7,'Autocraft (agg)'!$AA:$AA) -> 0 | H11: =SUMIF('Autocraft (agg)'!$A:$A,H$7,'Autocraft (agg)'!$AA:$AA) -> 2919100 | I11: =SUMIF('Autocraft (agg)'!$A:$A,I$7,'Autocraft (agg)'!$AA:$AA) -> 0 | J11: =SUMIF('Autocraft (agg)'!$A:$A,J$7,'Autocraft (agg)'!$AA:$AA) -> 0 | K11: =SUM(G11:J11) -> 2919100
F12: Autones | G12: =SUMIF('Autones (agg)'!$A:$A,G$7,'Autones (agg)'!$AA:$AA) -> 17372940 | H12: =SUMIF('Autones (agg)'!$A:$A,H$7,'Autones (agg)'!$AA:$AA) -> 7508003.8 | I12: =SUMIF('Autones (agg)'!$A:$A,I$7,'Autones (agg)'!$AA:$AA) -> 5215847 | J12: =SUMIF('Autones (agg)'!$A:$A,J$7,'Autones (agg)'!$AA:$AA) -> 0 | K12: =SUM(G12:J12) -> 30096791
F13: ADS Prima | G13: =SUMIF('ADS Prima (agg)'!$A:$A,G$7,'ADS Prima (agg)'!$AA:$AA) -> 49304337 | H13: =SUMIF('ADS Prima (agg)'!$A:$A,H$7,'ADS Prima (agg)'!$AA:$AA) -> 0 | I13: =SUMIF('ADS Prima (agg)'!$A:$A,I$7,'ADS Prima (agg)'!$AA:$AA) -> 3438500 | J13: =SUMIF('ADS Prima (agg)'!$A:$A,J$7,'ADS Prima (agg)'!$AA:$AA) -> 5339379.5 | K13: =SUM(G13:J13) -> 58082216
F14: Auto Mekanika | G14: =SUMIF('Auto Mekanika (agg)'!$A:$A,G$7,'Auto Mekanika (agg)'!$AA:$AA) -> 15928672 | H14: =SUMIF('Auto Mekanika (agg)'!$A:$A,H$7,'Auto Mekanika (agg)'!$AA:$AA) -> 11203394 | I14: =SUMIF('Auto Mekanika (agg)'!$A:$A,I$7,'Auto Mekanika (agg)'!$AA:$AA) -> 17351100 | J14: =SUMIF('Auto Mekanika (agg)'!$A:$A,J$7,'Auto Mekanika (agg)'!$AA:$AA) -> 8911994 | K14: =SUM(G14:J14) -> 53395160
F15: Bengkel Multi Variasi | G15: =SUMIF('Bengkel Multi Var (agg)'!$A:$A,G$7,'Bengkel Multi Var (agg)'!$AA:$AA) -> 0 | H15: =SUMIF('Bengkel Multi Var (agg)'!$A:$A,H$7,'Bengkel Multi Var (agg)'!$AA:$AA) -> 23418512 | I15: =SUMIF('Bengkel Multi Var (agg)'!$A:$A,I$7,'Bengkel Multi Var (agg)'!$AA:$AA) -> 6192569.5 | J15: =SUMIF('Bengkel Multi Var (agg)'!$A:$A,J$7,'Bengkel Multi Var (agg)'!$AA:$AA) -> 3667716 | K15: =SUM(G15:J15) -> 33278798
F16: Euro Galleria | G16: =SUMIF('[2]EURO GALLARIA'!$A:$A,G$7,'[2]EURO GALLARIA'!$AA:$AA) -> 0 | H16: =SUMIF('[2]EURO GALLARIA'!$A:$A,H$7,'[2]EURO GALLARIA'!$AA:$AA) -> 2088785.4 | I16: =SUMIF('[2]EURO GALLARIA'!$A:$A,I$7,'[2]EURO GALLARIA'!$AA:$AA) -> 6151600 | J16: =SUMIF('[2]EURO GALLARIA'!$A:$A,J$7,'[2]EURO GALLARIA'!$AA:$AA) -> 0 | K16: =SUM(G16:J16) -> 8240385.4
F17: Drivewell | G17: =SUMIF('Drivewell (agg)'!$A:$A,G$7,'Drivewell (agg)'!$AA:$AA) -> 15232704 | H17: =SUMIF('Drivewell (agg)'!$A:$A,H$7,'Drivewell (agg)'!$AA:$AA) -> 0 | I17: =SUMIF('Drivewell (agg)'!$A:$A,I$7,'Drivewell (agg)'!$AA:$AA) -> 1968850 | J17: =SUMIF('Drivewell (agg)'!$A:$A,J$7,'Drivewell (agg)'!$AA:$AA) -> 8690500 | K17: =SUM(G17:J17) -> 25892054
F18: Mersi (no sales yet) | G18: =SUMIF('[2]Mersi '!$A:$A,G$7,'[2]Mersi '!$AA:$AA) -> 0 | H18: =SUMIF('[2]Mersi '!$A:$A,H$7,'[2]Mersi '!$AA:$AA) -> 712614 | I18: =SUMIF('[2]Mersi '!$A:$A,I$7,'[2]Mersi '!$AA:$AA) -> 703783.5 | J18: =SUMIF('[2]Mersi '!$A:$A,J$7,'[2]Mersi '!$AA:$AA) -> 0 | K18: =SUM(G18:J18) -> 1416397.5
F19: K (No sales yet) | G19: - | H19: - | I19: - | K19: =SUM(G19:J19) -> 0
F20: Auto Service (no sales yet) | G20: - | H20: - | I20: - | K20: =SUM(G20:J20) -> 0
F21: CV Sun | G21: =SUMIF('CV Sun (agg)'!$A:$A,G$7,'CV Sun (agg)'!$AA:$AA) -> 0 | H21: =SUMIF('CV Sun (agg)'!$A:$A,H$7,'CV Sun (agg)'!$AA:$AA) -> 18081336 | I21: =SUMIF('CV Sun (agg)'!$A:$A,I$7,'CV Sun (agg)'!$AA:$AA) -> 68491777 | J21: =SUMIF('CV Sun (agg)'!$A:$A,J$7,'CV Sun (agg)'!$AA:$AA) -> 0 | K21: =SUM(G21:J21) -> 86573113
F22: Sumber Timur | G22: =SUMIF('Sumber Timur (clean)'!$A:$A,G$7,'Sumber Timur (clean)'!$AA:$AA) -> 0 | H22: =SUMIF('Sumber Timur (clean)'!$A:$A,H$7,'Sumber Timur (clean)'!$AA:$AA) -> 3062618 | I22: =SUMIF('Sumber Timur (clean)'!$A:$A,I$7,'Sumber Timur (clean)'!$AA:$AA) -> 3117400 | J22: =SUMIF('Sumber Timur (clean)'!$A:$A,J$7,'Sumber Timur (clean)'!$AA:$AA) -> 0 | K22: =SUM(G22:J22) -> 6180018
F23: Honda Auto Duren Sawit | G23: =SUMIF('Honda Duren (clean)'!$A:$A,G$7,'Honda Duren (clean)'!$AA:$AA) -> 0 | H23: =SUMIF('Honda Duren (clean)'!$A:$A,H$7,'Honda Duren (clean)'!$AA:$AA) -> 2675920 | I23: =SUMIF('Honda Duren (clean)'!$A:$A,I$7,'Honda Duren (clean)'!$AA:$AA) -> 0 | J23: =SUMIF('Honda Duren (clean)'!$A:$A,J$7,'Honda Duren (clean)'!$AA:$AA) -> 9256981.5 | K23: =SUM(G23:J23) -> 11932902
F24: Lavender Car Solution | G24: =SUMIF('Lavender（Agg）'!$A:$A,G7,'Lavender（Agg）'!$AA:$AA) -> 1075100 | H24: =SUMIF('Lavender（Agg）'!$A:$A,H7,'Lavender（Agg）'!$AA:$AA) -> 4081174.5 | I24: =SUMIF('Lavender（Agg）'!$A:$A,I7,'Lavender（Agg）'!$AA:$AA) -> 6204861 | J24: =SUMIF('Lavender（Agg）'!$A:$A,J7,'Lavender（Agg）'!$AA:$AA) -> 2618850 | K24: =SUM(G24:J24) -> 13979986
F25: Total | G25: =SUM(G8:G24) -> 1.2191643e+08 | H25: =SUM(H8:H24) -> 80271557 | I25: =SUM(I8:I24) -> 1.3179295e+08 | J25: =SUM(J8:J24) -> 52711444 | K25: =SUM(K8:K24) -> 386692390
F26: PPN 11%
F27: Total | K27: =K25*1.11 -> 4.2922855e+08

Sheet Pit Stop (Agregated)
A1: MONTH | B1: Kode Barang | F1: Nama Barang | L1: Kts. | P1: @Harga | T1: Diskon | AA1: Total Harga
A2: NOV | B2: 101761 | F2: BOSCH Wiper Clear Advantage 14 inch BCA14 | L2: 10 | P2: 77928 | T2: =L2*P2*35% -> 272748 | AA2: =L2*P2-T2 -> 506532
A3: NOV | B3: 101762 | F3: BOSCH Wiper Clear Advantage 16 inch BCA16 | L3: 10 | P3: 77928 | T3: =L3*P3*35% -> 272748 | AA3: =L3*P3-T3 -> 506532
A4: NOV | B4: 101769 | F4: BOSCH Wiper Clear Advantage 17 inch BCA17 | L4: 10 | P4: 90090 | T4: =L4*P4*35% -> 315315 | AA4: =L4*P4-T4 -> 585585
A5: NOV | B5: 101770 | F5: BOSCH Wiper Clear Advantage 18 inch BCA18 | L5: 10 | P5: 90090 | T5: =L5*P5*35% -> 315315 | AA5: =L5*P5-T5 -> 585585
A6: NOV | B6: 101778 | F6: BOSCH Wiper Clear Advantage 19 inch BCA19 | L6: 10 | P6: 96396 | T6: =L6*P6*35% -> 337386 | AA6: =L6*P6-T6 -> 626574
A7: NOV | B7: 101779 | F7: BOSCH Wiper Clear Advantage 20 inch BCA20 | L7: 10 | P7: 96396 | T7: =L7*P7*35% -> 337386 | AA7: =L7*P7-T7 -> 626574
A8: NOV | B8: 101780 | F8: BOSCH Wiper Clear Advantage 21 inch BCA21 | L8: 10 | P8: 98198 | T8: =L8*P8*35% -> 343693 | AA8: =L8*P8-T8 -> 638287
A9: NOV | B9: 101787 | F9: BOSCH Wiper Clear Advantage 22 inch BCA22 | L9: 10 | P9: 104955 | T9: =L9*P9*35% -> 367342.5 | AA9: =L9*P9-T9 -> 682207.5
A10: NOV | B10: 101788 | F10: BOSCH Wiper Clear Advantage 24 inch BCA24 | L10: 10 | P10: 104955 | T10: =L10*P10*35% -> 367342.5 | AA10: =L10*P10-T10 -> 682207.5
A11: NOV | B11: 101791 | F11: BOSCH Wiper Clear Advantage 26 inch BCA26 | L11: 10 | P11: 110811 | T11: =L11*P11*35% -> 387838.5 | AA11: =L11*P11-T11 -> 720271.5
A12: NOV | B12: 101740 | F12: BOSCH Wiper Advantage 14 inch BA14 | L12: 10 | P12: 50901 | T12: =L12*P12*35% -> 178153.5 | AA12: =L12*P12-T12 -> 330856.5
A13: NOV | B13: 101741 | F13: BOSCH Wiper Advantage 16 inch BA16 | L13: 10 | P13: 50901 | T13: =L13*P13*35% -> 178153.5 | AA13: =L13*P13-T13 -> 330856.5
... A25: NOV | B25: 101807 | F25: BOSCH Spark Plug VR8SII30X - Iridium | L25: 10 | P25: 165400 | T25: =L25*P25*35% -> 578900 | AA25: =L25*P25-T25 -> 1075100
B27: Kode Barang | F27: Nama Barang | L27: Kts. | P27: @Harga | T27: Diskon | AA27: Total Harga
A28: NOV | B28: 101740 | F28: BOSCH Wiper Advantage 14 inch BA14 | L28: 20 | P28: 50901 | T28: =L28*P28*35% -> 356307 | AA28: =L28*P28-T28 -> 661713
A29: NOV | B29: 101745 | F29: BOSCH Wiper Advantage 17 inch BA17 | L29: 30 | P29: 54505 | T29: =L29*P29*35% -> 572302.5 | AA29: =L29*P29-T29 -> 1062847.5
A30: NOV | B30: 101759 | F30: BOSCH Wiper Advantage 22 inch BA22 | L30: 20 | P30: 72793 | T30: =L30*P30*35% -> 509551 | AA30: =L30*P30-T30 -> 946309
A31: NOV | B31: 101761 | F31: BOSCH Wiper Clear Advantage 14 inch BCA14 | L31: 30 | P31: 77928 | T31: =L31*P31*35% -> 818244 | AA31: =L31*P31-T31 -> 1519596
A32: NOV | B32: 101762 | F32: BOSCH Wiper Clear Advantage 16 inch BCA16 | L32: 20 | P32: 77928 | T32: =L32*P32*35% -> 545496 | AA32: =L32*P32-T32 -> 1013064
A33: NOV | B33: 101769 | F33: BOSCH Wiper Clear Advantage 17 inch BCA17 | L33: 10 | P33: 90090 | T33: =L33*P33*35% -> 315315 | AA33: =L33*P33-T33 -> 585585
A34: NOV | B34: 101770 | F34: BOSCH Wiper Clear Advantage 18 inch BCA18 | L34: 10 | P34: 90090 | T34: =L34*P34*35% -> 315315 | AA34: =L34*P34-T34 -> 585585
A35: NOV | B35: 101778 | F35: BOSCH Wiper Clear Advantage 19 inch BCA19 | L35: 10 | P35: 96396 | T35: =L35*P35*35% -> 337386 | AA35: =L35*P35-T35 -> 626574
A36: NOV | B36: 101788 | F36: BOSCH Wiper Clear Advantage 24 inch BCA24 | L36: 20 | P36: 104955 | T36: =L36*P36*35% -> 734685 | AA36: =L36*P36-T36 -> 1364415
A37: NOV | B37: 101791 | F37: BOSCH Wiper Clear Advantage 26 inch BCA26 | L37: 20 | P37: 110811 | T37: =L37*P37*35% -> 775677 | AA37: =L37*P37-T37 -> 1440543
A38: NOV | B38: 101742 | F38: BOSCH Oil Filter O 1014 | L38: 10 | P38: 49700 | T38: =L38*P38*35% -> 173950 | AA38: =L38*P38-T38 -> 323050
A39: NOV | B39: 101737 | F39: BOSCH Oil Filter O 1041 | L39: 10 | P39: 43000 | T39: =L39*P39*35% -> 150500 | AA39: =L39*P39-T39 -> 279500
A40: NOV | B40: 101743 | F40: BOSCH Oil Filter O 1042 | L40: 10 | P40: 50000 | T40: =L40*P40*35% -> 175000 | AA40: =L40*P40-T40 -> 325000
B42: Kode Barang | F42: Nama Barang | L42: Kts. | P42: @Harga | T42: Diskon | AA42: Total Harga
A43: DEC | B43: 101743 | F43: BOSCH Oil Filter O 1042 | L43: 20 | P43: 50000 | T43: =L43*P43*35% -> 350000 | AA43: =L43*P43-T43 -> 650000
A44: DEC | B44: 101737 | F44: BOSCH Oil Filter O 1041 | L44: 20 | P44: 43000 | T44: =L44*P44*35% -> 301000 | AA44: =L44*P44-T44 -> 559000
A45: DEC | B45: 101742 | F45: BOSCH Oil Filter O 1014 | L45: 20 | P45: 49700 | T45: =L45*P45*35% -> 347900 | AA45: =L45*P45-T45 -> 646100
A46: DEC | B46: 101750 | F46: BOSCH Oil Filter O 1001 | L46: 20 | P46: 56000 | T46: =L46*P46*35% -> 392000 | AA46: =L46*P46-T46 -> 728000
B48: Kode Barang | F48: Nama Barang | L48: Kts. | P48: @Harga | T48: Diskon | AA48: Total Harga
